Workbook

Sheet LEIA-ME
A1: PAINEL DE GESTÃO POR DADOS — DADM · padrão DTNH
A2: Mesma linguagem visual, mesma lógica de governança e mesma organização do painel DTNH.
B4: 1. Como a DADM usa a base acadêmica
B5: DADM-01 recebe os desligamentos e usa como denominador a população acadêmica do mês anterior. A população não é recadastrada na DADM.
B6: DADM-09 divide a despesa administrativa pela população acadêmica ativa. DADM-10 usa despesa de infraestrutura, área em uso e a mesma população para a leitura auxiliar por aluno.
B8: 2. Metas e direção dos indicadores
B9: Nos três KPIs implementados, menor é melhor. A meta e o limiar de atenção possuem vigência histórica e nunca devem ser sobrescritos; uma revisão cria uma nova linha em METAS.
B11: 3. O que ver no painel
B12: O PAINEL mantém três blocos executivos, um por KPI, seguindo a mesma lógica do DTNH: resumo, gráfico mês a mês e detalhe do recorte.
B13: DADM-01 detalha evasão por curso. DADM-09 detalha despesas por centro de custo. DADM-10 mantém R$/m² como medida principal e R$/aluno como leitura complementar.
B15: 4. Camada de cálculo
B16: A aba CALC é visível, como no DTNH. Ela documenta os dados que alimentam cartões, gráficos, matriz e comparações. Não edite essa aba manualmente.
B18: 5. Qualidade e governança
B19: Antes de usar o arquivo em reunião gerencial, confira QUALIDADE E GOVERNANÇA. O objetivo é manter zero erros, metas vigentes e fontes acadêmicas claramente identificadas.
... B22: Enquanto DEAD ainda não publica sua própria população, EAD e Semipresencial podem aparecer como base demonstrativa temporária. Quando DEAD entrar, a fonte acadêmica deve substituir automaticamente o fallback.

Sheet PARAMETROS
A1: PARÂMETROS DO PAINEL
A2: Só as células amarelas representam os recortes usados na exportação. A organização segue o mesmo padrão do painel DTNH.
A4: SELEÇÃO
A5: Diretoria | B5: DADM | D5: Diretoria administrativa.
A6: Início da operação | B6: 2026-01 | D6: Primeiro mês alimentado.
A7: Mês de referência | B7: 2026-08 | D7: O mês analisado.
A8: Mês de comparação | B8: 2026-07 | D8: Pode ficar vazio.
A9: Janela — de | B9: 2026-01 | D9: Primeiro mês do gráfico e da matriz.
A10: Janela — até | B10: 2026-08 | D10: Último mês da janela.
A11: Curso em foco | B11: (todos) | D11: Filtra população e evasão. Não rateia custos administrativos por curso.
A12: Modalidade | B12: (todas) | D12: Presencial, EAD ou Semipresencial.
A13: Setor | B13: (todos) | D13: Centro de custo aplicado ao DADM-09.
A15: JANELA EFETIVA
A16: Janela efetiva — de | B16: =IF(IFERROR(VALUE(SUBSTITUTE($B$9,"-","")),0)<IFERROR(VALUE(SUBSTITUTE($B$6,"-","")),0),$B$6,$B$9) | D16: Recuada para o início da operação, se necessário.
A17: Janela efetiva — até | B17: =IF(IFERROR(VALUE(SUBSTITUTE($B$10,"-","")),0)<IFERROR(VALUE(SUBSTITUTE($B$16,"-","")),0),$B$16,$B$10)
A18: Meses na janela | B18: =(VALUE(LEFT($B$17,4))-VALUE(LEFT($B$16,4)))*12+VALUE(RIGHT($B$17,2))-VALUE(RIGHT($B$16,2))+1
A20: aux · data da referência | B20: =IF($B$7="","",DATE(VALUE(LEFT($B$7,4)),VALUE(RIGHT($B$7,2)),1))
A21: aux · data do início da janela | B21: =IF($B$16="","",DATE(VALUE(LEFT($B$16,4)),VALUE(RIGHT($B$16,2)),1))
A22: aux · chave do fim da janela | B22: =IFERROR(VALUE(SUBSTITUTE($B$17,"-","")),0)
A24: ATALHOS | D24: Referências úteis para leitura do fechamento.
A25: Mês anterior à referência | B25: =IF($B$7="","",YEAR(EDATE($B$20,-1))&"-"&IF(MONTH(EDATE($B$20,-1))<10,"0","")&MONTH(EDATE($B$20,-1)))
A26: Mesmo mês do ano anterior | B26: =IF($B$7="","",YEAR(EDATE($B$20,-12))&"-"&IF(MONTH(EDATE($B$20,-12))<10,"0","")&MONTH(EDATE($B$20,-12)))
A27: Primeiro mês com dado | B27: =IF(MIN(DIM_MES!$G$5:$G$148)=999999,"—",INDEX(DIM_MES!$B$5:$B$148,MATCH(MIN(DIM_MES!$G$5:$G$148),DIM_MES!$G$5:$G$148,0)))
A28: Último mês com dado | B28: =IF(MAX(DIM_MES!$H$5:$H$148)=0,"—",INDEX(DIM_MES!$B$5:$B$148,MATCH(MAX(DIM_MES!$H$5:$H$148),DIM_MES!$H$5:$H$148,0)))
A29: Modalidades na base | B29: =COUNTIF('LISTAS DE APOIO'!$B$5:$B$7,"<>")&" modalidades cadastradas"
A30: Recorte atual | B30: =$B$11&" · "&$B$12&" · "&$B$13
A33: DIAGNÓSTICO
A34: Mês de referência tem dado? | B34: =IF($B$7="","sem mês escolhido",IF(IFERROR(INDEX(DIM_MES!$F$5:$F$148,MATCH($B$7,DIM_MES!$B$5:$B$148,0)),0)>0,"OK — há lançamentos","SEM DADO neste mês"))
A35: Mês de comparação tem dado? | B35: =IF($B$8="","(sem comparação)",IF(IFERROR(INDEX(DIM_MES!$F$5:$F$148,MATCH($B$8,DIM_MES!$B$5:$B$148,0)),0)>0,"OK — há lançamentos","SEM DADO neste mês"))
A36: Referência está dentro da janela? | B36: =IF($B$7="","—",IF(AND(IFERROR(VALUE(SUBSTITUTE($B$7,"-","")),0)>=IFERROR(VALUE(SUBSTITUTE($B$16,"-","")),0),IFERROR(VALUE(SUBSTITUTE($B$7,"-","")),0)<=IFERROR(VALUE(SUBSTITUTE($B$17,"-","")),0)),"OK — dentro da janela","FORA DA JANELA — o gráfico não mostra o mês analisado"))
A37: Tamanho da janela | B37: =IF($B$18>12,"EXCEDE 12 MESES — só os primeiros 12 aparecem",$B$18&" meses, dentro do limite de 12")
A38: Meses vazios na janela | B38: =IF(SUMPRODUCT((DIM_MES!$E$5:$E$148>=IFERROR(VALUE(SUBSTITUTE($B$16,"-","")),0))*(DIM_MES!$E$5:$E$148<=IFERROR(VALUE(SUBSTITUTE($B$17,"-","")),0))*(DIM_MES!$F$5:$F$148=0))=0,"OK — nenhum mês vazio",SUMPRODUCT((DIM_MES!$E$5:$E$148>=IFERROR(VALUE(SUBSTITUTE($B$16,"-","")),0))*(DIM_MES!$E$5:$E$148<=IFERROR(VALUE(SUBSTITUTE($B$17,"-","")),0))*(DIM_MES!$F$5:$F$148=0))&" meses vazios — revise a janela")
A39: Base acadêmica temporária | B39: =IF(COUNTIF('DADM-09 ALUNOS'!$G$5:$G$1200,"Sim")=0,"OK — sem fallback temporário",COUNTIF('DADM-09 ALUNOS'!$G$5:$G$1200,"Sim")&" linhas temporárias — revisar quando DEAD estiver ativo")
A40: Metas históricas cadastradas | B40: =IF(COUNTIF(METAS!$A$5:$A$404,"DADM-*")>=3,"OK — metas cadastradas","SEM META — revisar a aba METAS")

Sheet PAINEL
A1: PAINEL DE GESTÃO — DADM
A2: Leitura do mês. Todos os números vêm de CALC; para entender o recorte, consulte PARAMETROS.
A4: Mês de referência | D4: Mês de comparação | G4: Janela | J4: Recorte
A5: =PARAMETROS!$B$7 | D5: =IF(PARAMETROS!$B$8="","(sem)",PARAMETROS!$B$8) | G5: =PARAMETROS!$B$16&" a "&PARAMETROS!$B$17 | J5: =PARAMETROS!$B$11&" · "&PARAMETROS!$B$12&" · "&PARAMETROS!$B$13
A7: DADM-01 · Taxa de Evasão · alimentação mensal · detalhe por curso
A8: Valor na referência | B8: Valor na comparação | C8: Variação | D8: Meta vigente | E8: Limiar de atenção | F8: Distância da meta | G8: Distância do limiar | H8: Atingimento | I8: Status | J8: Situação | K8: Lançamentos
A9: =CALC!$B$37 | B9: =CALC!$C$37 | C9: =CALC!$D$37 | D9: =CALC!$E$37 | E9: =CALC!$F$37 | F9: =CALC!$G$37 | G9: =CALC!$H$37 | H9: =CALC!$I$37 | I9: =CALC!$J$37 | J9: =CALC!$K$37 | K9: =CALC!$L$37
A26: Curso | B26: Referência | C26: Comparação | D26: Variação | E26: Meta | F26: Status
A27: =CALC!$A$41 | B27: =CALC!$F$41 | C27: =CALC!$G$41 | D27: =CALC!$H$41 | E27: =CALC!$I$41 | F27: =CALC!$K$41
A28: =CALC!$A$42 | B28: =CALC!$F$42 | C28: =CALC!$G$42 | D28: =CALC!$H$42 | E28: =CALC!$I$42 | F28: =CALC!$K$42
A29: =CALC!$A$43 | B29: =CALC!$F$43 | C29: =CALC!$G$43 | D29: =CALC!$H$43 | E29: =CALC!$I$43 | F29: =CALC!$K$43
A30: =CALC!$A$44 | B30: =CALC!$F$44 | C30: =CALC!$G$44 | D30: =CALC!$H$44 | E30: =CALC!$I$44 | F30: =CALC!$K$44
A31: =CALC!$A$45 | B31: =CALC!$F$45 | C31: =CALC!$G$45 | D31: =CALC!$H$45 | E31: =CALC!$I$45 | F31: =CALC!$K$45
A32: =CALC!$A$46 | B32: =CALC!$F$46 | C32: =CALC!$G$46 | D32: =CALC!$H$46 | E32: =CALC!$I$46 | F32: =CALC!$K$46
A33: =CALC!$A$47 | B33: =CALC!$F$47 | C33: =CALC!$G$47 | D33: =CALC!$H$47 | E33: =CALC!$I$47 | F33: =CALC!$K$47
A34: =CALC!$A$48 | B34: =CALC!$F$48 | C34: =CALC!$G$48 | D34: =CALC!$H$48 | E34: =CALC!$I$48 | F34: =CALC!$K$48
A35: =CALC!$A$49 | B35: =CALC!$F$49 | C35: =CALC!$G$49 | D35: =CALC!$H$49 | E35: =CALC!$I$49 | F35: =CALC!$K$49
A38: DADM-09 · Custo Administrativo por Aluno · alimentação mensal · detalhe por centro de custo
A39: Valor na referência | B39: Valor na comparação | C39: Variação | D39: Meta vigente | E39: Limiar de atenção | F39: Distância da meta | G39: Distância do limiar | H39: Atingimento | I39: Status | J39: Situação | K39: Lançamentos
A40: =CALC!$B$70 | B40: =CALC!$C$70 | C40: =CALC!$D$70 | D40: =CALC!$E$70 | E40: =CALC!$F$70 | F40: =CALC!$G$70 | G40: =CALC!$H$70 | H40: =CALC!$I$70 | I40: =CALC!$J$70 | J40: =CALC!$K$70 | K40: =CALC!$L$70
A57: Centro de custo | B57: Referência | C57: Comparação | D57: Variação | E57: % da despesa | F57: Leitura
A58: =CALC!$A$74 | B58: =CALC!$D$74 | C58: =CALC!$E$74 | D58: =CALC!$F$74 | E58: =CALC!$G$74 | F58: =CALC!$H$74
A59: =CALC!$A$75 | B59: =CALC!$D$75 | C59: =CALC!$E$75 | D59: =CALC!$F$75 | E59: =CALC!$G$75 | F59: =CALC!$H$75
A60: =CALC!$A$76 | B60: =CALC!$D$76 | C60: =CALC!$E$76 | D60: =CALC!$F$76 | E60: =CALC!$G$76 | F60: =CALC!$H$76
A61: =CALC!$A$77 | B61: =CALC!$D$77 | C61: =CALC!$E$77 | D61: =CALC!$F$77 | E61: =CALC!$G$77 | F61: =CALC!$H$77
A62: =CALC!$A$78 | B62: =CALC!$D$78 | C62: =CALC!$E$78 | D62: =CALC!$F$78 | E62: =CALC!$G$78 | F62: =CALC!$H$78
A63: =CALC!$A$79 | B63: =CALC!$D$79 | C63: =CALC!$E$79 | D63: =CALC!$F$79 | E63: =CALC!$G$79 | F63: =CALC!$H$79
A64: =CALC!$A$80 | B64: =CALC!$D$80 | C64: =CALC!$E$80 | D64: =CALC!$F$80 | E64: =CALC!$G$80 | F64: =CALC!$H$80
A65: =CALC!$A$81 | B65: =CALC!$D$81 | C65: =CALC!$E$81 | D65: =CALC!$F$81 | E65: =CALC!$G$81 | F65: =CALC!$H$81
A66: =CALC!$A$82 | B66: =CALC!$D$82 | C66: =CALC!$E$82 | D66: =CALC!$F$82 | E66: =CALC!$G$82 | F66: =CALC!$H$82
A69: DADM-10 · Eficiência das Despesas de Infraestrutura · medida principal R$/m²
A70: Valor na referência | B70: Valor na comparação | C70: Variação | D70: Meta vigente | E70: Limiar de atenção | F70: Distância da meta | G70: Distância do limiar | H70: Atingimento | I70: Status | J70: Situação | K70: Lançamentos
A71: =CALC!$B$103 | B71: =CALC!$C$103 | C71: =CALC!$D$103 | D71: =CALC!$E$103 | E71: =CALC!$F$103 | F71: =CALC!$G$103 | G71: =CALC!$H$103 | H71: =CALC!$I$103 | I71: =CALC!$J$103 | J71: =CALC!$K$103 | K71: =CALC!$L$103
A88: Medida | B88: Referência | C88: Comparação | D88: Variação | E88: Meta | F88: Status
A89: =CALC!$A$107 | B89: =CALC!$D$107 | C89: =CALC!$E$107 | D89: =CALC!$F$107 | E89: =CALC!$G$107 | F89: =CALC!$I$107
A90: =CALC!$A$108 | B90: =CALC!$D$108 | C90: =CALC!$E$108 | D90: =CALC!$F$108 | E90: =CALC!$G$108 | F90: =CALC!$I$108
A91: =CALC!$A$109 | B91: =CALC!$D$109 | C91: =CALC!$E$109 | D91: =CALC!$F$109 | E91: =CALC!$G$109 | F91: =CALC!$I$109
A92: =CALC!$A$110 | B92: =CALC!$D$110 | C92: =CALC!$E$110 | D92: =CALC!$F$110 | E92: =CALC!$G$110 | F92: =CALC!$I$110
A93: =CALC!$A$111 | B93: =CALC!$D$111 | C93: =CALC!$E$111 | D93: =CALC!$F$111 | E93: =CALC!$G$111 | F93: =CALC!$I$111
A94: =CALC!$A$112 | B94: =CALC!$D$112 | C94: =CALC!$E$112 | D94: =CALC!$F$112 | E94: =CALC!$G$112 | F94: =CALC!$I$112
...

Sheet QUALIDADE E GOVERNANÇA
A1: QUALIDADE DOS DADOS E GOVERNANÇA DO PROTÓTIPO
A2: Controles criados para reduzir dupla contagem, denominadores divergentes e decisões baseadas em bases incompletas.
A4: CONTROLES AUTOMÁTICOS
A5: Base | B5: Regra verificada | C5: Erros atuais | D5: Risco de gestão | E5: Ação recomendada | F5: Prioridade
A6: DADM-01 · Evasão | B6: Base do mês anterior, desligamentos não negativos e chave única por curso | C6: 0 | D6: Taxa de evasão inconsistente | E6: Corrigir base ou desligamentos antes de publicar | F6: Crítica
A7: DADM-09 · Custos | B7: Despesa não negativa e chave única por mês, centro de custo e modalidade | C7: 0 | D7: Custo por aluno distorcido | E7: Revisar despesas e classificação dos centros de custo | F7: Crítica
A8: Base acadêmica | B8: População consolidada sem recadastro manual; fallbacks temporários identificados | C8: 0 | D8: Denominador financeiro divergente | E8: Validar origem acadêmica e retirar fallback quando DEAD entrar | F8: Alta
A9: DADM-10 · Infra | B9: Despesa não negativa, área em uso > 0 e uma fotografia por mês | C9: 0 | D9: Custo por m² inválido | E9: Validar despesa e mapa de áreas antes da reunião | F9: Alta
A11: AVALIAÇÃO DO DESENHO DO PAINEL
A12: Tema | B12: Diagnóstico | C12: Decisão aplicada | D12: Próximo passo recomendado | E12: Prazo sugerido | F12: Responsável
A13: População acadêmica | B13: Recadastrar alunos na DADM criaria duas fontes para o mesmo estoque. | C13: DADM consome Matrículas Ativas das diretorias acadêmicas. | D13: Ao ativar DCS/DEAD, incluir suas bases no agregador sem criar nova digitação na DADM. | E13: Na implantação das diretorias | F13: Responsável técnico
A14: Evasão | B14: A variação líquida de matrículas não equivale a evasão: entradas podem compensar saídas. | C14: O numerador permanece desligamentos reais; o denominador vem do fechamento do mês anterior. | D14: Integrar desligamentos à fonte acadêmica oficial quando houver disponibilidade. | E14: Curto prazo | F14: DADM + Secretaria
A15: Modalidade | B15: Presencial, EAD e Semipresencial precisam ser identificados na origem acadêmica. | C15: Modalidade pertence ao curso e acompanha a população consolidada. | D15: Substituir o fallback EAD/Semipresencial pela base DEAD quando a diretoria entrar no sistema. | E15: Na ativação do DEAD | F15: DEAD + DADM
A16: Custo administrativo | B16: Filtrar despesa institucional por curso sem regra de rateio gera interpretação falsa. | C16: Curso não rateia DADM-09; modalidade e centro de custo podem ser usados como recorte analítico. | D16: Definir regra institucional de rateio somente se houver necessidade gerencial real. | E16: Médio prazo | F16: DADM + Financeiro
A17: Metas de custo | B17: A meta institucional fala em redução real anual, mas o protótipo precisa exercitar vigência e status. | C17: Mantidas metas operacionais demonstrativas com histórico preservado. | D17: Substituir pelos limites oficiais após aprovação de baseline e deflator. | E17: Antes do uso oficial | F17: Diretoria + Financeiro
A18: Infraestrutura | B18: R$/m² é a medida operacional principal; R$/aluno é complementar. | C18: Uma única meta é aplicada ao R$/m² para evitar metas concorrentes no mesmo KPI. | D18: Vincular a leitura definitiva ao DADM-02 quando a Taxa de Ensalamento estiver implementada. | E18: Fase DADM-02 | F18: DADM
A19: Metas históricas | B19: Sobrescrever uma meta apaga o contexto das decisões passadas. | C19: Cada mudança cria nova vigência na aba METAS. | D19: Registrar justificativa e aprovação em toda revisão de meta. | E19: Rotina mensal | F19: Diretoria
A20: Expansão das diretorias | B20: A DADM depende de fontes acadêmicas que ainda serão incorporadas ao Data UNIVC. | C20: A população foi centralizada para permitir novas diretorias sem duplicar estruturas. | D20: Revisar o agregador e os filtros ao ativar DCS e DEAD. | E20: Conforme roadmap | F20: Responsável técnico
A23: CRITÉRIOS DE LIBERAÇÃO PARA USO GERENCIAL
A24: ☐ | B24: Zero linhas com erro nas bases de evasão, custos, população e infraestrutura.
A25: ☐ | B25: Fonte oficial, responsável e data de corte definidos para os três KPIs.
A26: ☐ | B26: Metas aprovadas e registradas com vigência para DADM-01, DADM-09 e DADM-10.
A27: ☐ | B27: Nenhum recadastro manual da população acadêmica na DADM.
A28: ☐ | B28: Fallback EAD/Semipresencial retirado assim que DEAD publicar a fonte acadêmica oficial.
A29: ☐ | B29: Planos de ação vinculados pelo recorte exato que ficou fora da meta.

Sheet MATRIZ
A1: RECORTES DO DADM AO LONGO DOS MESES DA JANELA
A2: Colunas em branco são meses fora da janela. As últimas colunas comparam referência, comparação, variação, meta e status.
A4: DADM-01 — Taxa de Evasão por Curso
A5: Curso | N5: Referência | O5: Comparação | P5: Variação | Q5: Meta | R5: Status
A17: DADM-09 — Custo Administrativo por Aluno por Modalidade
A18: Modalidade | N18: Referência | O18: Comparação | P18: Variação | Q18: Meta | R18: Status
A30: DADM-10 — Infraestrutura
A31: Medida | N31: Referência | O31: Comparação | P31: Variação | Q31: Meta | R31: Status
A43: DADM-01 — Base de alunos ativos por curso | D43: a mesma população acadêmica usada no denominador da evasão
A44: Diretoria / Curso | B44: Modalidade
A53: A DADM consome a população das diretorias acadêmicas. Quando DCS e DEAD forem ativadas, esta matriz passa a agregar as novas fontes.

Sheet PLANO_DE_ACAO
A1: PLANO DE AÇÃO — OBRIGATÓRIO PARA RECORTE FORA DA META
A2: Abra uma ação quando o recorte ficar fora da meta. Preserve problema, causa, responsável, prazo e resultado esperado.
A4: COBERTURA NO MÊS DE REFERÊNCIA
A5: Recortes fora da meta | B5: =COUNTIF(CALC!$K$41:$K$50,"Fora da meta")+COUNTIF(CALC!$J$37,"Fora da meta")+COUNTIF(CALC!$J$70,"Fora da meta")+COUNTIF(CALC!$J$103,"Fora da meta") | C5: Planos abertos | D5: =COUNTIFS($B$9:$B$308,PARAMETROS!$B$7) | E5: Cobertura | F5: =IF($B$5=0,"—",IFERROR($D$5/$B$5,"")) | G5: =IF($B$5=0,"Nenhum recorte fora da meta neste mês.",IF($D$5>=$B$5,"Cobertura completa.","FALTAM PLANOS: há recorte fora da meta sem plano de ação aberto."))
A8: Nº | B8: Mês | C8: KPI | D8: Recorte afetado | E8: Resultado | F8: Meta | G8: Problema identificado | H8: Causa provável | I8: Ação corretiva | J8: Responsável | K8: Prazo | L8: Meta da ação | M8: Status | N8: Dias p/ o prazo
N9: =IF($K9="","",IF(OR($M9="Concluído",$M9="Cancelado"),"—",DATEVALUE($K9)-TODAY()))
N10: =IF($K10="","",IF(OR($M10="Concluído",$M10="Cancelado"),"—",DATEVALUE($K10)-TODAY()))
N11: =IF($K11="","",IF(OR($M11="Concluído",$M11="Cancelado"),"—",DATEVALUE($K11)-TODAY()))
N12: =IF($K12="","",IF(OR($M12="Concluído",$M12="Cancelado"),"—",DATEVALUE($K12)-TODAY()))
N13: =IF($K13="","",IF(OR($M13="Concluído",$M13="Cancelado"),"—",DATEVALUE($K13)-TODAY()))
N14: =IF($K14="","",IF(OR($M14="Concluído",$M14="Cancelado"),"—",DATEVALUE($K14)-TODAY()))
N15: =IF($K15="","",IF(OR($M15="Concluído",$M15="Cancelado"),"—",DATEVALUE($K15)-TODAY()))
N16: =IF($K16="","",IF(OR($M16="Concluído",$M16="Cancelado"),"—",DATEVALUE($K16)-TODAY()))
N17: =IF($K17="","",IF(OR($M17="Concluído",$M17="Cancelado"),"—",DATEVALUE($K17)-TODAY()))
N18: =IF($K18="","",IF(OR($M18="Concluído",$M18="Cancelado"),"—",DATEVALUE($K18)-TODAY()))
N19: =IF($K19="","",IF(OR($M19="Concluído",$M19="Cancelado"),"—",DATEVALUE($K19)-TODAY()))
N20: =IF($K20="","",IF(OR($M20="Concluído",$M20="Cancelado"),"—",DATEVALUE($K20)-TODAY()))
... N308: =IF($K308="","",IF(OR($M308="Concluído",$M308="Cancelado"),"—",DATEVALUE($K308)-TODAY()))

Sheet DADM-01 EVASAO
A1: BASE — DADM-01 · Taxa de Evasão
A2: Desligamentos mensais por curso. A base inicial é herdada automaticamente da população acadêmica do mês anterior.
A4: Período | B4: Diretoria Acadêmica | C4: Curso | D4: Modalidade | E4: Alunos no Início | F4: Desligamentos | G4: Taxa de Evasão | H4: Meta vigente | I4: Status | J4: Lançado por

Sheet DADM-09 CUSTOS
A1: BASE — DADM-09 · Custos Administrativos
A2: Despesas mensais por centro de custo e modalidade. A população usada no denominador vem da base acadêmica.
A4: Período | B4: Centro de Custo | C4: Modalidade | D4: Despesa Administrativa | E4: Lançado por

Sheet DADM-09 ALUNOS
A1: BASE ACADÊMICA — ALUNOS ATIVOS
A2: População consumida automaticamente pela DADM. Bases temporárias permanecem identificadas até a diretoria acadêmica responsável entrar no sistema.
A4: Período | B4: Diretoria Acadêmica | C4: Curso | D4: Modalidade | E4: Alunos Ativos | F4: Origem | G4: Base Temporária

Sheet DADM-10 INFRA
A1: BASE — DADM-10 · Infraestrutura
A2: Despesa mensal de infraestrutura, área em uso e métricas derivadas. R$/m² é a medida principal do KPI.
A4: Período | B4: Despesa de Infraestrutura | C4: Área em Uso (m²) | D4: Custo por m² | E4: Alunos Ativos | F4: Custo por Aluno | G4: Meta R$/m² | H4: Status | I4: Lançado por

Sheet METAS
A1: METAS COM VIGÊNCIA — HISTÓRICO PRESERVADO
A2: Para mudar uma meta, ACRESCENTE uma linha com nova vigência; nunca sobrescreva. DADM-01, DADM-09 e DADM-10 usam a lógica 'menor é melhor'.
A4: KPI | B4: Recorte | C4: Vigência (AAAA-MM) | D4: Chave (calc.) | E4: Meta | F4: Limiar de atenção | G4: Limite superior | H4: Justificativa
D5: =IFERROR(VALUE(SUBSTITUTE($C5,"-","")),0)
D6: =IFERROR(VALUE(SUBSTITUTE($C6,"-","")),0)
D7: =IFERROR(VALUE(SUBSTITUTE($C7,"-","")),0)
D8: =IFERROR(VALUE(SUBSTITUTE($C8,"-","")),0)
D9: =IFERROR(VALUE(SUBSTITUTE($C9,"-","")),0)
D10: =IFERROR(VALUE(SUBSTITUTE($C10,"-","")),0)
D11: =IFERROR(VALUE(SUBSTITUTE($C11,"-","")),0)
D12: =IFERROR(VALUE(SUBSTITUTE($C12,"-","")),0)
D13: =IFERROR(VALUE(SUBSTITUTE($C13,"-","")),0)
D14: =IFERROR(VALUE(SUBSTITUTE($C14,"-","")),0)
D15: =IFERROR(VALUE(SUBSTITUTE($C15,"-","")),0)
D16: =IFERROR(VALUE(SUBSTITUTE($C16,"-","")),0)
... D404: =IFERROR(VALUE(SUBSTITUTE($C404,"-","")),0)

Sheet CURSOS
A1: CURSOS ACADÊMICOS CONSUMIDOS PELA DADM
A2: A população e a evasão são herdadas das diretorias acadêmicas. A DADM não recadastra o estoque de alunos.
A4: Diretoria Acadêmica | B4: Curso | C4: Modalidade | D4: Ativo | E4: Uso na DADM | F4: Observação

Sheet INDICADORES
A1: REGISTRO DE DEFINIÇÕES
A2: Os três KPIs da DADM são alimentados mensalmente. A direção é 'menor é melhor'; DADM-10 usa R$/m² como medida principal.
A4: Código | B4: Nome | C4: Aba de entrada | D4: Tabela | E4: Direção | F4: Formato | G4: Variação medida como | H4: Objetivo | I4: Periodicidade de alimentação | J4: Nível de detalhe
A5: DADM-01 | B5: Taxa de Evasão | C5: DADM-01 EVASAO | D5: Dadm01Base | E5: Menor é melhor | F5: pct | G5: Diferença (p.p.) | H5: Desligamentos do mês sobre alunos ativos no início do mês. | I5: Mensal | J5: Curso
A6: DADM-09 | B6: Custo Administrativo por Aluno | C6: DADM-09 CUSTOS | D6: Dadm09Custos | E6: Menor é melhor | F6: R$/aluno | G6: Razão (%) | H6: Despesa administrativa consolidada sobre população acadêmica ativa. | I6: Mensal | J6: Modalidade / centro de custo
A7: DADM-10 | B7: Eficiência das Despesas de Infraestrutura | C7: DADM-10 INFRA | D7: Dadm10Infra | E7: Menor é melhor | F7: R$/m² | G7: Razão (%) | H7: Despesa de infraestrutura sobre área em uso; R$/aluno é complementar. | I7: Mensal | J7: Institucional
A9: A medida principal do DADM-10 é R$/m². Mudanças de definição, meta ou fonte devem preservar vigência e histórico.

Sheet CALC
A1: CAMADA DE PROCESSAMENTO — NÃO EDITAR
A2: Mesma função da CALC do DTNH: documenta séries, metas, resumos e recortes que alimentam PAINEL e MATRIZ.
A4: Janela de | D4: até | G4: Referência | J4: Comparação | M4: Recorte
A6: METAS VIGENTES NO MÊS DE REFERÊNCIA
A7: Recorte | B7: DADM-01 meta | C7: DADM-01 atenção | D7: DADM-09 meta | E7: DADM-09 atenção | F7: DADM-10 meta | G7: DADM-10 atenção
A20: DADM-01 — Taxa de Evasão
A21: Mês | B21: Base de alunos | C21: Desligamentos | D21: Valor apurado | E21: Meta | F21: Atenção | G21: Status | H21: Lançamentos
A36: KPI | B36: Referência | C36: Comparação | D36: Variação | E36: Meta | F36: Atenção | G36: Distância meta | H36: Distância atenção | I36: Atingimento | J36: Status | K36: Situação | L36: Lançamentos | N36: Mês referência | O36: Mês comparação
A40: Curso | B40: Diretoria | C40: Modalidade | D40: Base | E40: Desligamentos | F40: Referência | G40: Comparação | H40: Variação | I40: Meta | J40: Atenção | K40: Status
A53: DADM-09 — Custo Administrativo por Aluno
A54: Mês | B54: Despesa | C54: Alunos ativos | D54: Valor apurado | E54: Meta | F54: Atenção | G54: Status | H54: Lançamentos
A69: KPI | B69: Referência | C69: Comparação | D69: Variação | E69: Meta | F69: Atenção | G69: Distância meta | H69: Distância atenção | I69: Atingimento | J69: Status | K69: Situação | L69: Lançamentos | N69: Mês referência | O69: Mês comparação
A73: Centro de custo | B73: Despesa | C73: Modalidade | D73: Referência | E73: Comparação | F73: Variação | G73: % da despesa | H73: Leitura
A86: DADM-10 — Eficiência das Despesas de Infraestrutura
A87: Mês | B87: Despesa | C87: Área em uso | D87: Alunos ativos | E87: R$/m² | F87: Meta | G87: Atenção | H87: R$/aluno | I87: Status
A102: KPI | B102: Referência | C102: Comparação | D102: Variação | E102: Meta | F102: Atenção | G102: Distância meta | H102: Distância atenção | I102: Atingimento | J102: Status | K102: Situação | L102: Lançamentos | N102: Mês referência | O102: Mês comparação
A106: Medida | B106: Unidade | C106: Origem | D106: Referência | E106: Comparação | F106: Variação | G106: Meta | H106: Atenção | I106: Status

Sheet LISTAS DE APOIO
A1: LISTAS DE APOIO
A2: Usadas pelas validações. Não apague colunas. A exportação preenche cursos e centros de custo disponíveis.
A4: Recortes | B4: Modalidades | C4: Sim / Não | D4: Ativo | E4: Status possíveis | F4: Status do plano de ação | G4: Direção | H4: Curso em foco | I4: Setor
A5: TOTAL | B5: Presencial | C5: Não | D5: S | E5: Dentro da meta | F5: Não iniciado | G5: Menor é melhor | H5: (todos) | I5: (todos)
B6: EAD | C6: Sim | D6: N | E6: Atenção | F6: Em andamento
B7: Semipresencial | E7: Fora da meta | F7: Concluído
B8: (todas) | E8: Sem dados | F8: Atrasado
E9: Recorte analítico | F9: Cancelado

Sheet DIM_PERIODO
A1: DIMENSÃO DE PERÍODOS DE ALIMENTAÇÃO
A2: Na DADM operacional, DADM-01, DADM-09 e DADM-10 usam competência mensal. A tabela mantém o mesmo papel da DIM_PERIODO do DTNH.
A4: Mensal | B4: DADM-01 | C4: DADM-09 | D4: DADM-10 | E4: Observação
A5: 2025-01 | B5: 2025-01 | C5: 2025-01 | D5: 2025-01 | E5: Competência mensal
A6: 2025-02 | B6: 2025-02 | C6: 2025-02 | D6: 2025-02 | E6: Competência mensal
A7: 2025-03 | B7: 2025-03 | C7: 2025-03 | D7: 2025-03 | E7: Competência mensal
A8: 2025-04 | B8: 2025-04 | C8: 2025-04 | D8: 2025-04 | E8: Competência mensal
A9: 2025-05 | B9: 2025-05 | C9: 2025-05 | D9: 2025-05 | E9: Competência mensal
A10: 2025-06 | B10: 2025-06 | C10: 2025-06 | D10: 2025-06 | E10: Competência mensal
A11: 2025-07 | B11: 2025-07 | C11: 2025-07 | D11: 2025-07 | E11: Competência mensal
A12: 2025-08 | B12: 2025-08 | C12: 2025-08 | D12: 2025-08 | E12: Competência mensal
A13: 2025-09 | B13: 2025-09 | C13: 2025-09 | D13: 2025-09 | E13: Competência mensal
A14: 2025-10 | B14: 2025-10 | C14: 2025-10 | D14: 2025-10 | E14: Competência mensal
A15: 2025-11 | B15: 2025-11 | C15: 2025-11 | D15: 2025-11 | E15: Competência mensal
... A148: 2036-12 | B148: 2036-12 | C148: 2036-12 | D148: 2036-12 | E148: Competência mensal

Sheet DIM_MES
A1: DIMENSÃO DE MESES (EXIBIÇÃO)
A2: Meses usados em parâmetros, diagnóstico e janela. Lançamentos somam as quatro bases operacionais da DADM.
A4: Data | B4: Mês | C4: Ano | D4: Nº mês | E4: Chave | F4: Lançamentos | G4: Primeira chave com dado | H4: Última chave com dado
A5: 45658 | B5: 2025-01 | C5: 2025 | D5: 1 | E5: 202501 | F5: =COUNTIF('DADM-01 EVASAO'!$A$5:$A$1200,$B5)+COUNTIF('DADM-09 CUSTOS'!$A$5:$A$1200,$B5)+COUNTIF('DADM-09 ALUNOS'!$A$5:$A$1200,$B5)+COUNTIF('DADM-10 INFRA'!$A$5:$A$1200,$B5) | G5: =IF($F5>0,$E5,999999) | H5: =IF($F5>0,$E5,0)
A6: 45689 | B6: 2025-02 | C6: 2025 | D6: 2 | E6: 202502 | F6: =COUNTIF('DADM-01 EVASAO'!$A$5:$A$1200,$B6)+COUNTIF('DADM-09 CUSTOS'!$A$5:$A$1200,$B6)+COUNTIF('DADM-09 ALUNOS'!$A$5:$A$1200,$B6)+COUNTIF('DADM-10 INFRA'!$A$5:$A$1200,$B6) | G6: =IF($F6>0,$E6,999999) | H6: =IF($F6>0,$E6,0)
A7: 45717 | B7: 2025-03 | C7: 2025 | D7: 3 | E7: 202503 | F7: =COUNTIF('DADM-01 EVASAO'!$A$5:$A$1200,$B7)+COUNTIF('DADM-09 CUSTOS'!$A$5:$A$1200,$B7)+COUNTIF('DADM-09 ALUNOS'!$A$5:$A$1200,$B7)+COUNTIF('DADM-10 INFRA'!$A$5:$A$1200,$B7) | G7: =IF($F7>0,$E7,999999) | H7: =IF($F7>0,$E7,0)
A8: 45748 | B8: 2025-04 | C8: 2025 | D8: 4 | E8: 202504 | F8: =COUNTIF('DADM-01 EVASAO'!$A$5:$A$1200,$B8)+COUNTIF('DADM-09 CUSTOS'!$A$5:$A$1200,$B8)+COUNTIF('DADM-09 ALUNOS'!$A$5:$A$1200,$B8)+COUNTIF('DADM-10 INFRA'!$A$5:$A$1200,$B8) | G8: =IF($F8>0,$E8,999999) | H8: =IF($F8>0,$E8,0)
A9: 45778 | B9: 2025-05 | C9: 2025 | D9: 5 | E9: 202505 | F9: =COUNTIF('DADM-01 EVASAO'!$A$5:$A$1200,$B9)+COUNTIF('DADM-09 CUSTOS'!$A$5:$A$1200,$B9)+COUNTIF('DADM-09 ALUNOS'!$A$5:$A$1200,$B9)+COUNTIF('DADM-10 INFRA'!$A$5:$A$1200,$B9) | G9: =IF($F9>0,$E9,999999) | H9: =IF($F9>0,$E9,0)
A10: 45809 | B10: 2025-06 | C10: 2025 | D10: 6 | E10: 202506 | F10: =COUNTIF('DADM-01 EVASAO'!$A$5:$A$1200,$B10)+COUNTIF('DADM-09 CUSTOS'!$A$5:$A$1200,$B10)+COUNTIF('DADM-09 ALUNOS'!$A$5:$A$1200,$B10)+COUNTIF('DADM-10 INFRA'!$A$5:$A$1200,$B10) | G10: =IF($F10>0,$E10,999999) | H10: =IF($F10>0,$E10,0)
A11: 45839 | B11: 2025-07 | C11: 2025 | D11: 7 | E11: 202507 | F11: =COUNTIF('DADM-01 EVASAO'!$A$5:$A$1200,$B11)+COUNTIF('DADM-09 CUSTOS'!$A$5:$A$1200,$B11)+COUNTIF('DADM-09 ALUNOS'!$A$5:$A$1200,$B11)+COUNTIF('DADM-10 INFRA'!$A$5:$A$1200,$B11) | G11: =IF($F11>0,$E11,999999) | H11: =IF($F11>0,$E11,0)
A12: 45870 | B12: 2025-08 | C12: 2025 | D12: 8 | E12: 202508 | F12: =COUNTIF('DADM-01 EVASAO'!$A$5:$A$1200,$B12)+COUNTIF('DADM-09 CUSTOS'!$A$5:$A$1200,$B12)+COUNTIF('DADM-09 ALUNOS'!$A$5:$A$1200,$B12)+COUNTIF('DADM-10 INFRA'!$A$5:$A$1200,$B12) | G12: =IF($F12>0,$E12,999999) | H12: =IF($F12>0,$E12,0)
A13: 45901 | B13: 2025-09 | C13: 2025 | D13: 9 | E13: 202509 | F13: =COUNTIF('DADM-01 EVASAO'!$A$5:$A$1200,$B13)+COUNTIF('DADM-09 CUSTOS'!$A$5:$A$1200,$B13)+COUNTIF('DADM-09 ALUNOS'!$A$5:$A$1200,$B13)+COUNTIF('DADM-10 INFRA'!$A$5:$A$1200,$B13) | G13: =IF($F13>0,$E13,999999) | H13: =IF($F13>0,$E13,0)
A14: 45931 | B14: 2025-10 | C14: 2025 | D14: 10 | E14: 202510 | F14: =COUNTIF('DADM-01 EVASAO'!$A$5:$A$1200,$B14)+COUNTIF('DADM-09 CUSTOS'!$A$5:$A$1200,$B14)+COUNTIF('DADM-09 ALUNOS'!$A$5:$A$1200,$B14)+COUNTIF('DADM-10 INFRA'!$A$5:$A$1200,$B14) | G14: =IF($F14>0,$E14,999999) | H14: =IF($F14>0,$E14,0)
A15: 45962 | B15: 2025-11 | C15: 2025 | D15: 11 | E15: 202511 | F15: =COUNTIF('DADM-01 EVASAO'!$A$5:$A$1200,$B15)+COUNTIF('DADM-09 CUSTOS'!$A$5:$A$1200,$B15)+COUNTIF('DADM-09 ALUNOS'!$A$5:$A$1200,$B15)+COUNTIF('DADM-10 INFRA'!$A$5:$A$1200,$B15) | G15: =IF($F15>0,$E15,999999) | H15: =IF($F15>0,$E15,0)
A16: 45992 | B16: 2025-12 | C16: 2025 | D16: 12 | E16: 202512 | F16: =COUNTIF('DADM-01 EVASAO'!$A$5:$A$1200,$B16)+COUNTIF('DADM-09 CUSTOS'!$A$5:$A$1200,$B16)+COUNTIF('DADM-09 ALUNOS'!$A$5:$A$1200,$B16)+COUNTIF('DADM-10 INFRA'!$A$5:$A$1200,$B16) | G16: =IF($F16>0,$E16,999999) | H16: =IF($F16>0,$E16,0)
... A148: 50010 | B148: 2036-12 | C148: 2036 | D148: 12 | E148: 203612 | F148: =COUNTIF('DADM-01 EVASAO'!$A$5:$A$1200,$B148)+COUNTIF('DADM-09 CUSTOS'!$A$5:$A$1200,$B148)+COUNTIF('DADM-09 ALUNOS'!$A$5:$A$1200,$B148)+COUNTIF('DADM-10 INFRA'!$A$5:$A$1200,$B148) | G148: =IF($F148>0,$E148,999999) | H148: =IF($F148>0,$E148,0)
