Workbook
Name LST_CURSOS: CURSOS!$A$5:$A$13
Name LST_CURSOS_FOCO: 'LISTAS DE APOIO'!$H$5:$H$14
Name LST_DISCIPLINAS: DISCIPLINAS!$B$5:$B$300
Name LST_DISCIPLINAS_FOCO: 'LISTAS DE APOIO'!$I$5:$I$305
Name LST_SEMESTRES: DIM_PERIODO!$A$5:$A$30
Name LST_MESES: DIM_MES!$B$5:$B$160

Sheet LEIA-ME
A1: PAINEL DE GESTÃO POR DADOS — DTNH · v0.5.8
A2: NPS discente · avaliação docente · aprovação, notas e motivos de reprovação
B4: 1. O arquivo segue o mesmo padrão do painel institucional
B5: As mesmas páginas do modelo-base foram preservadas. As três bases acadêmicas agora são NPS DISCENTES, AVALIAÇÃO DOCENTE e RESULTADOS ACADÊMICOS.
B8: 2. Visualização Semestral ou Mensal
B9: Em PARAMETROS, escolha Semestral ou Mensal. Avaliação docente e resultados acadêmicos são semestrais; na visão mensal o valor do semestre é repetido em seus seis meses (SEM1 = janeiro a junho; SEM2 = julho a dezembro).
B12: 3. NPS aceita origem mensal ou semestral
B13: Se houver NPS mensal, a visão mensal usa o mês real. Se a base tiver NPS semestral, o valor é projetado para os seis meses. Na visão semestral, um NPS mensal é consolidado no semestre. Não misture origem mensal e semestral para o mesmo curso e semestre.
B17: 4. Resultados acadêmicos preservam a situação oficial
B18: A nota média é analítica. Aprovado/Reprovado é derivado da situação oficial registrada; Reprovado Falta é separado de reprovação por nota.
B21: 5. Recortes
B22: O painel permite leitura consolidada, por curso e por disciplina. NPS é por curso; avaliação docente e resultados podem ser filtrados por curso e disciplina.
B25: 6. Dados e fórmulas
B26: Células amarelas/azuis são entradas. Fórmulas são pretas. Dados exportados do banco aparecem em verde. O Excel está configurado para recalcular ao abrir.
... B30: O site e o Excel usam a mesma lógica de visualização. O banco continua sendo a fonte oficial; a planilha é ferramenta de entrada, auditoria e exportação.

Sheet PARAMETROS
A1: PARÂMETROS DO PAINEL
A2: Células amarelas são editáveis. Visualização e períodos controlam todo o arquivo.
A4: SELEÇÃO
A5: Diretoria | B5: DTNH | D5: Visualização | E5: Semestral
A7: Período de referência | B7: 2026-SEM2 | D7: Período de comparação | E7: 2026-SEM1
A9: Janela — de | B9: 2026-SEM1 | D9: Janela — até | E9: 2026-SEM2
A11: Curso em foco | B11: (todos) | D11: Disciplina em foco | E11: (todas)
A13: PERÍODO DERIVADO
A14: Semestre da referência | B14: =IF($B$7="","",IF(ISNUMBER(SEARCH("-SEM",$B$7)),$B$7,LEFT($B$7,4)&"-SEM"&IF(VALUE(RIGHT($B$7,2))<=6,1,2))) | D14: Semestre da comparação | E14: =IF($E$7="","",IF(ISNUMBER(SEARCH("-SEM",$E$7)),$E$7,LEFT($E$7,4)&"-SEM"&IF(VALUE(RIGHT($E$7,2))<=6,1,2)))
A15: Meses do semestre | B15: =IF($B$14="","",IF(RIGHT($B$14,1)="1",LEFT($B$14,4)&"-01 a "&LEFT($B$14,4)&"-06",LEFT($B$14,4)&"-07 a "&LEFT($B$14,4)&"-12")) | D15: Regra mensal | E15: Dados semestrais são repetidos nos 6 meses
A18: DIAGNÓSTICO
A19: Linhas com erro — NPS | B19: =COUNTIFS(TabelaNPS[Validação da linha],"<>OK",TabelaNPS[Validação da linha],"<>")
A20: Linhas com erro — Avaliação | B20: =COUNTIFS(TabelaAvaliacaoDocente[Validação da linha],"<>OK",TabelaAvaliacaoDocente[Validação da linha],"<>")
A21: Linhas com erro — Resultados | B21: =COUNTIFS(TabelaResultadosAcademicos[Validação da linha],"<>OK",TabelaResultadosAcademicos[Validação da linha],"<>")
A22: Status geral | B22: =IF(SUM($B$19:$B$21)=0,"OK — bases consistentes","REVISAR — há linhas com erro")

Sheet PAINEL
A1: PAINEL DE GESTÃO — DTNH
A2: A mesma visão pode ser alternada entre Semestral e Mensal em PARAMETROS.
A4: Visualização | B4: =PARAMETROS!$E$5 | D4: Referência | E4: =PARAMETROS!$B$7 | G4: Comparação | H4: =PARAMETROS!$E$7 | J4: Curso / disciplina | K4: =PARAMETROS!$B$11&IF(PARAMETROS!$E$11="(todas)",""," · "&PARAMETROS!$E$11)
A7: DTNH-01 · NPS Discente
A8: Valor na referência | B8: Valor na comparação | C8: Variação | D8: Meta vigente | E8: Limiar de atenção | F8: Aprovados | G8: Rep. nota | H8: Rep. falta | I8: Média | J8: Status | K8: Lançamentos
A9: =CALC!$B$9 | B9: =CALC!$C$9 | C9: =CALC!$D$9 | D9: =CALC!$E$9 | E9: =CALC!$F$9 | J9: =CALC!$L$9 | K9: =CALC!$M$9
A11: Leitura temporal
A25: Curso | B25: NPS | C25: Aval. docente | D25: Aprovação | E25: Média | F25: Rep. nota | G25: Rep. falta
A26: =CALC!$A$17 | B26: =CALC!$E$17 | C26: =CALC!$J$17 | D26: =CALC!$K$17 | E26: =CALC!$L$17 | F26: =CALC!$M$17 | G26: =CALC!$N$17
A27: =CALC!$A$18 | B27: =CALC!$E$18 | C27: =CALC!$J$18 | D27: =CALC!$K$18 | E27: =CALC!$L$18 | F27: =CALC!$M$18 | G27: =CALC!$N$18
A28: =CALC!$A$19 | B28: =CALC!$E$19 | C28: =CALC!$J$19 | D28: =CALC!$K$19 | E28: =CALC!$L$19 | F28: =CALC!$M$19 | G28: =CALC!$N$19
A29: =CALC!$A$20 | B29: =CALC!$E$20 | C29: =CALC!$J$20 | D29: =CALC!$K$20 | E29: =CALC!$L$20 | F29: =CALC!$M$20 | G29: =CALC!$N$20
A30: =CALC!$A$21 | B30: =CALC!$E$21 | C30: =CALC!$J$21 | D30: =CALC!$K$21 | E30: =CALC!$L$21 | F30: =CALC!$M$21 | G30: =CALC!$N$21
A31: =CALC!$A$22 | B31: =CALC!$E$22 | C31: =CALC!$J$22 | D31: =CALC!$K$22 | E31: =CALC!$L$22 | F31: =CALC!$M$22 | G31: =CALC!$N$22
A32: =CALC!$A$23 | B32: =CALC!$E$23 | C32: =CALC!$J$23 | D32: =CALC!$K$23 | E32: =CALC!$L$23 | F32: =CALC!$M$23 | G32: =CALC!$N$23
A33: =CALC!$A$24 | B33: =CALC!$E$24 | C33: =CALC!$J$24 | D33: =CALC!$K$24 | E33: =CALC!$L$24 | F33: =CALC!$M$24 | G33: =CALC!$N$24
A34: =CALC!$A$25 | B34: =CALC!$E$25 | C34: =CALC!$J$25 | D34: =CALC!$K$25 | E34: =CALC!$L$25 | F34: =CALC!$M$25 | G34: =CALC!$N$25
A55: DTNH-02 · Avaliação Docente pelo Aluno
A56: Valor na referência | B56: Valor na comparação | C56: Variação | D56: Meta vigente | E56: Limiar de atenção | F56: Aprovados | G56: Rep. nota | H56: Rep. falta | I56: Média | J56: Status | K56: Lançamentos
A57: =CALC!$B$10 | B57: =CALC!$C$10 | C57: =CALC!$D$10 | D57: =CALC!$E$10 | E57: =CALC!$F$10 | J57: =CALC!$L$10 | K57: =CALC!$M$10
A59: Leitura temporal
A103: DTNH-03 · Aprovação e Desempenho Acadêmico
A104: Valor na referência | B104: Valor na comparação | C104: Variação | D104: Meta vigente | E104: Limiar de atenção | F104: Aprovados | G104: Rep. nota | H104: Rep. falta | I104: Média | J104: Status | K104: Lançamentos
A105: =CALC!$B$11 | B105: =CALC!$C$11 | C105: =CALC!$D$11 | D105: =CALC!$E$11 | E105: =CALC!$F$11 | F105: =CALC!$G$11 | G105: =CALC!$H$11 | H105: =CALC!$I$11 | I105: =CALC!$K$11 | J105: =CALC!$L$11 | K105: =CALC!$M$11
A107: Leitura temporal
A116: Aprovações | B116: =CALC!$G$11 | D116: Reprovação por nota | E116: =CALC!$H$11 | G116: Reprovação por falta | H116: =CALC!$I$11 | J116: Média das notas | K116: =CALC!$K$11
A122: Curso | B122: Disciplina | C122: Aprovados | D122: Rep. nota | E122: Rep. falta | F122: Outros | G122: Taxa | H122: Média | I122: Total
A123: =CALC!$A$32 | B123: =CALC!$B$32 | C123: =CALC!$C$32 | D123: =CALC!$D$32 | E123: =CALC!$E$32 | F123: =CALC!$F$32 | G123: =CALC!$G$32 | H123: =CALC!$H$32 | I123: =CALC!$I$32
A124: =CALC!$A$33 | B124: =CALC!$B$33 | C124: =CALC!$C$33 | D124: =CALC!$D$33 | E124: =CALC!$E$33 | F124: =CALC!$F$33 | G124: =CALC!$G$33 | H124: =CALC!$H$33 | I124: =CALC!$I$33
A125: =CALC!$A$34 | B125: =CALC!$B$34 | C125: =CALC!$C$34 | D125: =CALC!$D$34 | E125: =CALC!$E$34 | F125: =CALC!$F$34 | G125: =CALC!$G$34 | H125: =CALC!$H$34 | I125: =CALC!$I$34
A126: =CALC!$A$35 | B126: =CALC!$B$35 | C126: =CALC!$C$35 | D126: =CALC!$D$35 | E126: =CALC!$E$35 | F126: =CALC!$F$35 | G126: =CALC!$G$35 | H126: =CALC!$H$35 | I126: =CALC!$I$35
A127: =CALC!$A$36 | B127: =CALC!$B$36 | C127: =CALC!$C$36 | D127: =CALC!$D$36 | E127: =CALC!$E$36 | F127: =CALC!$F$36 | G127: =CALC!$G$36 | H127: =CALC!$H$36 | I127: =CALC!$I$36
A128: =CALC!$A$37 | B128: =CALC!$B$37 | C128: =CALC!$C$37 | D128: =CALC!$D$37 | E128: =CALC!$E$37 | F128: =CALC!$F$37 | G128: =CALC!$G$37 | H128: =CALC!$H$37 | I128: =CALC!$I$37
A129: =CALC!$A$38 | B129: =CALC!$B$38 | C129: =CALC!$C$38 | D129: =CALC!$D$38 | E129: =CALC!$E$38 | F129: =CALC!$F$38 | G129: =CALC!$G$38 | H129: =CALC!$H$38 | I129: =CALC!$I$38
A130: =CALC!$A$39 | B130: =CALC!$B$39 | C130: =CALC!$C$39 | D130: =CALC!$D$39 | E130: =CALC!$E$39 | F130: =CALC!$F$39 | G130: =CALC!$G$39 | H130: =CALC!$H$39 | I130: =CALC!$I$39
A131: =CALC!$A$40 | B131: =CALC!$B$40 | C131: =CALC!$C$40 | D131: =CALC!$D$40 | E131: =CALC!$E$40 | F131: =CALC!$F$40 | G131: =CALC!$G$40 | H131: =CALC!$H$40 | I131: =CALC!$I$40
A132: =CALC!$A$41 | B132: =CALC!$B$41 | C132: =CALC!$C$41 | D132: =CALC!$D$41 | E132: =CALC!$E$41 | F132: =CALC!$F$41 | G132: =CALC!$G$41 | H132: =CALC!$H$41 | I132: =CALC!$I$41
A133: =CALC!$A$42 | B133: =CALC!$B$42 | C133: =CALC!$C$42 | D133: =CALC!$D$42 | E133: =CALC!$E$42 | F133: =CALC!$F$42 | G133: =CALC!$G$42 | H133: =CALC!$H$42 | I133: =CALC!$I$42
A134: =CALC!$A$43 | B134: =CALC!$B$43 | C134: =CALC!$C$43 | D134: =CALC!$D$43 | E134: =CALC!$E$43 | F134: =CALC!$F$43 | G134: =CALC!$G$43 | H134: =CALC!$H$43 | I134: =CALC!$I$43
A135: =CALC!$A$44 | B135: =CALC!$B$44 | C135: =CALC!$C$44 | D135: =CALC!$D$44 | E135: =CALC!$E$44 | F135: =CALC!$F$44 | G135: =CALC!$G$44 | H135: =CALC!$H$44 | I135: =CALC!$I$44
...

Sheet QUALIDADE E GOVERNANÇA
A1: QUALIDADE E GOVERNANÇA
A2: Os cálculos abaixo ajudam a localizar erros de entrada antes da reunião de gestão.
A4: RESUMO DE QUALIDADE
A5: Base | B5: Linhas preenchidas | C5: Linhas OK | D5: Linhas com erro | E5: Regra principal | F5: Ação
A6: NPS DISCENTES | B6: =COUNTIF(TabelaNPS[Período],"<>") | C6: =COUNTIF(TabelaNPS[Validação da linha],"OK") | D6: =COUNTIFS(TabelaNPS[Validação da linha],"<>OK",TabelaNPS[Validação da linha],"<>") | E6: Respondentes = promotores + neutros + detratores | F6: Corrigir linha sinalizada
A7: AVALIAÇÃO DOCENTE | B7: =COUNTIF(TabelaAvaliacaoDocente[Período],"<>") | C7: =COUNTIF(TabelaAvaliacaoDocente[Validação da linha],"OK") | D7: =COUNTIFS(TabelaAvaliacaoDocente[Validação da linha],"<>OK",TabelaAvaliacaoDocente[Validação da linha],"<>") | E7: Nota entre 0 e 10; chave única por professor | F7: Corrigir linha sinalizada
A8: RESULTADOS ACADÊMICOS | B8: =COUNTIF(TabelaResultadosAcademicos[Período],"<>") | C8: =COUNTIF(TabelaResultadosAcademicos[Validação da linha],"OK") | D8: =COUNTIFS(TabelaResultadosAcademicos[Validação da linha],"<>OK",TabelaResultadosAcademicos[Validação da linha],"<>") | E8: Consolidação por semestre, curso e disciplina | F8: Revisar consolidação sinalizada
A11: Total de pendências | B11: =SUM(D6:D8)
A13: Regra mensal/semestral | B13: SEM1 corresponde a jan-jun; SEM2 a jul-dez. Na visão mensal, dados semestrais se repetem em cada mês do semestre.

Sheet MATRIZ
A1: MATRIZ DE DESEMPENHO — DTNH
A2: Curso × período para a taxa de aprovação; abaixo, disciplinas do curso em foco.
A4: Curso | B4: =CALC!$A$157 | C4: =CALC!$A$158 | D4: =CALC!$A$159 | E4: =CALC!$A$160 | F4: =CALC!$A$161 | G4: =CALC!$A$162 | H4: =CALC!$A$163 | I4: =CALC!$A$164 | J4: =CALC!$A$165 | K4: =CALC!$A$166 | L4: =CALC!$A$167 | M4: =CALC!$A$168 | N4: =CALC!$A$169 | O4: =CALC!$A$170 | P4: =CALC!$A$171 | Q4: =CALC!$A$172 | R4: =CALC!$A$173 | S4: =CALC!$A$174 | T4: =CALC!$A$175 | U4: =CALC!$A$176 | V4: =CALC!$A$177 | W4: =CALC!$A$178 | X4: =CALC!$A$179 | Y4: =CALC!$A$180
A5: Administração | B5: =IF(B4="","",IFERROR((SUMIFS(TabelaResultadosAcademicos[Aprovados],TabelaResultadosAcademicos[Período],(IF(B4="","",IF(ISNUMBER(SEARCH("-SEM",B4)),B4,LEFT(B4,4)&"-SEM"&IF(VALUE(RIGHT(B4,2))<=6,1,2)))),TabelaResultadosAcademicos[Curso],IF($A5="(todos)","*",$A5),TabelaResultadosAcademicos[Disciplina],IF("(todas)"="(todas)","*","(todas)")))/((SUMIFS(TabelaResultadosAcademicos[Aprovados],TabelaResultadosAcademicos[Período],(IF(B4="","",IF(ISNUMBER(SEARCH("-SEM",B4)),B4,LEFT(B4,4)&"-SEM"&IF(VALUE(RIGHT(B4,2))<=6,1,2)))),TabelaResultadosAcademicos[Curso],IF($A5="(todos)","*",$A5),TabelaResultadosAcademicos[Disciplina],IF("(todas)"="(todas)","*","(todas)")))+(SUMIFS(TabelaResultadosAcademicos[Reprovados],TabelaResultadosAcademicos[Período],(IF(B4="","",IF(ISNUMBER(SEARCH("-SEM",B4)),B4,LEFT(B4,4)&"-SEM"&IF(VALUE(RIGHT(B4,2))<=6,1,2)))),TabelaResultadosAcademicos[Curso],IF($A5="(todos)","*",$A5),TabelaResultadosAcademicos[Disciplina],IF("(todas)"="(todas)","*","(todas)"))))*100,"")) | C5: =IF(C4="","",IFERROR((SUMIFS(TabelaResultadosAcademicos[Aprovados],TabelaResultadosAcademicos[Período],(IF(C4="","",IF(ISNUMBER(SEARCH("-SEM",C4)),C4,LEFT(C4,4)&"-SEM"&IF(VALUE(RIGHT(C4,2))<=6,1,2)))),TabelaResultadosAcademicos[Curso],IF($A5="(todos)","*",$A5),TabelaResultadosAcademicos[Disciplina],IF("(todas)"="(todas)","*","(todas)")))/((SUMIFS(TabelaResultadosAcademicos[Aprovados],TabelaResultadosAcademicos[Período],(IF(C4="","",IF(ISNUMBER(SEARCH("-SEM",C4)),C4,LEFT(C4,4)&"-SEM"&IF(VALUE(RIGHT(C4,2))<=6,1,2)))),TabelaResultadosAcademicos[Curso],IF($A5="(todos)","*",$A5),TabelaResultadosAcademicos[Disciplina],IF("(todas)"="(todas)","*","(todas)")))+(SUMIFS(TabelaResultadosAcademicos[Reprovados],TabelaResultadosAcademicos[Período],(IF(C4="","",IF(ISNUMBER(SEARCH("-SEM",C4)),C4,LEFT(C4,4)&"-SEM"&IF(VALUE(RIGHT(C4,2))<=6,1,2)))),TabelaResultadosAcademicos[Curso],IF($A5="(todos)","*",$A5),TabelaResultadosAcademicos[Disciplina],IF("(todas)"="(todas)","*","(todas)"))))*100,"")) | D5: =IF(D4="","",IFERROR((SUMIFS(TabelaResultadosAcademicos[Aprovados],TabelaResultadosAcademicos[Período],(IF(D4="","",IF(ISNUMBER(SEARCH("-SEM",D4)),D4,LEFT(D4,4)&"-SEM"&IF(VALUE(RIGHT(D4,2))<=6,1,2)))),TabelaResultadosAcademicos[Curso],IF($A5="(todos)","*",$A5),TabelaResultadosAcademicos[Disciplina],IF("(todas)"="(todas)","*","(todas)")))/((SUMIFS(TabelaResultadosAcademicos[Aprovados],TabelaResultadosAcademicos[Período],(IF(D4="","",IF(ISNUMBER(SEARCH("-SEM",D4)),D4,LEFT(D4,4)&"-SEM"&IF(VALUE(RIGHT(D4,2))<=6,1,2)))),TabelaResultadosAcademicos[Curso],IF($A5="(todos)","*",$A5),TabelaResultadosAcademicos[Disciplina],IF("(todas)"="(todas)","*","(todas)")))+(SUMIFS(TabelaResultadosAcademicos[Reprovados],TabelaResultadosAcademicos[Período],(IF(D4="","",IF(ISNUMBER(SEARCH("-SEM",D4)),D4,LEFT(D4,4)&"-SEM"&IF(VALUE(RIGHT(D4,2))<=6,1,2)))),TabelaResultadosAcademicos[Curso],IF($A5="(todos)","*",$A5),TabelaResultadosAcademicos[Disciplina],IF("(todas)"="(todas)","*","(todas)"))))*100,"")) | E5: =IF(E4="","",IFERROR((SUMIFS(TabelaResultadosAcademicos[Aprovados],TabelaResultadosAcademicos[Período],(IF(E4="","",IF(ISNUMBER(SEARCH("-SEM",E4)),E4,LEFT(E4,4)&"-SEM"&IF(VALUE(RIGHT(E4,2))<=6,1,2)))),TabelaResultadosAcademicos[Curso],IF($A5="(todos)","*",$A5),TabelaResultadosAcademicos[Disciplina],IF("(todas)"="(todas)","*","(todas)")))/((SUMIFS(TabelaResultadosAcademicos[Aprovados],TabelaResultadosAcademicos[Período],(IF(E4="","",IF(ISNUMBER(SEARCH("-SEM",E4)),E4,LEFT(E4,4)&"-SEM"&IF(VALUE(RIGHT(E4,2))<=6,1,2)))),TabelaResultadosAcademicos[Curso],IF($A5="(todos)","*",$A5),TabelaResultadosAcademicos[Disciplina],IF("(todas)"="(todas)","*","(todas)")))+(SUMIFS(TabelaResultadosAcademicos[Reprovados],TabelaResultadosAcademicos[Período],(IF(E4="","",IF(ISNUMBER(SEARCH("-SEM",E4)),E4,LEFT(E4,4)&"-SEM"&IF(VALUE(RIGHT(E4,2))<=6,1,2)))),TabelaResultadosAcademicos[Curso],IF($A5="(todos)","*",$A5),TabelaResultadosAcademicos[Disciplina],IF("(todas)"="(todas)","*","(todas)"))))*100,"")) | F5: =IF(F4="","",IFERROR((SUMIFS(TabelaResultadosAcademicos[Aprovados],TabelaResultadosAcademicos[Período],(IF(F4="","",IF(ISNUMBER(SEARCH("-SEM",F4)),F4,LEFT(F4,4)&"-SEM"&IF(VALUE(RIGHT(F4,2))<=6,1,2)))),TabelaResultadosAcademicos[Curso],IF($A5="(todos)","*",$A5),TabelaResultadosAcademicos[Disciplina],IF("(todas)"="(todas)","*","(todas)")))/((SUMIFS(TabelaResultadosAcademicos[Aprovados],TabelaResultadosAcademicos[Período],(IF(F4="","",IF(ISNUMBER(SEARCH("-SEM",F4)),F4,LEFT(F4,4)&"-SEM"&IF(VALUE(RIGHT(F4,2))<=6,1,2)))),TabelaResultadosAcademicos[Curso],IF($A5="(todos)","*",$A5),TabelaResultadosAcademicos[Disciplina],IF("(todas)"="(todas)","*","(todas)")))+(SUMIFS(TabelaResultadosAcademicos[Reprovados],TabelaResultadosAcademicos[Período],(IF(F4="","",IF(ISNUMBER(SEARCH("-SEM",F4)),F4,LEFT(F4,4)&"-SEM"&IF(VALUE(RIGHT(F4,2))<=6,1,2)))),TabelaResultadosAcademicos[Curso],IF($A5="(todos)","*",$A5),TabelaResultadosAcademicos[Disciplina],IF("(todas)"="(todas)","*","(todas)"))))*100,"")) | G5: =IF(G4="","",IFERROR((SUMIFS(TabelaResultadosAcademicos[Aprovados],TabelaResultadosAcademicos[Período],(IF(G4="","",IF(ISNUMBER(SEARCH("-SEM",G4)),G4,LEFT(G4,4)&"-SEM"&IF(VALUE(RIGHT(G4,2))<=6,1,2)))),TabelaResultadosAcademicos[Curso],IF($A5="(todos)","*",$A5),TabelaResultadosAcademicos[Disciplina],IF("(todas)"="(todas)","*","(todas)")))/((SUMIFS(TabelaResultadosAcademicos[Aprovados],TabelaResultadosAcademicos[Período],(IF(G4="","",IF(ISNUMBER(SEARCH("-SEM",G4)),G4,LEFT(G4,4)&"-SEM"&IF(VALUE(RIGHT(G4,2))<=6,1,2)))),TabelaResultadosAcademicos[Curso],IF($A5="(todos)","*",$A5),TabelaResultadosAcademicos[Disciplina],IF("(todas)"="(todas)","*","(todas)")))+(SUMIFS(TabelaResultadosAcademicos[Reprovados],TabelaResultadosAcademicos[Período],(IF(G4="","",IF(ISNUMBER(SEARCH("-SEM",G4)),G4,LEFT(G4,4)&"-SEM"&IF(VALUE(RIGHT(G4,2))<=6,1,2)))),TabelaResultadosAcademicos[Curso],IF($A5="(todos)","*",$A5),TabelaResultadosAcademicos[Disciplina],IF("(todas)"="(todas)","*","(todas)"))))*100,"")) | H5: =IF(H4="","",IFERROR((SUMIFS(TabelaResultadosAcademicos[Aprovados],TabelaResultadosAcademicos[Período],(IF(H4="","",IF(ISNUMBER(SEARCH("-SEM",H4)),H4,LEFT(H4,4)&"-SEM"&IF(VALUE(RIGHT(H4,2))<=6,1,2)))),TabelaResultadosAcademicos[Curso],IF($A5="(todos)","*",$A5),TabelaResultadosAcademicos[Disciplina],IF("(todas)"="(todas)","*","(todas)")))/((SUMIFS(TabelaResultadosAcademicos[Aprovados],TabelaResultadosAcademicos[Período],(IF(H4="","",IF(ISNUMBER(SEARCH("-SEM",H4)),H4,LEFT(H4,4)&"-SEM"&IF(VALUE(RIGHT(H4,2))<=6,1,2)))),TabelaResultadosAcademicos[Curso],IF($A5="(todos)","*",$A5),TabelaResultadosAcademicos[Disciplina],IF("(todas)"="(todas)","*","(todas)")))+(SUMIFS(TabelaResultadosAcademicos[Reprovados],TabelaResultadosAcademicos[Período],(IF(H4="","",IF(ISNUMBER(SEARCH("-SEM",H4)),H4,LEFT(H4,4)&"-SEM"&IF(VALUE(RIGHT(H4,2))<=6,1,2)))),TabelaResultadosAcademicos[Curso],IF($A5="(todos)","*",$A5),TabelaResultadosAcademicos[Disciplina],IF("(todas)"="(todas)","*","(todas)"))))*100,"")) | I5: =IF(I4="","",IFERROR((SUMIFS(TabelaResultadosAcademicos[Aprovados],TabelaResultadosAcademicos[Período],(IF(I4="","",IF(ISNUMBER(SEARCH("-SEM",I4)),I4,LEFT(I4,4)&"-SEM"&IF(VALUE(RIGHT(I4,2))<=6,1,2)))),TabelaResultadosAcademicos[Curso],IF($A5="(todos)","*",$A5),TabelaResultadosAcademicos[Disciplina],IF("(todas)"="(todas)","*","(todas)")))/((SUMIFS(TabelaResultadosAcademicos[Aprovados],TabelaResultadosAcademicos[Período],(IF(I4="","",IF(ISNUMBER(SEARCH("-SEM",I4)),I4,LEFT(I4,4)&"-SEM"&IF(VALUE(RIGHT(I4,2))<=6,1,2)))),TabelaResultadosAcademicos[Curso],IF($A5="(todos)","*",$A5),TabelaResultadosAcademicos[Disciplina],IF("(todas)"="(todas)","*","(todas)")))+(SUMIFS(TabelaResultadosAcademicos[Reprovados],TabelaResultadosAcademicos[Período],(IF(I4="","",IF(ISNUMBER(SEARCH("-SEM",I4)),I4,LEFT(I4,4)&"-SEM"&IF(VALUE(RIGHT(I4,2))<=6,1,2)))),TabelaResultadosAcademicos[Curso],IF($A5="(todos)","*",$A5),TabelaResultadosAcademicos[Disciplina],IF("(todas)"="(todas)","*","(todas)"))))*100,"")) | ... Y5: =IF(Y4="","",IFERROR((SUMIFS(TabelaResultadosAcademicos[Aprovados],TabelaResultadosAcademicos[Período],(IF(Y4="","",IF(ISNUMBER(SEARCH("-SEM",Y4)),Y4,LEFT(Y4,4)&"-SEM"&IF(VALUE(RIGHT(Y4,2))<=6,1,2)))),TabelaResultadosAcademicos[Curso],IF($A5="(todos)","*",$A5),TabelaResultadosAcademicos[Disciplina],IF("(todas)"="(todas)","*","(todas)")))/((SUMIFS(TabelaResultadosAcademicos[Aprovados],TabelaResultadosAcademicos[Período],(IF(Y4="","",IF(ISNUMBER(SEARCH("-SEM",Y4)),Y4,LEFT(Y4,4)&"-SEM"&IF(VALUE(RIGHT(Y4,2))<=6,1,2)))),TabelaResultadosAcademicos[Curso],IF($A5="(todos)","*",$A5),TabelaResultadosAcademicos[Disciplina],IF("(todas)"="(todas)","*","(todas)")))+(SUMIFS(TabelaResultadosAcademicos[Reprovados],TabelaResultadosAcademicos[Período],(IF(Y4="","",IF(ISNUMBER(SEARCH("-SEM",Y4)),Y4,LEFT(Y4,4)&"-SEM"&IF(VALUE(RIGHT(Y4,2))<=6,1,2)))),TabelaResultadosAcademicos[Curso],IF($A5="(todos)","*",$A5),TabelaResultadosAcademicos[Disciplina],IF("(todas)"="(todas)","*","(todas)"))))*100,""))
A6: Análise e Desenvolvimento de Sistemas | B6: =IF(B4="","",IFERROR((SUMIFS(TabelaResultadosAcademicos[Aprovados],TabelaResultadosAcademicos[Período],(IF(B4="","",IF(ISNUMBER(SEARCH("-SEM",B4)),B4,LEFT(B4,4)&"-SEM"&IF(VALUE(RIGHT(B4,2))<=6,1,2)))),TabelaResultadosAcademicos[Curso],IF($A6="(todos)","*",$A6),TabelaResultadosAcademicos[Disciplina],IF("(todas)"="(todas)","*","(todas)")))/((SUMIFS(TabelaResultadosAcademicos[Aprovados],TabelaResultadosAcademicos[Período],(IF(B4="","",IF(ISNUMBER(SEARCH("-SEM",B4)),B4,LEFT(B4,4)&"-SEM"&IF(VALUE(RIGHT(B4,2))<=6,1,2)))),TabelaResultadosAcademicos[Curso],IF($A6="(todos)","*",$A6),TabelaResultadosAcademicos[Disciplina],IF("(todas)"="(todas)","*","(todas)")))+(SUMIFS(TabelaResultadosAcademicos[Reprovados],TabelaResultadosAcademicos[Período],(IF(B4="","",IF(ISNUMBER(SEARCH("-SEM",B4)),B4,LEFT(B4,4)&"-SEM"&IF(VALUE(RIGHT(B4,2))<=6,1,2)))),TabelaResultadosAcademicos[Curso],IF($A6="(todos)","*",$A6),TabelaResultadosAcademicos[Disciplina],IF("(todas)"="(todas)","*","(todas)"))))*100,"")) | C6: =IF(C4="","",IFERROR((SUMIFS(TabelaResultadosAcademicos[Aprovados],TabelaResultadosAcademicos[Período],(IF(C4="","",IF(ISNUMBER(SEARCH("-SEM",C4)),C4,LEFT(C4,4)&"-SEM"&IF(VALUE(RIGHT(C4,2))<=6,1,2)))),TabelaResultadosAcademicos[Curso],IF($A6="(todos)","*",$A6),TabelaResultadosAcademicos[Disciplina],IF("(todas)"="(todas)","*","(todas)")))/((SUMIFS(TabelaResultadosAcademicos[Aprovados],TabelaResultadosAcademicos[Período],(IF(C4="","",IF(ISNUMBER(SEARCH("-SEM",C4)),C4,LEFT(C4,4)&"-SEM"&IF(VALUE(RIGHT(C4,2))<=6,1,2)))),TabelaResultadosAcademicos[Curso],IF($A6="(todos)","*",$A6),TabelaResultadosAcademicos[Disciplina],IF("(todas)"="(todas)","*","(todas)")))+(SUMIFS(TabelaResultadosAcademicos[Reprovados],TabelaResultadosAcademicos[Período],(IF(C4="","",IF(ISNUMBER(SEARCH("-SEM",C4)),C4,LEFT(C4,4)&"-SEM"&IF(VALUE(RIGHT(C4,2))<=6,1,2)))),TabelaResultadosAcademicos[Curso],IF($A6="(todos)","*",$A6),TabelaResultadosAcademicos[Disciplina],IF("(todas)"="(todas)","*","(todas)"))))*100,"")) | D6: =IF(D4="","",IFERROR((SUMIFS(TabelaResultadosAcademicos[Aprovados],TabelaResultadosAcademicos[Período],(IF(D4="","",IF(ISNUMBER(SEARCH("-SEM",D4)),D4,LEFT(D4,4)&"-SEM"&IF(VALUE(RIGHT(D4,2))<=6,1,2)))),TabelaResultadosAcademicos[Curso],IF($A6="(todos)","*",$A6),TabelaResultadosAcademicos[Disciplina],IF("(todas)"="(todas)","*","(todas)")))/((SUMIFS(TabelaResultadosAcademicos[Aprovados],TabelaResultadosAcademicos[Período],(IF(D4="","",IF(ISNUMBER(SEARCH("-SEM",D4)),D4,LEFT(D4,4)&"-SEM"&IF(VALUE(RIGHT(D4,2))<=6,1,2)))),TabelaResultadosAcademicos[Curso],IF($A6="(todos)","*",$A6),TabelaResultadosAcademicos[Disciplina],IF("(todas)"="(todas)","*","(todas)")))+(SUMIFS(TabelaResultadosAcademicos[Reprovados],TabelaResultadosAcademicos[Período],(IF(D4="","",IF(ISNUMBER(SEARCH("-SEM",D4)),D4,LEFT(D4,4)&"-SEM"&IF(VALUE(RIGHT(D4,2))<=6,1,2)))),TabelaResultadosAcademicos[Curso],IF($A6="(todos)","*",$A6),TabelaResultadosAcademicos[Disciplina],IF("(todas)"="(todas)","*","(todas)"))))*100,"")) | E6: =IF(E4="","",IFERROR((SUMIFS(TabelaResultadosAcademicos[Aprovados],TabelaResultadosAcademicos[Período],(IF(E4="","",IF(ISNUMBER(SEARCH("-SEM",E4)),E4,LEFT(E4,4)&"-SEM"&IF(VALUE(RIGHT(E4,2))<=6,1,2)))),TabelaResultadosAcademicos[Curso],IF($A6="(todos)","*",$A6),TabelaResultadosAcademicos[Disciplina],IF("(todas)"="(todas)","*","(todas)")))/((SUMIFS(TabelaResultadosAcademicos[Aprovados],TabelaResultadosAcademicos[Período],(IF(E4="","",IF(ISNUMBER(SEARCH("-SEM",E4)),E4,LEFT(E4,4)&"-SEM"&IF(VALUE(RIGHT(E4,2))<=6,1,2)))),TabelaResultadosAcademicos[Curso],IF($A6="(todos)","*",$A6),TabelaResultadosAcademicos[Disciplina],IF("(todas)"="(todas)","*","(todas)")))+(SUMIFS(TabelaResultadosAcademicos[Reprovados],TabelaResultadosAcademicos[Período],(IF(E4="","",IF(ISNUMBER(SEARCH("-SEM",E4)),E4,LEFT(E4,4)&"-SEM"&IF(VALUE(RIGHT(E4,2))<=6,1,2)))),TabelaResultadosAcademicos[Curso],IF($A6="(todos)","*",$A6),TabelaResultadosAcademicos[Disciplina],IF("(todas)"="(todas)","*","(todas)"))))*100,"")) | F6: =IF(F4="","",IFERROR((SUMIFS(TabelaResultadosAcademicos[Aprovados],TabelaResultadosAcademicos[Período],(IF(F4="","",IF(ISNUMBER(SEARCH("-SEM",F4)),F4,LEFT(F4,4)&"-SEM"&IF(VALUE(RIGHT(F4,2))<=6,1,2)))),TabelaResultadosAcademicos[Curso],IF($A6="(todos)","*",$A6),TabelaResultadosAcademicos[Disciplina],IF("(todas)"="(todas)","*","(todas)")))/((SUMIFS(TabelaResultadosAcademicos[Aprovados],TabelaResultadosAcademicos[Período],(IF(F4="","",IF(ISNUMBER(SEARCH("-SEM",F4)),F4,LEFT(F4,4)&"-SEM"&IF(VALUE(RIGHT(F4,2))<=6,1,2)))),TabelaResultadosAcademicos[Curso],IF($A6="(todos)","*",$A6),TabelaResultadosAcademicos[Disciplina],IF("(todas)"="(todas)","*","(todas)")))+(SUMIFS(TabelaResultadosAcademicos[Reprovados],TabelaResultadosAcademicos[Período],(IF(F4="","",IF(ISNUMBER(SEARCH("-SEM",F4)),F4,LEFT(F4,4)&"-SEM"&IF(VALUE(RIGHT(F4,2))<=6,1,2)))),TabelaResultadosAcademicos[Curso],IF($A6="(todos)","*",$A6),TabelaResultadosAcademicos[Disciplina],IF("(todas)"="(todas)","*","(todas)"))))*100,"")) | G6: =IF(G4="","",IFERROR((SUMIFS(TabelaResultadosAcademicos[Aprovados],TabelaResultadosAcademicos[Período],(IF(G4="","",IF(ISNUMBER(SEARCH("-SEM",G4)),G4,LEFT(G4,4)&"-SEM"&IF(VALUE(RIGHT(G4,2))<=6,1,2)))),TabelaResultadosAcademicos[Curso],IF($A6="(todos)","*",$A6),TabelaResultadosAcademicos[Disciplina],IF("(todas)"="(todas)","*","(todas)")))/((SUMIFS(TabelaResultadosAcademicos[Aprovados],TabelaResultadosAcademicos[Período],(IF(G4="","",IF(ISNUMBER(SEARCH("-SEM",G4)),G4,LEFT(G4,4)&"-SEM"&IF(VALUE(RIGHT(G4,2))<=6,1,2)))),TabelaResultadosAcademicos[Curso],IF($A6="(todos)","*",$A6),TabelaResultadosAcademicos[Disciplina],IF("(todas)"="(todas)","*","(todas)")))+(SUMIFS(TabelaResultadosAcademicos[Reprovados],TabelaResultadosAcademicos[Período],(IF(G4="","",IF(ISNUMBER(SEARCH("-SEM",G4)),G4,LEFT(G4,4)&"-SEM"&IF(VALUE(RIGHT(G4,2))<=6,1,2)))),TabelaResultadosAcademicos[Curso],IF($A6="(todos)","*",$A6),TabelaResultadosAcademicos[Disciplina],IF("(todas)"="(todas)","*","(todas)"))))*100,"")) | H6: =IF(H4="","",IFERROR((SUMIFS(TabelaResultadosAcademicos[Aprovados],TabelaResultadosAcademicos[Período],(IF(H4="","",IF(ISNUMBER(SEARCH("-SEM",H4)),H4,LEFT(H4,4)&"-SEM"&IF(VALUE(RIGHT(H4,2))<=6,1,2)))),TabelaResultadosAcademicos[Curso],IF($A6="(todos)","*",$A6),TabelaResultadosAcademicos[Disciplina],IF("(todas)"="(todas)","*","(todas)")))/((SUMIFS(TabelaResultadosAcademicos[Aprovados],TabelaResultadosAcademicos[Período],(IF(H4="","",IF(ISNUMBER(SEARCH("-SEM",H4)),H4,LEFT(H4,4)&"-SEM"&IF(VALUE(RIGHT(H4,2))<=6,1,2)))),TabelaResultadosAcademicos[Curso],IF($A6="(todos)","*",$A6),TabelaResultadosAcademicos[Disciplina],IF("(todas)"="(todas)","*","(todas)")))+(SUMIFS(TabelaResultadosAcademicos[Reprovados],TabelaResultadosAcademicos[Período],(IF(H4="","",IF(ISNUMBER(SEARCH("-SEM",H4)),H4,LEFT(H4,4)&"-SEM"&IF(VALUE(RIGHT(H4,2))<=6,1,2)))),TabelaResultadosAcademicos[Curso],IF($A6="(todos)","*",$A6),TabelaResultadosAcademicos[Disciplina],IF("(todas)"="(todas)","*","(todas)"))))*100,"")) | I6: =IF(I4="","",IFERROR((SUMIFS(TabelaResultadosAcademicos[Aprovados],TabelaResultadosAcademicos[Período],(IF(I4="","",IF(ISNUMBER(SEARCH("-SEM",I4)),I4,LEFT(I4,4)&"-SEM"&IF(VALUE(RIGHT(I4,2))<=6,1,2)))),TabelaResultadosAcademicos[Curso],IF($A6="(todos)","*",$A6),TabelaResultadosAcademicos[Disciplina],IF("(todas)"="(todas)","*","(todas)")))/((SUMIFS(TabelaResultadosAcademicos[Aprovados],TabelaResultadosAcademicos[Período],(IF(I4="","",IF(ISNUMBER(SEARCH("-SEM",I4)),I4,LEFT(I4,4)&"-SEM"&IF(VALUE(RIGHT(I4,2))<=6,1,2)))),TabelaResultadosAcademicos[Curso],IF($A6="(todos)","*",$A6),TabelaResultadosAcademicos[Disciplina],IF("(todas)"="(todas)","*","(todas)")))+(SUMIFS(TabelaResultadosAcademicos[Reprovados],TabelaResultadosAcademicos[Período],(IF(I4="","",IF(ISNUMBER(SEARCH("-SEM",I4)),I4,LEFT(I4,4)&"-SEM"&IF(VALUE(RIGHT(I4,2))<=6,1,2)))),TabelaResultadosAcademicos[Curso],IF($A6="(todos)","*",$A6),TabelaResultadosAcademicos[Disciplina],IF("(todas)"="(todas)","*","(todas)"))))*100,"")) | ... Y6: =IF(Y4="","",IFERROR((SUMIFS(TabelaResultadosAcademicos[Aprovados],TabelaResultadosAcademicos[Período],(IF(Y4="","",IF(ISNUMBER(SEARCH("-SEM",Y4)),Y4,LEFT(Y4,4)&"-SEM"&IF(VALUE(RIGHT(Y4,2))<=6,1,2)))),TabelaResultadosAcademicos[Curso],IF($A6="(todos)","*",$A6),TabelaResultadosAcademicos[Disciplina],IF("(todas)"="(todas)","*","(todas)")))/((SUMIFS(TabelaResultadosAcademicos[Aprovados],TabelaResultadosAcademicos[Período],(IF(Y4="","",IF(ISNUMBER(SEARCH("-SEM",Y4)),Y4,LEFT(Y4,4)&"-SEM"&IF(VALUE(RIGHT(Y4,2))<=6,1,2)))),TabelaResultadosAcademicos[Curso],IF($A6="(todos)","*",$A6),TabelaResultadosAcademicos[Disciplina],IF("(todas)"="(todas)","*","(todas)")))+(SUMIFS(TabelaResultadosAcademicos[Reprovados],TabelaResultadosAcademicos[Período],(IF(Y4="","",IF(ISNUMBER(SEARCH("-SEM",Y4)),Y4,LEFT(Y4,4)&"-SEM"&IF(VALUE(RIGHT(Y4,2))<=6,1,2)))),TabelaResultadosAcademicos[Curso],IF($A6="(todos)","*",$A6),TabelaResultadosAcademicos[Disciplina],IF("(todas)"="(todas)","*","(todas)"))))*100,""))
A7: Agronomia | B7: =IF(B4="","",IFERROR((SUMIFS(TabelaResultadosAcademicos[Aprovados],TabelaResultadosAcademicos[Período],(IF(B4="","",IF(ISNUMBER(SEARCH("-SEM",B4)),B4,LEFT(B4,4)&"-SEM"&IF(VALUE(RIGHT(B4,2))<=6,1,2)))),TabelaResultadosAcademicos[Curso],IF($A7="(todos)","*",$A7),TabelaResultadosAcademicos[Disciplina],IF("(todas)"="(todas)","*","(todas)")))/((SUMIFS(TabelaResultadosAcademicos[Aprovados],TabelaResultadosAcademicos[Período],(IF(B4="","",IF(ISNUMBER(SEARCH("-SEM",B4)),B4,LEFT(B4,4)&"-SEM"&IF(VALUE(RIGHT(B4,2))<=6,1,2)))),TabelaResultadosAcademicos[Curso],IF($A7="(todos)","*",$A7),TabelaResultadosAcademicos[Disciplina],IF("(todas)"="(todas)","*","(todas)")))+(SUMIFS(TabelaResultadosAcademicos[Reprovados],TabelaResultadosAcademicos[Período],(IF(B4="","",IF(ISNUMBER(SEARCH("-SEM",B4)),B4,LEFT(B4,4)&"-SEM"&IF(VALUE(RIGHT(B4,2))<=6,1,2)))),TabelaResultadosAcademicos[Curso],IF($A7="(todos)","*",$A7),TabelaResultadosAcademicos[Disciplina],IF("(todas)"="(todas)","*","(todas)"))))*100,"")) | C7: =IF(C4="","",IFERROR((SUMIFS(TabelaResultadosAcademicos[Aprovados],TabelaResultadosAcademicos[Período],(IF(C4="","",IF(ISNUMBER(SEARCH("-SEM",C4)),C4,LEFT(C4,4)&"-SEM"&IF(VALUE(RIGHT(C4,2))<=6,1,2)))),TabelaResultadosAcademicos[Curso],IF($A7="(todos)","*",$A7),TabelaResultadosAcademicos[Disciplina],IF("(todas)"="(todas)","*","(todas)")))/((SUMIFS(TabelaResultadosAcademicos[Aprovados],TabelaResultadosAcademicos[Período],(IF(C4="","",IF(ISNUMBER(SEARCH("-SEM",C4)),C4,LEFT(C4,4)&"-SEM"&IF(VALUE(RIGHT(C4,2))<=6,1,2)))),TabelaResultadosAcademicos[Curso],IF($A7="(todos)","*",$A7),TabelaResultadosAcademicos[Disciplina],IF("(todas)"="(todas)","*","(todas)")))+(SUMIFS(TabelaResultadosAcademicos[Reprovados],TabelaResultadosAcademicos[Período],(IF(C4="","",IF(ISNUMBER(SEARCH("-SEM",C4)),C4,LEFT(C4,4)&"-SEM"&IF(VALUE(RIGHT(C4,2))<=6,1,2)))),TabelaResultadosAcademicos[Curso],IF($A7="(todos)","*",$A7),TabelaResultadosAcademicos[Disciplina],IF("(todas)"="(todas)","*","(todas)"))))*100,"")) | D7: =IF(D4="","",IFERROR((SUMIFS(TabelaResultadosAcademicos[Aprovados],TabelaResultadosAcademicos[Período],(IF(D4="","",IF(ISNUMBER(SEARCH("-SEM",D4)),D4,LEFT(D4,4)&"-SEM"&IF(VALUE(RIGHT(D4,2))<=6,1,2)))),TabelaResultadosAcademicos[Curso],IF($A7="(todos)","*",$A7),TabelaResultadosAcademicos[Disciplina],IF("(todas)"="(todas)","*","(todas)")))/((SUMIFS(TabelaResultadosAcademicos[Aprovados],TabelaResultadosAcademicos[Período],(IF(D4="","",IF(ISNUMBER(SEARCH("-SEM",D4)),D4,LEFT(D4,4)&"-SEM"&IF(VALUE(RIGHT(D4,2))<=6,1,2)))),TabelaResultadosAcademicos[Curso],IF($A7="(todos)","*",$A7),TabelaResultadosAcademicos[Disciplina],IF("(todas)"="(todas)","*","(todas)")))+(SUMIFS(TabelaResultadosAcademicos[Reprovados],TabelaResultadosAcademicos[Período],(IF(D4="","",IF(ISNUMBER(SEARCH("-SEM",D4)),D4,LEFT(D4,4)&"-SEM"&IF(VALUE(RIGHT(D4,2))<=6,1,2)))),TabelaResultadosAcademicos[Curso],IF($A7="(todos)","*",$A7),TabelaResultadosAcademicos[Disciplina],IF("(todas)"="(todas)","*","(todas)"))))*100,"")) | E7: =IF(E4="","",IFERROR((SUMIFS(TabelaResultadosAcademicos[Aprovados],TabelaResultadosAcademicos[Período],(IF(E4="","",IF(ISNUMBER(SEARCH("-SEM",E4)),E4,LEFT(E4,4)&"-SEM"&IF(VALUE(RIGHT(E4,2))<=6,1,2)))),TabelaResultadosAcademicos[Curso],IF($A7="(todos)","*",$A7),TabelaResultadosAcademicos[Disciplina],IF("(todas)"="(todas)","*","(todas)")))/((SUMIFS(TabelaResultadosAcademicos[Aprovados],TabelaResultadosAcademicos[Período],(IF(E4="","",IF(ISNUMBER(SEARCH("-SEM",E4)),E4,LEFT(E4,4)&"-SEM"&IF(VALUE(RIGHT(E4,2))<=6,1,2)))),TabelaResultadosAcademicos[Curso],IF($A7="(todos)","*",$A7),TabelaResultadosAcademicos[Disciplina],IF("(todas)"="(todas)","*","(todas)")))+(SUMIFS(TabelaResultadosAcademicos[Reprovados],TabelaResultadosAcademicos[Período],(IF(E4="","",IF(ISNUMBER(SEARCH("-SEM",E4)),E4,LEFT(E4,4)&"-SEM"&IF(VALUE(RIGHT(E4,2))<=6,1,2)))),TabelaResultadosAcademicos[Curso],IF($A7="(todos)","*",$A7),TabelaResultadosAcademicos[Disciplina],IF("(todas)"="(todas)","*","(todas)"))))*100,"")) | F7: =IF(F4="","",IFERROR((SUMIFS(TabelaResultadosAcademicos[Aprovados],TabelaResultadosAcademicos[Período],(IF(F4="","",IF(ISNUMBER(SEARCH("-SEM",F4)),F4,LEFT(F4,4)&"-SEM"&IF(VALUE(RIGHT(F4,2))<=6,1,2)))),TabelaResultadosAcademicos[Curso],IF($A7="(todos)","*",$A7),TabelaResultadosAcademicos[Disciplina],IF("(todas)"="(todas)","*","(todas)")))/((SUMIFS(TabelaResultadosAcademicos[Aprovados],TabelaResultadosAcademicos[Período],(IF(F4="","",IF(ISNUMBER(SEARCH("-SEM",F4)),F4,LEFT(F4,4)&"-SEM"&IF(VALUE(RIGHT(F4,2))<=6,1,2)))),TabelaResultadosAcademicos[Curso],IF($A7="(todos)","*",$A7),TabelaResultadosAcademicos[Disciplina],IF("(todas)"="(todas)","*","(todas)")))+(SUMIFS(TabelaResultadosAcademicos[Reprovados],TabelaResultadosAcademicos[Período],(IF(F4="","",IF(ISNUMBER(SEARCH("-SEM",F4)),F4,LEFT(F4,4)&"-SEM"&IF(VALUE(RIGHT(F4,2))<=6,1,2)))),TabelaResultadosAcademicos[Curso],IF($A7="(todos)","*",$A7),TabelaResultadosAcademicos[Disciplina],IF("(todas)"="(todas)","*","(todas)"))))*100,"")) | G7: =IF(G4="","",IFERROR((SUMIFS(TabelaResultadosAcademicos[Aprovados],TabelaResultadosAcademicos[Período],(IF(G4="","",IF(ISNUMBER(SEARCH("-SEM",G4)),G4,LEFT(G4,4)&"-SEM"&IF(VALUE(RIGHT(G4,2))<=6,1,2)))),TabelaResultadosAcademicos[Curso],IF($A7="(todos)","*",$A7),TabelaResultadosAcademicos[Disciplina],IF("(todas)"="(todas)","*","(todas)")))/((SUMIFS(TabelaResultadosAcademicos[Aprovados],TabelaResultadosAcademicos[Período],(IF(G4="","",IF(ISNUMBER(SEARCH("-SEM",G4)),G4,LEFT(G4,4)&"-SEM"&IF(VALUE(RIGHT(G4,2))<=6,1,2)))),TabelaResultadosAcademicos[Curso],IF($A7="(todos)","*",$A7),TabelaResultadosAcademicos[Disciplina],IF("(todas)"="(todas)","*","(todas)")))+(SUMIFS(TabelaResultadosAcademicos[Reprovados],TabelaResultadosAcademicos[Período],(IF(G4="","",IF(ISNUMBER(SEARCH("-SEM",G4)),G4,LEFT(G4,4)&"-SEM"&IF(VALUE(RIGHT(G4,2))<=6,1,2)))),TabelaResultadosAcademicos[Curso],IF($A7="(todos)","*",$A7),TabelaResultadosAcademicos[Disciplina],IF("(todas)"="(todas)","*","(todas)"))))*100,"")) | H7: =IF(H4="","",IFERROR((SUMIFS(TabelaResultadosAcademicos[Aprovados],TabelaResultadosAcademicos[Período],(IF(H4="","",IF(ISNUMBER(SEARCH("-SEM",H4)),H4,LEFT(H4,4)&"-SEM"&IF(VALUE(RIGHT(H4,2))<=6,1,2)))),TabelaResultadosAcademicos[Curso],IF($A7="(todos)","*",$A7),TabelaResultadosAcademicos[Disciplina],IF("(todas)"="(todas)","*","(todas)")))/((SUMIFS(TabelaResultadosAcademicos[Aprovados],TabelaResultadosAcademicos[Período],(IF(H4="","",IF(ISNUMBER(SEARCH("-SEM",H4)),H4,LEFT(H4,4)&"-SEM"&IF(VALUE(RIGHT(H4,2))<=6,1,2)))),TabelaResultadosAcademicos[Curso],IF($A7="(todos)","*",$A7),TabelaResultadosAcademicos[Disciplina],IF("(todas)"="(todas)","*","(todas)")))+(SUMIFS(TabelaResultadosAcademicos[Reprovados],TabelaResultadosAcademicos[Período],(IF(H4="","",IF(ISNUMBER(SEARCH("-SEM",H4)),H4,LEFT(H4,4)&"-SEM"&IF(VALUE(RIGHT(H4,2))<=6,1,2)))),TabelaResultadosAcademicos[Curso],IF($A7="(todos)","*",$A7),TabelaResultadosAcademicos[Disciplina],IF("(todas)"="(todas)","*","(todas)"))))*100,"")) | I7: =IF(I4="","",IFERROR((SUMIFS(TabelaResultadosAcademicos[Aprovados],TabelaResultadosAcademicos[Período],(IF(I4="","",IF(ISNUMBER(SEARCH("-SEM",I4)),I4,LEFT(I4,4)&"-SEM"&IF(VALUE(RIGHT(I4,2))<=6,1,2)))),TabelaResultadosAcademicos[Curso],IF($A7="(todos)","*",$A7),TabelaResultadosAcademicos[Disciplina],IF("(todas)"="(todas)","*","(todas)")))/((SUMIFS(TabelaResultadosAcademicos[Aprovados],TabelaResultadosAcademicos[Período],(IF(I4="","",IF(ISNUMBER(SEARCH("-SEM",I4)),I4,LEFT(I4,4)&"-SEM"&IF(VALUE(RIGHT(I4,2))<=6,1,2)))),TabelaResultadosAcademicos[Curso],IF($A7="(todos)","*",$A7),TabelaResultadosAcademicos[Disciplina],IF("(todas)"="(todas)","*","(todas)")))+(SUMIFS(TabelaResultadosAcademicos[Reprovados],TabelaResultadosAcademicos[Período],(IF(I4="","",IF(ISNUMBER(SEARCH("-SEM",I4)),I4,LEFT(I4,4)&"-SEM"&IF(VALUE(RIGHT(I4,2))<=6,1,2)))),TabelaResultadosAcademicos[Curso],IF($A7="(todos)","*",$A7),TabelaResultadosAcademicos[Disciplina],IF("(todas)"="(todas)","*","(todas)"))))*100,"")) | ... Y7: =IF(Y4="","",IFERROR((SUMIFS(TabelaResultadosAcademicos[Aprovados],TabelaResultadosAcademicos[Período],(IF(Y4="","",IF(ISNUMBER(SEARCH("-SEM",Y4)),Y4,LEFT(Y4,4)&"-SEM"&IF(VALUE(RIGHT(Y4,2))<=6,1,2)))),TabelaResultadosAcademicos[Curso],IF($A7="(todos)","*",$A7),TabelaResultadosAcademicos[Disciplina],IF("(todas)"="(todas)","*","(todas)")))/((SUMIFS(TabelaResultadosAcademicos[Aprovados],TabelaResultadosAcademicos[Período],(IF(Y4="","",IF(ISNUMBER(SEARCH("-SEM",Y4)),Y4,LEFT(Y4,4)&"-SEM"&IF(VALUE(RIGHT(Y4,2))<=6,1,2)))),TabelaResultadosAcademicos[Curso],IF($A7="(todos)","*",$A7),TabelaResultadosAcademicos[Disciplina],IF("(todas)"="(todas)","*","(todas)")))+(SUMIFS(TabelaResultadosAcademicos[Reprovados],TabelaResultadosAcademicos[Período],(IF(Y4="","",IF(ISNUMBER(SEARCH("-SEM",Y4)),Y4,LEFT(Y4,4)&"-SEM"&IF(VALUE(RIGHT(Y4,2))<=6,1,2)))),TabelaResultadosAcademicos[Curso],IF($A7="(todos)","*",$A7),TabelaResultadosAcademicos[Disciplina],IF("(todas)"="(todas)","*","(todas)"))))*100,""))
A8: Arquitetura e Urbanismo | B8: =IF(B4="","",IFERROR((SUMIFS(TabelaResultadosAcademicos[Aprovados],TabelaResultadosAcademicos[Período],(IF(B4="","",IF(ISNUMBER(SEARCH("-SEM",B4)),B4,LEFT(B4,4)&"-SEM"&IF(VALUE(RIGHT(B4,2))<=6,1,2)))),TabelaResultadosAcademicos[Curso],IF($A8="(todos)","*",$A8),TabelaResultadosAcademicos[Disciplina],IF("(todas)"="(todas)","*","(todas)")))/((SUMIFS(TabelaResultadosAcademicos[Aprovados],TabelaResultadosAcademicos[Período],(IF(B4="","",IF(ISNUMBER(SEARCH("-SEM",B4)),B4,LEFT(B4,4)&"-SEM"&IF(VALUE(RIGHT(B4,2))<=6,1,2)))),TabelaResultadosAcademicos[Curso],IF($A8="(todos)","*",$A8),TabelaResultadosAcademicos[Disciplina],IF("(todas)"="(todas)","*","(todas)")))+(SUMIFS(TabelaResultadosAcademicos[Reprovados],TabelaResultadosAcademicos[Período],(IF(B4="","",IF(ISNUMBER(SEARCH("-SEM",B4)),B4,LEFT(B4,4)&"-SEM"&IF(VALUE(RIGHT(B4,2))<=6,1,2)))),TabelaResultadosAcademicos[Curso],IF($A8="(todos)","*",$A8),TabelaResultadosAcademicos[Disciplina],IF("(todas)"="(todas)","*","(todas)"))))*100,"")) | C8: =IF(C4="","",IFERROR((SUMIFS(TabelaResultadosAcademicos[Aprovados],TabelaResultadosAcademicos[Período],(IF(C4="","",IF(ISNUMBER(SEARCH("-SEM",C4)),C4,LEFT(C4,4)&"-SEM"&IF(VALUE(RIGHT(C4,2))<=6,1,2)))),TabelaResultadosAcademicos[Curso],IF($A8="(todos)","*",$A8),TabelaResultadosAcademicos[Disciplina],IF("(todas)"="(todas)","*","(todas)")))/((SUMIFS(TabelaResultadosAcademicos[Aprovados],TabelaResultadosAcademicos[Período],(IF(C4="","",IF(ISNUMBER(SEARCH("-SEM",C4)),C4,LEFT(C4,4)&"-SEM"&IF(VALUE(RIGHT(C4,2))<=6,1,2)))),TabelaResultadosAcademicos[Curso],IF($A8="(todos)","*",$A8),TabelaResultadosAcademicos[Disciplina],IF("(todas)"="(todas)","*","(todas)")))+(SUMIFS(TabelaResultadosAcademicos[Reprovados],TabelaResultadosAcademicos[Período],(IF(C4="","",IF(ISNUMBER(SEARCH("-SEM",C4)),C4,LEFT(C4,4)&"-SEM"&IF(VALUE(RIGHT(C4,2))<=6,1,2)))),TabelaResultadosAcademicos[Curso],IF($A8="(todos)","*",$A8),TabelaResultadosAcademicos[Disciplina],IF("(todas)"="(todas)","*","(todas)"))))*100,"")) | D8: =IF(D4="","",IFERROR((SUMIFS(TabelaResultadosAcademicos[Aprovados],TabelaResultadosAcademicos[Período],(IF(D4="","",IF(ISNUMBER(SEARCH("-SEM",D4)),D4,LEFT(D4,4)&"-SEM"&IF(VALUE(RIGHT(D4,2))<=6,1,2)))),TabelaResultadosAcademicos[Curso],IF($A8="(todos)","*",$A8),TabelaResultadosAcademicos[Disciplina],IF("(todas)"="(todas)","*","(todas)")))/((SUMIFS(TabelaResultadosAcademicos[Aprovados],TabelaResultadosAcademicos[Período],(IF(D4="","",IF(ISNUMBER(SEARCH("-SEM",D4)),D4,LEFT(D4,4)&"-SEM"&IF(VALUE(RIGHT(D4,2))<=6,1,2)))),TabelaResultadosAcademicos[Curso],IF($A8="(todos)","*",$A8),TabelaResultadosAcademicos[Disciplina],IF("(todas)"="(todas)","*","(todas)")))+(SUMIFS(TabelaResultadosAcademicos[Reprovados],TabelaResultadosAcademicos[Período],(IF(D4="","",IF(ISNUMBER(SEARCH("-SEM",D4)),D4,LEFT(D4,4)&"-SEM"&IF(VALUE(RIGHT(D4,2))<=6,1,2)))),TabelaResultadosAcademicos[Curso],IF($A8="(todos)","*",$A8),TabelaResultadosAcademicos[Disciplina],IF("(todas)"="(todas)","*","(todas)"))))*100,"")) | E8: =IF(E4="","",IFERROR((SUMIFS(TabelaResultadosAcademicos[Aprovados],TabelaResultadosAcademicos[Período],(IF(E4="","",IF(ISNUMBER(SEARCH("-SEM",E4)),E4,LEFT(E4,4)&"-SEM"&IF(VALUE(RIGHT(E4,2))<=6,1,2)))),TabelaResultadosAcademicos[Curso],IF($A8="(todos)","*",$A8),TabelaResultadosAcademicos[Disciplina],IF("(todas)"="(todas)","*","(todas)")))/((SUMIFS(TabelaResultadosAcademicos[Aprovados],TabelaResultadosAcademicos[Período],(IF(E4="","",IF(ISNUMBER(SEARCH("-SEM",E4)),E4,LEFT(E4,4)&"-SEM"&IF(VALUE(RIGHT(E4,2))<=6,1,2)))),TabelaResultadosAcademicos[Curso],IF($A8="(todos)","*",$A8),TabelaResultadosAcademicos[Disciplina],IF("(todas)"="(todas)","*","(todas)")))+(SUMIFS(TabelaResultadosAcademicos[Reprovados],TabelaResultadosAcademicos[Período],(IF(E4="","",IF(ISNUMBER(SEARCH("-SEM",E4)),E4,LEFT(E4,4)&"-SEM"&IF(VALUE(RIGHT(E4,2))<=6,1,2)))),TabelaResultadosAcademicos[Curso],IF($A8="(todos)","*",$A8),TabelaResultadosAcademicos[Disciplina],IF("(todas)"="(todas)","*","(todas)"))))*100,"")) | F8: =IF(F4="","",IFERROR((SUMIFS(TabelaResultadosAcademicos[Aprovados],TabelaResultadosAcademicos[Período],(IF(F4="","",IF(ISNUMBER(SEARCH("-SEM",F4)),F4,LEFT(F4,4)&"-SEM"&IF(VALUE(RIGHT(F4,2))<=6,1,2)))),TabelaResultadosAcademicos[Curso],IF($A8="(todos)","*",$A8),TabelaResultadosAcademicos[Disciplina],IF("(todas)"="(todas)","*","(todas)")))/((SUMIFS(TabelaResultadosAcademicos[Aprovados],TabelaResultadosAcademicos[Período],(IF(F4="","",IF(ISNUMBER(SEARCH("-SEM",F4)),F4,LEFT(F4,4)&"-SEM"&IF(VALUE(RIGHT(F4,2))<=6,1,2)))),TabelaResultadosAcademicos[Curso],IF($A8="(todos)","*",$A8),TabelaResultadosAcademicos[Disciplina],IF("(todas)"="(todas)","*","(todas)")))+(SUMIFS(TabelaResultadosAcademicos[Reprovados],TabelaResultadosAcademicos[Período],(IF(F4="","",IF(ISNUMBER(SEARCH("-SEM",F4)),F4,LEFT(F4,4)&"-SEM"&IF(VALUE(RIGHT(F4,2))<=6,1,2)))),TabelaResultadosAcademicos[Curso],IF($A8="(todos)","*",$A8),TabelaResultadosAcademicos[Disciplina],IF("(todas)"="(todas)","*","(todas)"))))*100,"")) | G8: =IF(G4="","",IFERROR((SUMIFS(TabelaResultadosAcademicos[Aprovados],TabelaResultadosAcademicos[Período],(IF(G4="","",IF(ISNUMBER(SEARCH("-SEM",G4)),G4,LEFT(G4,4)&"-SEM"&IF(VALUE(RIGHT(G4,2))<=6,1,2)))),TabelaResultadosAcademicos[Curso],IF($A8="(todos)","*",$A8),TabelaResultadosAcademicos[Disciplina],IF("(todas)"="(todas)","*","(todas)")))/((SUMIFS(TabelaResultadosAcademicos[Aprovados],TabelaResultadosAcademicos[Período],(IF(G4="","",IF(ISNUMBER(SEARCH("-SEM",G4)),G4,LEFT(G4,4)&"-SEM"&IF(VALUE(RIGHT(G4,2))<=6,1,2)))),TabelaResultadosAcademicos[Curso],IF($A8="(todos)","*",$A8),TabelaResultadosAcademicos[Disciplina],IF("(todas)"="(todas)","*","(todas)")))+(SUMIFS(TabelaResultadosAcademicos[Reprovados],TabelaResultadosAcademicos[Período],(IF(G4="","",IF(ISNUMBER(SEARCH("-SEM",G4)),G4,LEFT(G4,4)&"-SEM"&IF(VALUE(RIGHT(G4,2))<=6,1,2)))),TabelaResultadosAcademicos[Curso],IF($A8="(todos)","*",$A8),TabelaResultadosAcademicos[Disciplina],IF("(todas)"="(todas)","*","(todas)"))))*100,"")) | H8: =IF(H4="","",IFERROR((SUMIFS(TabelaResultadosAcademicos[Aprovados],TabelaResultadosAcademicos[Período],(IF(H4="","",IF(ISNUMBER(SEARCH("-SEM",H4)),H4,LEFT(H4,4)&"-SEM"&IF(VALUE(RIGHT(H4,2))<=6,1,2)))),TabelaResultadosAcademicos[Curso],IF($A8="(todos)","*",$A8),TabelaResultadosAcademicos[Disciplina],IF("(todas)"="(todas)","*","(todas)")))/((SUMIFS(TabelaResultadosAcademicos[Aprovados],TabelaResultadosAcademicos[Período],(IF(H4="","",IF(ISNUMBER(SEARCH("-SEM",H4)),H4,LEFT(H4,4)&"-SEM"&IF(VALUE(RIGHT(H4,2))<=6,1,2)))),TabelaResultadosAcademicos[Curso],IF($A8="(todos)","*",$A8),TabelaResultadosAcademicos[Disciplina],IF("(todas)"="(todas)","*","(todas)")))+(SUMIFS(TabelaResultadosAcademicos[Reprovados],TabelaResultadosAcademicos[Período],(IF(H4="","",IF(ISNUMBER(SEARCH("-SEM",H4)),H4,LEFT(H4,4)&"-SEM"&IF(VALUE(RIGHT(H4,2))<=6,1,2)))),TabelaResultadosAcademicos[Curso],IF($A8="(todos)","*",$A8),TabelaResultadosAcademicos[Disciplina],IF("(todas)"="(todas)","*","(todas)"))))*100,"")) | I8: =IF(I4="","",IFERROR((SUMIFS(TabelaResultadosAcademicos[Aprovados],TabelaResultadosAcademicos[Período],(IF(I4="","",IF(ISNUMBER(SEARCH("-SEM",I4)),I4,LEFT(I4,4)&"-SEM"&IF(VALUE(RIGHT(I4,2))<=6,1,2)))),TabelaResultadosAcademicos[Curso],IF($A8="(todos)","*",$A8),TabelaResultadosAcademicos[Disciplina],IF("(todas)"="(todas)","*","(todas)")))/((SUMIFS(TabelaResultadosAcademicos[Aprovados],TabelaResultadosAcademicos[Período],(IF(I4="","",IF(ISNUMBER(SEARCH("-SEM",I4)),I4,LEFT(I4,4)&"-SEM"&IF(VALUE(RIGHT(I4,2))<=6,1,2)))),TabelaResultadosAcademicos[Curso],IF($A8="(todos)","*",$A8),TabelaResultadosAcademicos[Disciplina],IF("(todas)"="(todas)","*","(todas)")))+(SUMIFS(TabelaResultadosAcademicos[Reprovados],TabelaResultadosAcademicos[Período],(IF(I4="","",IF(ISNUMBER(SEARCH("-SEM",I4)),I4,LEFT(I4,4)&"-SEM"&IF(VALUE(RIGHT(I4,2))<=6,1,2)))),TabelaResultadosAcademicos[Curso],IF($A8="(todos)","*",$A8),TabelaResultadosAcademicos[Disciplina],IF("(todas)"="(todas)","*","(todas)"))))*100,"")) | ... Y8: =IF(Y4="","",IFERROR((SUMIFS(TabelaResultadosAcademicos[Aprovados],TabelaResultadosAcademicos[Período],(IF(Y4="","",IF(ISNUMBER(SEARCH("-SEM",Y4)),Y4,LEFT(Y4,4)&"-SEM"&IF(VALUE(RIGHT(Y4,2))<=6,1,2)))),TabelaResultadosAcademicos[Curso],IF($A8="(todos)","*",$A8),TabelaResultadosAcademicos[Disciplina],IF("(todas)"="(todas)","*","(todas)")))/((SUMIFS(TabelaResultadosAcademicos[Aprovados],TabelaResultadosAcademicos[Período],(IF(Y4="","",IF(ISNUMBER(SEARCH("-SEM",Y4)),Y4,LEFT(Y4,4)&"-SEM"&IF(VALUE(RIGHT(Y4,2))<=6,1,2)))),TabelaResultadosAcademicos[Curso],IF($A8="(todos)","*",$A8),TabelaResultadosAcademicos[Disciplina],IF("(todas)"="(todas)","*","(todas)")))+(SUMIFS(TabelaResultadosAcademicos[Reprovados],TabelaResultadosAcademicos[Período],(IF(Y4="","",IF(ISNUMBER(SEARCH("-SEM",Y4)),Y4,LEFT(Y4,4)&"-SEM"&IF(VALUE(RIGHT(Y4,2))<=6,1,2)))),TabelaResultadosAcademicos[Curso],IF($A8="(todos)","*",$A8),TabelaResultadosAcademicos[Disciplina],IF("(todas)"="(todas)","*","(todas)"))))*100,""))
A9: Ciências Contábeis | B9: =IF(B4="","",IFERROR((SUMIFS(TabelaResultadosAcademicos[Aprovados],TabelaResultadosAcademicos[Período],(IF(B4="","",IF(ISNUMBER(SEARCH("-SEM",B4)),B4,LEFT(B4,4)&"-SEM"&IF(VALUE(RIGHT(B4,2))<=6,1,2)))),TabelaResultadosAcademicos[Curso],IF($A9="(todos)","*",$A9),TabelaResultadosAcademicos[Disciplina],IF("(todas)"="(todas)","*","(todas)")))/((SUMIFS(TabelaResultadosAcademicos[Aprovados],TabelaResultadosAcademicos[Período],(IF(B4="","",IF(ISNUMBER(SEARCH("-SEM",B4)),B4,LEFT(B4,4)&"-SEM"&IF(VALUE(RIGHT(B4,2))<=6,1,2)))),TabelaResultadosAcademicos[Curso],IF($A9="(todos)","*",$A9),TabelaResultadosAcademicos[Disciplina],IF("(todas)"="(todas)","*","(todas)")))+(SUMIFS(TabelaResultadosAcademicos[Reprovados],TabelaResultadosAcademicos[Período],(IF(B4="","",IF(ISNUMBER(SEARCH("-SEM",B4)),B4,LEFT(B4,4)&"-SEM"&IF(VALUE(RIGHT(B4,2))<=6,1,2)))),TabelaResultadosAcademicos[Curso],IF($A9="(todos)","*",$A9),TabelaResultadosAcademicos[Disciplina],IF("(todas)"="(todas)","*","(todas)"))))*100,"")) | C9: =IF(C4="","",IFERROR((SUMIFS(TabelaResultadosAcademicos[Aprovados],TabelaResultadosAcademicos[Período],(IF(C4="","",IF(ISNUMBER(SEARCH("-SEM",C4)),C4,LEFT(C4,4)&"-SEM"&IF(VALUE(RIGHT(C4,2))<=6,1,2)))),TabelaResultadosAcademicos[Curso],IF($A9="(todos)","*",$A9),TabelaResultadosAcademicos[Disciplina],IF("(todas)"="(todas)","*","(todas)")))/((SUMIFS(TabelaResultadosAcademicos[Aprovados],TabelaResultadosAcademicos[Período],(IF(C4="","",IF(ISNUMBER(SEARCH("-SEM",C4)),C4,LEFT(C4,4)&"-SEM"&IF(VALUE(RIGHT(C4,2))<=6,1,2)))),TabelaResultadosAcademicos[Curso],IF($A9="(todos)","*",$A9),TabelaResultadosAcademicos[Disciplina],IF("(todas)"="(todas)","*","(todas)")))+(SUMIFS(TabelaResultadosAcademicos[Reprovados],TabelaResultadosAcademicos[Período],(IF(C4="","",IF(ISNUMBER(SEARCH("-SEM",C4)),C4,LEFT(C4,4)&"-SEM"&IF(VALUE(RIGHT(C4,2))<=6,1,2)))),TabelaResultadosAcademicos[Curso],IF($A9="(todos)","*",$A9),TabelaResultadosAcademicos[Disciplina],IF("(todas)"="(todas)","*","(todas)"))))*100,"")) | D9: =IF(D4="","",IFERROR((SUMIFS(TabelaResultadosAcademicos[Aprovados],TabelaResultadosAcademicos[Período],(IF(D4="","",IF(ISNUMBER(SEARCH("-SEM",D4)),D4,LEFT(D4,4)&"-SEM"&IF(VALUE(RIGHT(D4,2))<=6,1,2)))),TabelaResultadosAcademicos[Curso],IF($A9="(todos)","*",$A9),TabelaResultadosAcademicos[Disciplina],IF("(todas)"="(todas)","*","(todas)")))/((SUMIFS(TabelaResultadosAcademicos[Aprovados],TabelaResultadosAcademicos[Período],(IF(D4="","",IF(ISNUMBER(SEARCH("-SEM",D4)),D4,LEFT(D4,4)&"-SEM"&IF(VALUE(RIGHT(D4,2))<=6,1,2)))),TabelaResultadosAcademicos[Curso],IF($A9="(todos)","*",$A9),TabelaResultadosAcademicos[Disciplina],IF("(todas)"="(todas)","*","(todas)")))+(SUMIFS(TabelaResultadosAcademicos[Reprovados],TabelaResultadosAcademicos[Período],(IF(D4="","",IF(ISNUMBER(SEARCH("-SEM",D4)),D4,LEFT(D4,4)&"-SEM"&IF(VALUE(RIGHT(D4,2))<=6,1,2)))),TabelaResultadosAcademicos[Curso],IF($A9="(todos)","*",$A9),TabelaResultadosAcademicos[Disciplina],IF("(todas)"="(todas)","*","(todas)"))))*100,"")) | E9: =IF(E4="","",IFERROR((SUMIFS(TabelaResultadosAcademicos[Aprovados],TabelaResultadosAcademicos[Período],(IF(E4="","",IF(ISNUMBER(SEARCH("-SEM",E4)),E4,LEFT(E4,4)&"-SEM"&IF(VALUE(RIGHT(E4,2))<=6,1,2)))),TabelaResultadosAcademicos[Curso],IF($A9="(todos)","*",$A9),TabelaResultadosAcademicos[Disciplina],IF("(todas)"="(todas)","*","(todas)")))/((SUMIFS(TabelaResultadosAcademicos[Aprovados],TabelaResultadosAcademicos[Período],(IF(E4="","",IF(ISNUMBER(SEARCH("-SEM",E4)),E4,LEFT(E4,4)&"-SEM"&IF(VALUE(RIGHT(E4,2))<=6,1,2)))),TabelaResultadosAcademicos[Curso],IF($A9="(todos)","*",$A9),TabelaResultadosAcademicos[Disciplina],IF("(todas)"="(todas)","*","(todas)")))+(SUMIFS(TabelaResultadosAcademicos[Reprovados],TabelaResultadosAcademicos[Período],(IF(E4="","",IF(ISNUMBER(SEARCH("-SEM",E4)),E4,LEFT(E4,4)&"-SEM"&IF(VALUE(RIGHT(E4,2))<=6,1,2)))),TabelaResultadosAcademicos[Curso],IF($A9="(todos)","*",$A9),TabelaResultadosAcademicos[Disciplina],IF("(todas)"="(todas)","*","(todas)"))))*100,"")) | F9: =IF(F4="","",IFERROR((SUMIFS(TabelaResultadosAcademicos[Aprovados],TabelaResultadosAcademicos[Período],(IF(F4="","",IF(ISNUMBER(SEARCH("-SEM",F4)),F4,LEFT(F4,4)&"-SEM"&IF(VALUE(RIGHT(F4,2))<=6,1,2)))),TabelaResultadosAcademicos[Curso],IF($A9="(todos)","*",$A9),TabelaResultadosAcademicos[Disciplina],IF("(todas)"="(todas)","*","(todas)")))/((SUMIFS(TabelaResultadosAcademicos[Aprovados],TabelaResultadosAcademicos[Período],(IF(F4="","",IF(ISNUMBER(SEARCH("-SEM",F4)),F4,LEFT(F4,4)&"-SEM"&IF(VALUE(RIGHT(F4,2))<=6,1,2)))),TabelaResultadosAcademicos[Curso],IF($A9="(todos)","*",$A9),TabelaResultadosAcademicos[Disciplina],IF("(todas)"="(todas)","*","(todas)")))+(SUMIFS(TabelaResultadosAcademicos[Reprovados],TabelaResultadosAcademicos[Período],(IF(F4="","",IF(ISNUMBER(SEARCH("-SEM",F4)),F4,LEFT(F4,4)&"-SEM"&IF(VALUE(RIGHT(F4,2))<=6,1,2)))),TabelaResultadosAcademicos[Curso],IF($A9="(todos)","*",$A9),TabelaResultadosAcademicos[Disciplina],IF("(todas)"="(todas)","*","(todas)"))))*100,"")) | G9: =IF(G4="","",IFERROR((SUMIFS(TabelaResultadosAcademicos[Aprovados],TabelaResultadosAcademicos[Período],(IF(G4="","",IF(ISNUMBER(SEARCH("-SEM",G4)),G4,LEFT(G4,4)&"-SEM"&IF(VALUE(RIGHT(G4,2))<=6,1,2)))),TabelaResultadosAcademicos[Curso],IF($A9="(todos)","*",$A9),TabelaResultadosAcademicos[Disciplina],IF("(todas)"="(todas)","*","(todas)")))/((SUMIFS(TabelaResultadosAcademicos[Aprovados],TabelaResultadosAcademicos[Período],(IF(G4="","",IF(ISNUMBER(SEARCH("-SEM",G4)),G4,LEFT(G4,4)&"-SEM"&IF(VALUE(RIGHT(G4,2))<=6,1,2)))),TabelaResultadosAcademicos[Curso],IF($A9="(todos)","*",$A9),TabelaResultadosAcademicos[Disciplina],IF("(todas)"="(todas)","*","(todas)")))+(SUMIFS(TabelaResultadosAcademicos[Reprovados],TabelaResultadosAcademicos[Período],(IF(G4="","",IF(ISNUMBER(SEARCH("-SEM",G4)),G4,LEFT(G4,4)&"-SEM"&IF(VALUE(RIGHT(G4,2))<=6,1,2)))),TabelaResultadosAcademicos[Curso],IF($A9="(todos)","*",$A9),TabelaResultadosAcademicos[Disciplina],IF("(todas)"="(todas)","*","(todas)"))))*100,"")) | H9: =IF(H4="","",IFERROR((SUMIFS(TabelaResultadosAcademicos[Aprovados],TabelaResultadosAcademicos[Período],(IF(H4="","",IF(ISNUMBER(SEARCH("-SEM",H4)),H4,LEFT(H4,4)&"-SEM"&IF(VALUE(RIGHT(H4,2))<=6,1,2)))),TabelaResultadosAcademicos[Curso],IF($A9="(todos)","*",$A9),TabelaResultadosAcademicos[Disciplina],IF("(todas)"="(todas)","*","(todas)")))/((SUMIFS(TabelaResultadosAcademicos[Aprovados],TabelaResultadosAcademicos[Período],(IF(H4="","",IF(ISNUMBER(SEARCH("-SEM",H4)),H4,LEFT(H4,4)&"-SEM"&IF(VALUE(RIGHT(H4,2))<=6,1,2)))),TabelaResultadosAcademicos[Curso],IF($A9="(todos)","*",$A9),TabelaResultadosAcademicos[Disciplina],IF("(todas)"="(todas)","*","(todas)")))+(SUMIFS(TabelaResultadosAcademicos[Reprovados],TabelaResultadosAcademicos[Período],(IF(H4="","",IF(ISNUMBER(SEARCH("-SEM",H4)),H4,LEFT(H4,4)&"-SEM"&IF(VALUE(RIGHT(H4,2))<=6,1,2)))),TabelaResultadosAcademicos[Curso],IF($A9="(todos)","*",$A9),TabelaResultadosAcademicos[Disciplina],IF("(todas)"="(todas)","*","(todas)"))))*100,"")) | I9: =IF(I4="","",IFERROR((SUMIFS(TabelaResultadosAcademicos[Aprovados],TabelaResultadosAcademicos[Período],(IF(I4="","",IF(ISNUMBER(SEARCH("-SEM",I4)),I4,LEFT(I4,4)&"-SEM"&IF(VALUE(RIGHT(I4,2))<=6,1,2)))),TabelaResultadosAcademicos[Curso],IF($A9="(todos)","*",$A9),TabelaResultadosAcademicos[Disciplina],IF("(todas)"="(todas)","*","(todas)")))/((SUMIFS(TabelaResultadosAcademicos[Aprovados],TabelaResultadosAcademicos[Período],(IF(I4="","",IF(ISNUMBER(SEARCH("-SEM",I4)),I4,LEFT(I4,4)&"-SEM"&IF(VALUE(RIGHT(I4,2))<=6,1,2)))),TabelaResultadosAcademicos[Curso],IF($A9="(todos)","*",$A9),TabelaResultadosAcademicos[Disciplina],IF("(todas)"="(todas)","*","(todas)")))+(SUMIFS(TabelaResultadosAcademicos[Reprovados],TabelaResultadosAcademicos[Período],(IF(I4="","",IF(ISNUMBER(SEARCH("-SEM",I4)),I4,LEFT(I4,4)&"-SEM"&IF(VALUE(RIGHT(I4,2))<=6,1,2)))),TabelaResultadosAcademicos[Curso],IF($A9="(todos)","*",$A9),TabelaResultadosAcademicos[Disciplina],IF("(todas)"="(todas)","*","(todas)"))))*100,"")) | ... Y9: =IF(Y4="","",IFERROR((SUMIFS(TabelaResultadosAcademicos[Aprovados],TabelaResultadosAcademicos[Período],(IF(Y4="","",IF(ISNUMBER(SEARCH("-SEM",Y4)),Y4,LEFT(Y4,4)&"-SEM"&IF(VALUE(RIGHT(Y4,2))<=6,1,2)))),TabelaResultadosAcademicos[Curso],IF($A9="(todos)","*",$A9),TabelaResultadosAcademicos[Disciplina],IF("(todas)"="(todas)","*","(todas)")))/((SUMIFS(TabelaResultadosAcademicos[Aprovados],TabelaResultadosAcademicos[Período],(IF(Y4="","",IF(ISNUMBER(SEARCH("-SEM",Y4)),Y4,LEFT(Y4,4)&"-SEM"&IF(VALUE(RIGHT(Y4,2))<=6,1,2)))),TabelaResultadosAcademicos[Curso],IF($A9="(todos)","*",$A9),TabelaResultadosAcademicos[Disciplina],IF("(todas)"="(todas)","*","(todas)")))+(SUMIFS(TabelaResultadosAcademicos[Reprovados],TabelaResultadosAcademicos[Período],(IF(Y4="","",IF(ISNUMBER(SEARCH("-SEM",Y4)),Y4,LEFT(Y4,4)&"-SEM"&IF(VALUE(RIGHT(Y4,2))<=6,1,2)))),TabelaResultadosAcademicos[Curso],IF($A9="(todos)","*",$A9),TabelaResultadosAcademicos[Disciplina],IF("(todas)"="(todas)","*","(todas)"))))*100,""))
