Workbook

Sheet LEIA-ME
A1: PAINEL DE GESTÃO POR DADOS — DTNH · v4
A2: Periodicidade de alimentação variável e frequência por disciplina.
B4: 1. Cada KPI tem seu próprio grão de alimentação
B5: A coluna 'Mês' das abas de entrada usa a competência de cada KPI. A periodicidade institucional é declarada na aba INDICADORES, coluna 'Periodicidade de alimentação'.
B6: • Semanal: 2026-08-W1 até 2026-08-W5
B7: • Quinzenal: 2026-08-Q1 e 2026-08-Q2
B8: • Mensal: 2026-08
B9: Regra de integridade: para um mesmo KPI, curso e competência, não duplique lançamentos. Mudanças de periodicidade devem valer somente para competências futuras e ser registradas na governança do painel.
B10: KPIs de estoque, como Matrículas Ativas, representam uma fotografia mensal de fechamento. A Frequência Média do Data UNIVC também é alimentada por competência mensal.
B11: Semestral funciona diferente: o CALC usa o código do semestre, e o valor apurado do semestre aparece igual nos seis meses. É a propagação que você pediu — uma alimentação, vários meses exibidos.
B13: 2. Como está configurado agora
B14: • DTNH-01 NPS Discente — alimentação mensal, detalhe por curso.
B15: • DTNH-02 Matrículas Ativas — alimentação mensal, detalhe por curso.
B16: • DTNH-03 Frequência Média — alimentação MENSAL, detalhe por CURSO E DISCIPLINA.
... B42: • Para mudar meta, acrescente linha com nova vigência; jamais sobrescreva.

Sheet PARAMETROS
A1: PARÂMETROS DO PAINEL
A2: Só as células amarelas são editáveis. Todas têm lista suspensa — não digite à mão.
A4: SELEÇÃO
A5: Diretoria | B5: DTNH
A6: Início da operação | B6: 2026-06 | D6: Primeiro mês alimentado.
A7: Mês de referência | B7: 2026-08 | D7: O mês analisado.
A8: Mês de comparação | B8: 2026-07 | D8: Pode ficar vazio.
A9: Janela — de | B9: 2026-06 | D9: Primeiro mês do gráfico e da matriz.
A10: Janela — até | B10: 2027-05 | D10: Último mês. Pode ser posterior à referência.
A11: Curso em foco | B11: (todos) | D11: Usado no detalhe semanal e por disciplina. '(todos)' soma a área.
A12: JANELA EFETIVA
A13: Janela efetiva — de | B13: =IF(IFERROR(VALUE(SUBSTITUTE($B$9,"-","")),0)<IFERROR(VALUE(SUBSTITUTE($B$6,"-","")),0),$B$6,$B$9) | D13: Recuada para o início da operação, se necessário.
A14: Janela efetiva — até | B14: =IF(IFERROR(VALUE(SUBSTITUTE($B$10,"-","")),0)<IFERROR(VALUE(SUBSTITUTE($B$13,"-","")),0),$B$13,$B$10)
A15: Meses na janela | B15: =(VALUE(LEFT($B$14,4))-VALUE(LEFT($B$13,4)))*12+VALUE(RIGHT($B$14,2))-VALUE(RIGHT($B$13,2))+1
A17: aux · data da referência | B17: =IF($B$7="","",DATE(VALUE(LEFT($B$7,4)),VALUE(RIGHT($B$7,2)),1))
A18: aux · data do início da janela | B18: =IF($B$13="","",DATE(VALUE(LEFT($B$13,4)),VALUE(RIGHT($B$13,2)),1))
A19: aux · chave do fim da janela | B19: =IFERROR(VALUE(SUBSTITUTE($B$14,"-","")),0)
A21: ATALHOS | D21: Copie o valor para o campo correspondente.
A22: Mês anterior à referência | B22: =IF($B$7="","",YEAR(EDATE($B$17,-1))&"-"&IF(MONTH(EDATE($B$17,-1))<10,"0","")&MONTH(EDATE($B$17,-1)))
A23: Mesmo mês do ano anterior | B23: =IF($B$7="","",YEAR(EDATE($B$17,-12))&"-"&IF(MONTH(EDATE($B$17,-12))<10,"0","")&MONTH(EDATE($B$17,-12)))
A24: Primeiro mês com dado | B24: =IF(MIN(DIM_MES!$G$5:$G$148)=999999,"—",INDEX(DIM_MES!$B$5:$B$148,MATCH(MIN(DIM_MES!$G$5:$G$148),DIM_MES!$G$5:$G$148,0)))
A25: Último mês com dado | B25: =IF(MAX(DIM_MES!$H$5:$H$148)=0,"—",INDEX(DIM_MES!$B$5:$B$148,MATCH(MAX(DIM_MES!$H$5:$H$148),DIM_MES!$H$5:$H$148,0)))
A26: Semestre da referência | B26: =IF($B$7="","",LEFT($B$7,4)&"-SEM"&IF(VALUE(RIGHT($B$7,2))<=6,1,2))
A27: Semanas da referência | B27: =IF($B$7="","",$B$7&"-W1 … "&$B$7&"-W5")
A30: DIAGNÓSTICO
A31: Mês de referência tem dado? | B31: =IF($B$7="","sem mês escolhido",IF(IFERROR(INDEX(DIM_MES!$F$5:$F$148,MATCH($B$7,DIM_MES!$B$5:$B$148,0)),0)>0,"OK — há lançamentos","SEM DADO neste mês"))
A32: Mês de comparação tem dado? | B32: =IF($B$8="","(sem comparação)",IF(IFERROR(INDEX(DIM_MES!$F$5:$F$148,MATCH($B$8,DIM_MES!$B$5:$B$148,0)),0)>0,"OK — há lançamentos","SEM DADO neste mês"))
A33: Referência está dentro da janela? | B33: =IF($B$7="","—",IF(AND(IFERROR(VALUE(SUBSTITUTE($B$7,"-","")),0)>=IFERROR(VALUE(SUBSTITUTE($B$13,"-","")),0),IFERROR(VALUE(SUBSTITUTE($B$7,"-","")),0)<=IFERROR(VALUE(SUBSTITUTE($B$14,"-","")),0)),"OK — dentro da janela","FORA DA JANELA — o gráfico não mostra o mês analisado"))
A34: Tamanho da janela | B34: =IF($B$15>12,"EXCEDE 12 MESES — só os primeiros 12 aparecem",$B$15&" meses, dentro do limite de 12")
A35: Meses vazios na janela | B35: =IF(SUMPRODUCT((DIM_MES!$E$5:$E$148>=IFERROR(VALUE(SUBSTITUTE($B$13,"-","")),0))*(DIM_MES!$E$5:$E$148<=IFERROR(VALUE(SUBSTITUTE($B$14,"-","")),0))*(DIM_MES!$F$5:$F$148=0))=0,"OK — nenhum mês vazio",SUMPRODUCT((DIM_MES!$E$5:$E$148>=IFERROR(VALUE(SUBSTITUTE($B$13,"-","")),0))*(DIM_MES!$E$5:$E$148<=IFERROR(VALUE(SUBSTITUTE($B$14,"-","")),0))*(DIM_MES!$F$5:$F$148=0))&" meses vazios — estreite a janela")
A36: Semanas lançadas na frequência | B36: =COUNTIFS(Tabela367[Período],$B$7&"-W*")&" lançamentos semanais · "&COUNTIFS(Tabela367[Período],$B$7)&" lançamentos de mês inteiro"
A37: Frequência com disciplina informada | B37: =COUNTIFS(Tabela367[Período],$B$7&"*",Tabela367[Disciplina],"<>")&" de "&COUNTIFS(Tabela367[Período],$B$7&"*")&" lançamentos do mês"

Sheet PAINEL
A1: PAINEL DE GESTÃO — DTNH
A2: Leitura do mês. Todos os números vêm de CALC; para mudar o recorte, use PARAMETROS.
A4: Mês de referência | D4: Mês de comparação | G4: Janela | J4: Curso em foco
A5: =PARAMETROS!$B$7 | D5: =IF(PARAMETROS!$B$8="","(sem)",PARAMETROS!$B$8) | G5: =PARAMETROS!$B$13&" a "&PARAMETROS!$B$14 | J5: =PARAMETROS!$B$11
A7: DTNH-01 · NPS Discente da Área · alimentação mensal · detalhe por curso
A8: Valor na referência | B8: Valor na comparação | C8: Variação | D8: Meta vigente | E8: Limiar de atenção | F8: Falta p/ a meta | G8: Falta p/ o limiar | H8: Atingimento | I8: Status | J8: Situação | K8: Lançamentos
A9: =CALC!$B$37 | B9: =CALC!$C$37 | C9: =CALC!$D$37 | D9: =CALC!$E$37 | E9: =CALC!$F$37 | F9: =CALC!$G$37 | G9: =CALC!$H$37 | H9: =CALC!$I$37 | I9: =CALC!$J$37 | J9: =CALC!$K$37 | K9: =CALC!$L$37
A26: Curso | B26: Referência | C26: Comparação | D26: Variação | E26: Meta | F26: Status
A27: =CALC!$A$41 | B27: =CALC!$F$41 | C27: =CALC!$G$41 | D27: =CALC!$H$41 | E27: =CALC!$I$41 | F27: =CALC!$K$41
A28: =CALC!$A$42 | B28: =CALC!$F$42 | C28: =CALC!$G$42 | D28: =CALC!$H$42 | E28: =CALC!$I$42 | F28: =CALC!$K$42
A29: =CALC!$A$43 | B29: =CALC!$F$43 | C29: =CALC!$G$43 | D29: =CALC!$H$43 | E29: =CALC!$I$43 | F29: =CALC!$K$43
A30: =CALC!$A$44 | B30: =CALC!$F$44 | C30: =CALC!$G$44 | D30: =CALC!$H$44 | E30: =CALC!$I$44 | F30: =CALC!$K$44
A31: =CALC!$A$45 | B31: =CALC!$F$45 | C31: =CALC!$G$45 | D31: =CALC!$H$45 | E31: =CALC!$I$45 | F31: =CALC!$K$45
A32: =CALC!$A$46 | B32: =CALC!$F$46 | C32: =CALC!$G$46 | D32: =CALC!$H$46 | E32: =CALC!$I$46 | F32: =CALC!$K$46
A33: =CALC!$A$47 | B33: =CALC!$F$47 | C33: =CALC!$G$47 | D33: =CALC!$H$47 | E33: =CALC!$I$47 | F33: =CALC!$K$47
A34: =CALC!$A$48 | B34: =CALC!$F$48 | C34: =CALC!$G$48 | D34: =CALC!$H$48 | E34: =CALC!$I$48 | F34: =CALC!$K$48
A35: =CALC!$A$49 | B35: =CALC!$F$49 | C35: =CALC!$G$49 | D35: =CALC!$H$49 | E35: =CALC!$I$49 | F35: =CALC!$K$49
A38: DTNH-02 · Matrículas Ativas por Curso · alimentação mensal · detalhe por curso
A39: Valor na referência | B39: Valor na comparação | C39: Variação | D39: Meta vigente | E39: Limiar de atenção | F39: Falta p/ a meta | G39: Falta p/ o limiar | H39: Atingimento | I39: Status | J39: Situação | K39: Lançamentos
A40: =CALC!$B$70 | B40: =CALC!$C$70 | C40: =CALC!$D$70 | D40: =CALC!$E$70 | E40: =CALC!$F$70 | F40: =CALC!$G$70 | G40: =CALC!$H$70 | H40: =CALC!$I$70 | I40: =CALC!$J$70 | J40: =CALC!$K$70 | K40: =CALC!$L$70
A57: Curso | B57: Referência | C57: Comparação | D57: Variação | E57: Meta | F57: Status
A58: =CALC!$A$74 | B58: =CALC!$C$74 | C58: =CALC!$D$74 | D58: =CALC!$E$74 | E58: =CALC!$F$74 | F58: =CALC!$H$74
A59: =CALC!$A$75 | B59: =CALC!$C$75 | C59: =CALC!$D$75 | D59: =CALC!$E$75 | E59: =CALC!$F$75 | F59: =CALC!$H$75
A60: =CALC!$A$76 | B60: =CALC!$C$76 | C60: =CALC!$D$76 | D60: =CALC!$E$76 | E60: =CALC!$F$76 | F60: =CALC!$H$76
A61: =CALC!$A$77 | B61: =CALC!$C$77 | C61: =CALC!$D$77 | D61: =CALC!$E$77 | E61: =CALC!$F$77 | F61: =CALC!$H$77
A62: =CALC!$A$78 | B62: =CALC!$C$78 | C62: =CALC!$D$78 | D62: =CALC!$E$78 | E62: =CALC!$F$78 | F62: =CALC!$H$78
A63: =CALC!$A$79 | B63: =CALC!$C$79 | C63: =CALC!$D$79 | D63: =CALC!$E$79 | E63: =CALC!$F$79 | F63: =CALC!$H$79
A64: =CALC!$A$80 | B64: =CALC!$C$80 | C64: =CALC!$D$80 | D64: =CALC!$E$80 | E64: =CALC!$F$80 | F64: =CALC!$H$80
A65: =CALC!$A$81 | B65: =CALC!$C$81 | C65: =CALC!$D$81 | D65: =CALC!$E$81 | E65: =CALC!$F$81 | F65: =CALC!$H$81
A66: =CALC!$A$82 | B66: =CALC!$C$82 | C66: =CALC!$D$82 | D66: =CALC!$E$82 | E66: =CALC!$F$82 | F66: =CALC!$H$82
A69: DTNH-03 · Frequência Média Discente · alimentação mensal · detalhe por curso e disciplina
A70: Valor na referência | B70: Valor na comparação | C70: Variação | D70: Meta vigente | E70: Limiar de atenção | F70: Falta p/ a meta | G70: Falta p/ o limiar | H70: Atingimento | I70: Status | J70: Situação | K70: Lançamentos
A71: =CALC!$B$103 | B71: =CALC!$C$103 | C71: =CALC!$D$103 | D71: =CALC!$E$103 | E71: =CALC!$F$103 | F71: =CALC!$G$103 | G71: =CALC!$H$103 | H71: =CALC!$I$103 | I71: =CALC!$J$103 | J71: =CALC!$K$103 | K71: =CALC!$L$103
A88: Curso | B88: Referência | C88: Comparação | D88: Variação | E88: Meta | F88: Status
A89: =CALC!$A$107 | B89: =CALC!$D$107 | C89: =CALC!$E$107 | D89: =CALC!$F$107 | E89: =CALC!$G$107 | F89: =CALC!$I$107
A90: =CALC!$A$108 | B90: =CALC!$D$108 | C90: =CALC!$E$108 | D90: =CALC!$F$108 | E90: =CALC!$G$108 | F90: =CALC!$I$108
A91: =CALC!$A$109 | B91: =CALC!$D$109 | C91: =CALC!$E$109 | D91: =CALC!$F$109 | E91: =CALC!$G$109 | F91: =CALC!$I$109
A92: =CALC!$A$110 | B92: =CALC!$D$110 | C92: =CALC!$E$110 | D92: =CALC!$F$110 | E92: =CALC!$G$110 | F92: =CALC!$I$110
A93: =CALC!$A$111 | B93: =CALC!$D$111 | C93: =CALC!$E$111 | D93: =CALC!$F$111 | E93: =CALC!$G$111 | F93: =CALC!$I$111
A94: =CALC!$A$112 | B94: =CALC!$D$112 | C94: =CALC!$E$112 | D94: =CALC!$F$112 | E94: =CALC!$G$112 | F94: =CALC!$I$112
...

Sheet QUALIDADE E GOVERNANÇA
A1: QUALIDADE DOS DADOS E GOVERNANÇA DO PROTÓTIPO
A2: Controles criados para reduzir dupla contagem, inconsistência de cadastro e decisões baseadas em dados incompletos.
A4: CONTROLES AUTOMÁTICOS
A5: Base | B5: Regra verificada | C5: Erros atuais | D5: Risco de gestão | E5: Ação recomendada | F5: Prioridade
A6: NPS Discente | B6: Respondentes = promotores + neutros + detratores, sem negativos e sem chave duplicada | C6: =COUNTIF('NPS DISCENTES'!$J$5:$J$1200,"ERRO*") | D6: NPS distorcido ou pesquisas contadas duas vezes | E6: Corrigir todas as linhas com erro antes da reunião de gestão | F6: Crítica
A7: Matrículas Ativas | B7: Valor não negativo e apenas uma fotografia por período e curso | C7: =COUNTIF('MATRICULAS ATIVAS'!$G$5:$G$1200,"ERRO*") | D7: Estoque inflado e comparação mensal incorreta | E7: Manter somente o fechamento oficial do mês | F7: Crítica
A8: Frequência Média | B8: Registradas não superam previstas, chave única e disciplina vinculada ao curso | C8: =COUNTIF('FREQUÊNCIA MÉDIA'!$I$5:$I$1200,"ERRO*") | D8: Taxa de frequência inválida e recorte acadêmico incorreto | E8: Corrigir vínculo e bases antes de publicar o KPI | F8: Crítica
A11: AVALIAÇÃO DO DESENHO DO PAINEL
A12: Tema | B12: Diagnóstico | C12: Decisão aplicada | D12: Próximo passo recomendado | E12: Prazo sugerido | F12: Responsável
A13: Granularidade temporal | B13: A flexibilidade semanal, quinzenal, mensal e semestral é útil, porém a soma por prefixo permite dupla contagem quando há mês inteiro junto com subperíodos. | C13: Incluída regra explícita de competência e validação por KPI. | D13: Na próxima versão, substituir o modelo por competência + data inicial + data final e bloquear sobreposição de intervalos. | E13: Próxima versão | F13: Responsável técnico
A14: Frequência mensal | B14: A frequência é corretamente ponderada por presenças previstas, porém repetir o mesmo resultado em seis meses pode ser interpretado como série mensal. | C14: A competência da frequência deve ser mensal (AAAA-MM) e única por curso e disciplina. | D14: No gráfico, utilizar um ponto por mês; períodos sem alimentação permanecem sem resultado. | E14: Curto prazo | F14: Responsável técnico
A15: Matrículas ativas | B15: É KPI de estoque e deve representar a fotografia oficial do mês. | C15: Mantida alimentação mensal e reforçada a definição como fotografia de fechamento. | D15: Definir data oficial de corte e fonte institucional única, por exemplo Secretaria Acadêmica. | E15: Antes da implantação | F15: Diretoria + Secretaria
A16: NPS | B16: A fórmula consolidada é ponderada por respondentes e está adequada. Faltava controle sobre composição e duplicidade. | C16: Adicionada validação automática em cada linha. | D16: Adicionar taxa de resposta e intervalo de confiança/amostra mínima para evitar decisões sobre amostras pequenas. | E16: Curto prazo | F16: CPA + Diretoria
A17: Metas | B17: A estrutura permite meta total e específica por recorte, com vigência, mas as fórmulas são extensas e difíceis de auditar. | C17: Preservada para compatibilidade. | D17: Criar uma tabela de metas vigentes normalizada e uma coluna de chave única para simplificar cálculos e manutenção. | E17: Médio prazo | F17: Responsável técnico
A18: Plano de ação | B18: A vinculação a recortes fora da meta é um ponto forte, porém quantidade de planos abertos não garante cobertura correta do mesmo recorte. | C18: Mantido o controle atual. | D18: Criar chave Mês + KPI + Recorte e comparar chaves, evitando que planos de um recorte sejam contabilizados em outro. | E18: Curto prazo | F18: Diretoria
A19: Escopo de KPIs | B19: Três KPIs são adequados para o protótipo atual, mas a matriz institucional prevê expansão progressiva. | C19: Mantido o escopo enxuto para piloto. | D19: Após estabilizar dados, incorporar NPS Docente, cumprimento de registros, titulação docente, reprovação e produção acadêmica. | E19: Fase 2 | F19: Reitoria + Diretoria
A20: Cadastro de disciplinas | B20: A lista atual é declaradamente ilustrativa e não pode ser tratada como grade oficial. | C20: Incluído controle de vínculo curso-disciplina. | D20: Substituir por extração oficial da matriz curricular, com código da disciplina, turma, docente e vigência. | E20: Antes da implantação | F20: Secretaria Acadêmica
A23: CRITÉRIOS DE LIBERAÇÃO PARA USO GERENCIAL
A24: ☐ | B24: Zero linhas com erro nas três bases de entrada.
A25: ☐ | B25: Fonte oficial, responsável e data de corte definidos para cada KPI.
A26: ☐ | B26: Metas aprovadas e registradas com vigência.
A27: ☐ | B27: Nenhuma competência com granularidades sobrepostas.
A28: ☐ | B28: Planos de ação vinculados pela chave exata do recorte fora da meta.
A29: ☐ | B29: Grade de disciplinas substituída pela base acadêmica oficial.

Sheet MATRIZ
A1: CADA CURSO AO LONGO DOS MESES DA JANELA
A2: Colunas em branco são meses fora da janela. Nas últimas colunas, a comparação entre o mês de referência e o de comparação. No DTNH-02 é a variação que define o status.
A4: DTNH-01 — NPS Discente da Área
A5: Curso | B5: =CALC!$B$22 | C5: =CALC!$B$23 | D5: =CALC!$B$24 | E5: =CALC!$B$25 | F5: =CALC!$B$26 | G5: =CALC!$B$27 | H5: =CALC!$B$28 | I5: =CALC!$B$29 | J5: =CALC!$B$30 | K5: =CALC!$B$31 | L5: =CALC!$B$32 | M5: =CALC!$B$33 | N5: Referência | O5: Comparação | P5: Variação | Q5: Meta | R5: Status
A6: =CURSOS!$A$5 | B6: =IF(B$5="","",IF(COUNTIFS(Tabela3[Período],B$5,Tabela3[Curso],$A6)=0,"",IFERROR((SUMIFS(Tabela3[Promotores (9-10)],Tabela3[Período],B$5,Tabela3[Curso],$A6)-SUMIFS(Tabela3[Detratores (0-6)],Tabela3[Período],B$5,Tabela3[Curso],$A6))/SUMIFS(Tabela3[Respondentes],Tabela3[Período],B$5,Tabela3[Curso],$A6)*100,""))) | C6: =IF(C$5="","",IF(COUNTIFS(Tabela3[Período],C$5,Tabela3[Curso],$A6)=0,"",IFERROR((SUMIFS(Tabela3[Promotores (9-10)],Tabela3[Período],C$5,Tabela3[Curso],$A6)-SUMIFS(Tabela3[Detratores (0-6)],Tabela3[Período],C$5,Tabela3[Curso],$A6))/SUMIFS(Tabela3[Respondentes],Tabela3[Período],C$5,Tabela3[Curso],$A6)*100,""))) | D6: =IF(D$5="","",IF(COUNTIFS(Tabela3[Período],D$5,Tabela3[Curso],$A6)=0,"",IFERROR((SUMIFS(Tabela3[Promotores (9-10)],Tabela3[Período],D$5,Tabela3[Curso],$A6)-SUMIFS(Tabela3[Detratores (0-6)],Tabela3[Período],D$5,Tabela3[Curso],$A6))/SUMIFS(Tabela3[Respondentes],Tabela3[Período],D$5,Tabela3[Curso],$A6)*100,""))) | E6: =IF(E$5="","",IF(COUNTIFS(Tabela3[Período],E$5,Tabela3[Curso],$A6)=0,"",IFERROR((SUMIFS(Tabela3[Promotores (9-10)],Tabela3[Período],E$5,Tabela3[Curso],$A6)-SUMIFS(Tabela3[Detratores (0-6)],Tabela3[Período],E$5,Tabela3[Curso],$A6))/SUMIFS(Tabela3[Respondentes],Tabela3[Período],E$5,Tabela3[Curso],$A6)*100,""))) | F6: =IF(F$5="","",IF(COUNTIFS(Tabela3[Período],F$5,Tabela3[Curso],$A6)=0,"",IFERROR((SUMIFS(Tabela3[Promotores (9-10)],Tabela3[Período],F$5,Tabela3[Curso],$A6)-SUMIFS(Tabela3[Detratores (0-6)],Tabela3[Período],F$5,Tabela3[Curso],$A6))/SUMIFS(Tabela3[Respondentes],Tabela3[Período],F$5,Tabela3[Curso],$A6)*100,""))) | G6: =IF(G$5="","",IF(COUNTIFS(Tabela3[Período],G$5,Tabela3[Curso],$A6)=0,"",IFERROR((SUMIFS(Tabela3[Promotores (9-10)],Tabela3[Período],G$5,Tabela3[Curso],$A6)-SUMIFS(Tabela3[Detratores (0-6)],Tabela3[Período],G$5,Tabela3[Curso],$A6))/SUMIFS(Tabela3[Respondentes],Tabela3[Período],G$5,Tabela3[Curso],$A6)*100,""))) | H6: =IF(H$5="","",IF(COUNTIFS(Tabela3[Período],H$5,Tabela3[Curso],$A6)=0,"",IFERROR((SUMIFS(Tabela3[Promotores (9-10)],Tabela3[Período],H$5,Tabela3[Curso],$A6)-SUMIFS(Tabela3[Detratores (0-6)],Tabela3[Período],H$5,Tabela3[Curso],$A6))/SUMIFS(Tabela3[Respondentes],Tabela3[Período],H$5,Tabela3[Curso],$A6)*100,""))) | I6: =IF(I$5="","",IF(COUNTIFS(Tabela3[Período],I$5,Tabela3[Curso],$A6)=0,"",IFERROR((SUMIFS(Tabela3[Promotores (9-10)],Tabela3[Período],I$5,Tabela3[Curso],$A6)-SUMIFS(Tabela3[Detratores (0-6)],Tabela3[Período],I$5,Tabela3[Curso],$A6))/SUMIFS(Tabela3[Respondentes],Tabela3[Período],I$5,Tabela3[Curso],$A6)*100,""))) | ... M6: =IF(M$5="","",IF(COUNTIFS(Tabela3[Período],M$5,Tabela3[Curso],$A6)=0,"",IFERROR((SUMIFS(Tabela3[Promotores (9-10)],Tabela3[Período],M$5,Tabela3[Curso],$A6)-SUMIFS(Tabela3[Detratores (0-6)],Tabela3[Período],M$5,Tabela3[Curso],$A6))/SUMIFS(Tabela3[Respondentes],Tabela3[Período],M$5,Tabela3[Curso],$A6)*100,""))) | N6: =IF(CALC!$N$37="","",IF(COUNTIFS(Tabela3[Período],CALC!$N$37,Tabela3[Curso],$A6)=0,"",IFERROR((SUMIFS(Tabela3[Promotores (9-10)],Tabela3[Período],CALC!$N$37,Tabela3[Curso],$A6)-SUMIFS(Tabela3[Detratores (0-6)],Tabela3[Período],CALC!$N$37,Tabela3[Curso],$A6))/SUMIFS(Tabela3[Respondentes],Tabela3[Período],CALC!$N$37,Tabela3[Curso],$A6)*100,""))) | O6: =IF(CALC!$O$37="","",IF(COUNTIFS(Tabela3[Período],CALC!$O$37,Tabela3[Curso],$A6)=0,"",IFERROR((SUMIFS(Tabela3[Promotores (9-10)],Tabela3[Período],CALC!$O$37,Tabela3[Curso],$A6)-SUMIFS(Tabela3[Detratores (0-6)],Tabela3[Período],CALC!$O$37,Tabela3[Curso],$A6))/SUMIFS(Tabela3[Respondentes],Tabela3[Período],CALC!$O$37,Tabela3[Curso],$A6)*100,""))) | P6: =IF(OR(N6="",O6=""),"",N6-O6) | Q6: =IFERROR(INDEX(CALC!$B$8:$B$17,MATCH($A6,CALC!$A$8:$A$17,0)),"") | R6: =IF(OR(N6="",Q6=""),"",IF(ROUND(N6,6)>=ROUND(Q6,6),"Dentro da meta",IF(AND(IFERROR(IFERROR(INDEX(CALC!$C$8:$C$17,MATCH($A6,CALC!$A$8:$A$17,0)),""),"")<>"",ROUND(N6,6)>=ROUND(IFERROR(IFERROR(INDEX(CALC!$C$8:$C$17,MATCH($A6,CALC!$A$8:$A$17,0)),""),""),6)),"Atenção","Fora da meta")))
A7: =CURSOS!$A$6 | B7: =IF(B$5="","",IF(COUNTIFS(Tabela3[Período],B$5,Tabela3[Curso],$A7)=0,"",IFERROR((SUMIFS(Tabela3[Promotores (9-10)],Tabela3[Período],B$5,Tabela3[Curso],$A7)-SUMIFS(Tabela3[Detratores (0-6)],Tabela3[Período],B$5,Tabela3[Curso],$A7))/SUMIFS(Tabela3[Respondentes],Tabela3[Período],B$5,Tabela3[Curso],$A7)*100,""))) | C7: =IF(C$5="","",IF(COUNTIFS(Tabela3[Período],C$5,Tabela3[Curso],$A7)=0,"",IFERROR((SUMIFS(Tabela3[Promotores (9-10)],Tabela3[Período],C$5,Tabela3[Curso],$A7)-SUMIFS(Tabela3[Detratores (0-6)],Tabela3[Período],C$5,Tabela3[Curso],$A7))/SUMIFS(Tabela3[Respondentes],Tabela3[Período],C$5,Tabela3[Curso],$A7)*100,""))) | D7: =IF(D$5="","",IF(COUNTIFS(Tabela3[Período],D$5,Tabela3[Curso],$A7)=0,"",IFERROR((SUMIFS(Tabela3[Promotores (9-10)],Tabela3[Período],D$5,Tabela3[Curso],$A7)-SUMIFS(Tabela3[Detratores (0-6)],Tabela3[Período],D$5,Tabela3[Curso],$A7))/SUMIFS(Tabela3[Respondentes],Tabela3[Período],D$5,Tabela3[Curso],$A7)*100,""))) | E7: =IF(E$5="","",IF(COUNTIFS(Tabela3[Período],E$5,Tabela3[Curso],$A7)=0,"",IFERROR((SUMIFS(Tabela3[Promotores (9-10)],Tabela3[Período],E$5,Tabela3[Curso],$A7)-SUMIFS(Tabela3[Detratores (0-6)],Tabela3[Período],E$5,Tabela3[Curso],$A7))/SUMIFS(Tabela3[Respondentes],Tabela3[Período],E$5,Tabela3[Curso],$A7)*100,""))) | F7: =IF(F$5="","",IF(COUNTIFS(Tabela3[Período],F$5,Tabela3[Curso],$A7)=0,"",IFERROR((SUMIFS(Tabela3[Promotores (9-10)],Tabela3[Período],F$5,Tabela3[Curso],$A7)-SUMIFS(Tabela3[Detratores (0-6)],Tabela3[Período],F$5,Tabela3[Curso],$A7))/SUMIFS(Tabela3[Respondentes],Tabela3[Período],F$5,Tabela3[Curso],$A7)*100,""))) | G7: =IF(G$5="","",IF(COUNTIFS(Tabela3[Período],G$5,Tabela3[Curso],$A7)=0,"",IFERROR((SUMIFS(Tabela3[Promotores (9-10)],Tabela3[Período],G$5,Tabela3[Curso],$A7)-SUMIFS(Tabela3[Detratores (0-6)],Tabela3[Período],G$5,Tabela3[Curso],$A7))/SUMIFS(Tabela3[Respondentes],Tabela3[Período],G$5,Tabela3[Curso],$A7)*100,""))) | H7: =IF(H$5="","",IF(COUNTIFS(Tabela3[Período],H$5,Tabela3[Curso],$A7)=0,"",IFERROR((SUMIFS(Tabela3[Promotores (9-10)],Tabela3[Período],H$5,Tabela3[Curso],$A7)-SUMIFS(Tabela3[Detratores (0-6)],Tabela3[Período],H$5,Tabela3[Curso],$A7))/SUMIFS(Tabela3[Respondentes],Tabela3[Período],H$5,Tabela3[Curso],$A7)*100,""))) | I7: =IF(I$5="","",IF(COUNTIFS(Tabela3[Período],I$5,Tabela3[Curso],$A7)=0,"",IFERROR((SUMIFS(Tabela3[Promotores (9-10)],Tabela3[Período],I$5,Tabela3[Curso],$A7)-SUMIFS(Tabela3[Detratores (0-6)],Tabela3[Período],I$5,Tabela3[Curso],$A7))/SUMIFS(Tabela3[Respondentes],Tabela3[Período],I$5,Tabela3[Curso],$A7)*100,""))) | ... M7: =IF(M$5="","",IF(COUNTIFS(Tabela3[Período],M$5,Tabela3[Curso],$A7)=0,"",IFERROR((SUMIFS(Tabela3[Promotores (9-10)],Tabela3[Período],M$5,Tabela3[Curso],$A7)-SUMIFS(Tabela3[Detratores (0-6)],Tabela3[Período],M$5,Tabela3[Curso],$A7))/SUMIFS(Tabela3[Respondentes],Tabela3[Período],M$5,Tabela3[Curso],$A7)*100,""))) | N7: =IF(CALC!$N$37="","",IF(COUNTIFS(Tabela3[Período],CALC!$N$37,Tabela3[Curso],$A7)=0,"",IFERROR((SUMIFS(Tabela3[Promotores (9-10)],Tabela3[Período],CALC!$N$37,Tabela3[Curso],$A7)-SUMIFS(Tabela3[Detratores (0-6)],Tabela3[Período],CALC!$N$37,Tabela3[Curso],$A7))/SUMIFS(Tabela3[Respondentes],Tabela3[Período],CALC!$N$37,Tabela3[Curso],$A7)*100,""))) | O7: =IF(CALC!$O$37="","",IF(COUNTIFS(Tabela3[Período],CALC!$O$37,Tabela3[Curso],$A7)=0,"",IFERROR((SUMIFS(Tabela3[Promotores (9-10)],Tabela3[Período],CALC!$O$37,Tabela3[Curso],$A7)-SUMIFS(Tabela3[Detratores (0-6)],Tabela3[Período],CALC!$O$37,Tabela3[Curso],$A7))/SUMIFS(Tabela3[Respondentes],Tabela3[Período],CALC!$O$37,Tabela3[Curso],$A7)*100,""))) | P7: =IF(OR(N7="",O7=""),"",N7-O7) | Q7: =IFERROR(INDEX(CALC!$B$8:$B$17,MATCH($A7,CALC!$A$8:$A$17,0)),"") | R7: =IF(OR(N7="",Q7=""),"",IF(ROUND(N7,6)>=ROUND(Q7,6),"Dentro da meta",IF(AND(IFERROR(IFERROR(INDEX(CALC!$C$8:$C$17,MATCH($A7,CALC!$A$8:$A$17,0)),""),"")<>"",ROUND(N7,6)>=ROUND(IFERROR(IFERROR(INDEX(CALC!$C$8:$C$17,MATCH($A7,CALC!$A$8:$A$17,0)),""),""),6)),"Atenção","Fora da meta")))
A8: =CURSOS!$A$7 | B8: =IF(B$5="","",IF(COUNTIFS(Tabela3[Período],B$5,Tabela3[Curso],$A8)=0,"",IFERROR((SUMIFS(Tabela3[Promotores (9-10)],Tabela3[Período],B$5,Tabela3[Curso],$A8)-SUMIFS(Tabela3[Detratores (0-6)],Tabela3[Período],B$5,Tabela3[Curso],$A8))/SUMIFS(Tabela3[Respondentes],Tabela3[Período],B$5,Tabela3[Curso],$A8)*100,""))) | C8: =IF(C$5="","",IF(COUNTIFS(Tabela3[Período],C$5,Tabela3[Curso],$A8)=0,"",IFERROR((SUMIFS(Tabela3[Promotores (9-10)],Tabela3[Período],C$5,Tabela3[Curso],$A8)-SUMIFS(Tabela3[Detratores (0-6)],Tabela3[Período],C$5,Tabela3[Curso],$A8))/SUMIFS(Tabela3[Respondentes],Tabela3[Período],C$5,Tabela3[Curso],$A8)*100,""))) | D8: =IF(D$5="","",IF(COUNTIFS(Tabela3[Período],D$5,Tabela3[Curso],$A8)=0,"",IFERROR((SUMIFS(Tabela3[Promotores (9-10)],Tabela3[Período],D$5,Tabela3[Curso],$A8)-SUMIFS(Tabela3[Detratores (0-6)],Tabela3[Período],D$5,Tabela3[Curso],$A8))/SUMIFS(Tabela3[Respondentes],Tabela3[Período],D$5,Tabela3[Curso],$A8)*100,""))) | E8: =IF(E$5="","",IF(COUNTIFS(Tabela3[Período],E$5,Tabela3[Curso],$A8)=0,"",IFERROR((SUMIFS(Tabela3[Promotores (9-10)],Tabela3[Período],E$5,Tabela3[Curso],$A8)-SUMIFS(Tabela3[Detratores (0-6)],Tabela3[Período],E$5,Tabela3[Curso],$A8))/SUMIFS(Tabela3[Respondentes],Tabela3[Período],E$5,Tabela3[Curso],$A8)*100,""))) | F8: =IF(F$5="","",IF(COUNTIFS(Tabela3[Período],F$5,Tabela3[Curso],$A8)=0,"",IFERROR((SUMIFS(Tabela3[Promotores (9-10)],Tabela3[Período],F$5,Tabela3[Curso],$A8)-SUMIFS(Tabela3[Detratores (0-6)],Tabela3[Período],F$5,Tabela3[Curso],$A8))/SUMIFS(Tabela3[Respondentes],Tabela3[Período],F$5,Tabela3[Curso],$A8)*100,""))) | G8: =IF(G$5="","",IF(COUNTIFS(Tabela3[Período],G$5,Tabela3[Curso],$A8)=0,"",IFERROR((SUMIFS(Tabela3[Promotores (9-10)],Tabela3[Período],G$5,Tabela3[Curso],$A8)-SUMIFS(Tabela3[Detratores (0-6)],Tabela3[Período],G$5,Tabela3[Curso],$A8))/SUMIFS(Tabela3[Respondentes],Tabela3[Período],G$5,Tabela3[Curso],$A8)*100,""))) | H8: =IF(H$5="","",IF(COUNTIFS(Tabela3[Período],H$5,Tabela3[Curso],$A8)=0,"",IFERROR((SUMIFS(Tabela3[Promotores (9-10)],Tabela3[Período],H$5,Tabela3[Curso],$A8)-SUMIFS(Tabela3[Detratores (0-6)],Tabela3[Período],H$5,Tabela3[Curso],$A8))/SUMIFS(Tabela3[Respondentes],Tabela3[Período],H$5,Tabela3[Curso],$A8)*100,""))) | I8: =IF(I$5="","",IF(COUNTIFS(Tabela3[Período],I$5,Tabela3[Curso],$A8)=0,"",IFERROR((SUMIFS(Tabela3[Promotores (9-10)],Tabela3[Período],I$5,Tabela3[Curso],$A8)-SUMIFS(Tabela3[Detratores (0-6)],Tabela3[Período],I$5,Tabela3[Curso],$A8))/SUMIFS(Tabela3[Respondentes],Tabela3[Período],I$5,Tabela3[Curso],$A8)*100,""))) | ... M8: =IF(M$5="","",IF(COUNTIFS(Tabela3[Período],M$5,Tabela3[Curso],$A8)=0,"",IFERROR((SUMIFS(Tabela3[Promotores (9-10)],Tabela3[Período],M$5,Tabela3[Curso],$A8)-SUMIFS(Tabela3[Detratores (0-6)],Tabela3[Período],M$5,Tabela3[Curso],$A8))/SUMIFS(Tabela3[Respondentes],Tabela3[Período],M$5,Tabela3[Curso],$A8)*100,""))) | N8: =IF(CALC!$N$37="","",IF(COUNTIFS(Tabela3[Período],CALC!$N$37,Tabela3[Curso],$A8)=0,"",IFERROR((SUMIFS(Tabela3[Promotores (9-10)],Tabela3[Período],CALC!$N$37,Tabela3[Curso],$A8)-SUMIFS(Tabela3[Detratores (0-6)],Tabela3[Período],CALC!$N$37,Tabela3[Curso],$A8))/SUMIFS(Tabela3[Respondentes],Tabela3[Período],CALC!$N$37,Tabela3[Curso],$A8)*100,""))) | O8: =IF(CALC!$O$37="","",IF(COUNTIFS(Tabela3[Período],CALC!$O$37,Tabela3[Curso],$A8)=0,"",IFERROR((SUMIFS(Tabela3[Promotores (9-10)],Tabela3[Período],CALC!$O$37,Tabela3[Curso],$A8)-SUMIFS(Tabela3[Detratores (0-6)],Tabela3[Período],CALC!$O$37,Tabela3[Curso],$A8))/SUMIFS(Tabela3[Respondentes],Tabela3[Período],CALC!$O$37,Tabela3[Curso],$A8)*100,""))) | P8: =IF(OR(N8="",O8=""),"",N8-O8) | Q8: =IFERROR(INDEX(CALC!$B$8:$B$17,MATCH($A8,CALC!$A$8:$A$17,0)),"") | R8: =IF(OR(N8="",Q8=""),"",IF(ROUND(N8,6)>=ROUND(Q8,6),"Dentro da meta",IF(AND(IFERROR(IFERROR(INDEX(CALC!$C$8:$C$17,MATCH($A8,CALC!$A$8:$A$17,0)),""),"")<>"",ROUND(N8,6)>=ROUND(IFERROR(IFERROR(INDEX(CALC!$C$8:$C$17,MATCH($A8,CALC!$A$8:$A$17,0)),""),""),6)),"Atenção","Fora da meta")))
A9: =CURSOS!$A$8 | B9: =IF(B$5="","",IF(COUNTIFS(Tabela3[Período],B$5,Tabela3[Curso],$A9)=0,"",IFERROR((SUMIFS(Tabela3[Promotores (9-10)],Tabela3[Período],B$5,Tabela3[Curso],$A9)-SUMIFS(Tabela3[Detratores (0-6)],Tabela3[Período],B$5,Tabela3[Curso],$A9))/SUMIFS(Tabela3[Respondentes],Tabela3[Período],B$5,Tabela3[Curso],$A9)*100,""))) | C9: =IF(C$5="","",IF(COUNTIFS(Tabela3[Período],C$5,Tabela3[Curso],$A9)=0,"",IFERROR((SUMIFS(Tabela3[Promotores (9-10)],Tabela3[Período],C$5,Tabela3[Curso],$A9)-SUMIFS(Tabela3[Detratores (0-6)],Tabela3[Período],C$5,Tabela3[Curso],$A9))/SUMIFS(Tabela3[Respondentes],Tabela3[Período],C$5,Tabela3[Curso],$A9)*100,""))) | D9: =IF(D$5="","",IF(COUNTIFS(Tabela3[Período],D$5,Tabela3[Curso],$A9)=0,"",IFERROR((SUMIFS(Tabela3[Promotores (9-10)],Tabela3[Período],D$5,Tabela3[Curso],$A9)-SUMIFS(Tabela3[Detratores (0-6)],Tabela3[Período],D$5,Tabela3[Curso],$A9))/SUMIFS(Tabela3[Respondentes],Tabela3[Período],D$5,Tabela3[Curso],$A9)*100,""))) | E9: =IF(E$5="","",IF(COUNTIFS(Tabela3[Período],E$5,Tabela3[Curso],$A9)=0,"",IFERROR((SUMIFS(Tabela3[Promotores (9-10)],Tabela3[Período],E$5,Tabela3[Curso],$A9)-SUMIFS(Tabela3[Detratores (0-6)],Tabela3[Período],E$5,Tabela3[Curso],$A9))/SUMIFS(Tabela3[Respondentes],Tabela3[Período],E$5,Tabela3[Curso],$A9)*100,""))) | F9: =IF(F$5="","",IF(COUNTIFS(Tabela3[Período],F$5,Tabela3[Curso],$A9)=0,"",IFERROR((SUMIFS(Tabela3[Promotores (9-10)],Tabela3[Período],F$5,Tabela3[Curso],$A9)-SUMIFS(Tabela3[Detratores (0-6)],Tabela3[Período],F$5,Tabela3[Curso],$A9))/SUMIFS(Tabela3[Respondentes],Tabela3[Período],F$5,Tabela3[Curso],$A9)*100,""))) | G9: =IF(G$5="","",IF(COUNTIFS(Tabela3[Período],G$5,Tabela3[Curso],$A9)=0,"",IFERROR((SUMIFS(Tabela3[Promotores (9-10)],Tabela3[Período],G$5,Tabela3[Curso],$A9)-SUMIFS(Tabela3[Detratores (0-6)],Tabela3[Período],G$5,Tabela3[Curso],$A9))/SUMIFS(Tabela3[Respondentes],Tabela3[Período],G$5,Tabela3[Curso],$A9)*100,""))) | H9: =IF(H$5="","",IF(COUNTIFS(Tabela3[Período],H$5,Tabela3[Curso],$A9)=0,"",IFERROR((SUMIFS(Tabela3[Promotores (9-10)],Tabela3[Período],H$5,Tabela3[Curso],$A9)-SUMIFS(Tabela3[Detratores (0-6)],Tabela3[Período],H$5,Tabela3[Curso],$A9))/SUMIFS(Tabela3[Respondentes],Tabela3[Período],H$5,Tabela3[Curso],$A9)*100,""))) | I9: =IF(I$5="","",IF(COUNTIFS(Tabela3[Período],I$5,Tabela3[Curso],$A9)=0,"",IFERROR((SUMIFS(Tabela3[Promotores (9-10)],Tabela3[Período],I$5,Tabela3[Curso],$A9)-SUMIFS(Tabela3[Detratores (0-6)],Tabela3[Período],I$5,Tabela3[Curso],$A9))/SUMIFS(Tabela3[Respondentes],Tabela3[Período],I$5,Tabela3[Curso],$A9)*100,""))) | ... M9: =IF(M$5="","",IF(COUNTIFS(Tabela3[Período],M$5,Tabela3[Curso],$A9)=0,"",IFERROR((SUMIFS(Tabela3[Promotores (9-10)],Tabela3[Período],M$5,Tabela3[Curso],$A9)-SUMIFS(Tabela3[Detratores (0-6)],Tabela3[Período],M$5,Tabela3[Curso],$A9))/SUMIFS(Tabela3[Respondentes],Tabela3[Período],M$5,Tabela3[Curso],$A9)*100,""))) | N9: =IF(CALC!$N$37="","",IF(COUNTIFS(Tabela3[Período],CALC!$N$37,Tabela3[Curso],$A9)=0,"",IFERROR((SUMIFS(Tabela3[Promotores (9-10)],Tabela3[Período],CALC!$N$37,Tabela3[Curso],$A9)-SUMIFS(Tabela3[Detratores (0-6)],Tabela3[Período],CALC!$N$37,Tabela3[Curso],$A9))/SUMIFS(Tabela3[Respondentes],Tabela3[Período],CALC!$N$37,Tabela3[Curso],$A9)*100,""))) | O9: =IF(CALC!$O$37="","",IF(COUNTIFS(Tabela3[Período],CALC!$O$37,Tabela3[Curso],$A9)=0,"",IFERROR((SUMIFS(Tabela3[Promotores (9-10)],Tabela3[Período],CALC!$O$37,Tabela3[Curso],$A9)-SUMIFS(Tabela3[Detratores (0-6)],Tabela3[Período],CALC!$O$37,Tabela3[Curso],$A9))/SUMIFS(Tabela3[Respondentes],Tabela3[Período],CALC!$O$37,Tabela3[Curso],$A9)*100,""))) | P9: =IF(OR(N9="",O9=""),"",N9-O9) | Q9: =IFERROR(INDEX(CALC!$B$8:$B$17,MATCH($A9,CALC!$A$8:$A$17,0)),"") | R9: =IF(OR(N9="",Q9=""),"",IF(ROUND(N9,6)>=ROUND(Q9,6),"Dentro da meta",IF(AND(IFERROR(IFERROR(INDEX(CALC!$C$8:$C$17,MATCH($A9,CALC!$A$8:$A$17,0)),""),"")<>"",ROUND(N9,6)>=ROUND(IFERROR(IFERROR(INDEX(CALC!$C$8:$C$17,MATCH($A9,CALC!$A$8:$A$17,0)),""),""),6)),"Atenção","Fora da meta")))
A10: =CURSOS!$A$9 | B10: =IF(B$5="","",IF(COUNTIFS(Tabela3[Período],B$5,Tabela3[Curso],$A10)=0,"",IFERROR((SUMIFS(Tabela3[Promotores (9-10)],Tabela3[Período],B$5,Tabela3[Curso],$A10)-SUMIFS(Tabela3[Detratores (0-6)],Tabela3[Período],B$5,Tabela3[Curso],$A10))/SUMIFS(Tabela3[Respondentes],Tabela3[Período],B$5,Tabela3[Curso],$A10)*100,""))) | C10: =IF(C$5="","",IF(COUNTIFS(Tabela3[Período],C$5,Tabela3[Curso],$A10)=0,"",IFERROR((SUMIFS(Tabela3[Promotores (9-10)],Tabela3[Período],C$5,Tabela3[Curso],$A10)-SUMIFS(Tabela3[Detratores (0-6)],Tabela3[Período],C$5,Tabela3[Curso],$A10))/SUMIFS(Tabela3[Respondentes],Tabela3[Período],C$5,Tabela3[Curso],$A10)*100,""))) | D10: =IF(D$5="","",IF(COUNTIFS(Tabela3[Período],D$5,Tabela3[Curso],$A10)=0,"",IFERROR((SUMIFS(Tabela3[Promotores (9-10)],Tabela3[Período],D$5,Tabela3[Curso],$A10)-SUMIFS(Tabela3[Detratores (0-6)],Tabela3[Período],D$5,Tabela3[Curso],$A10))/SUMIFS(Tabela3[Respondentes],Tabela3[Período],D$5,Tabela3[Curso],$A10)*100,""))) | E10: =IF(E$5="","",IF(COUNTIFS(Tabela3[Período],E$5,Tabela3[Curso],$A10)=0,"",IFERROR((SUMIFS(Tabela3[Promotores (9-10)],Tabela3[Período],E$5,Tabela3[Curso],$A10)-SUMIFS(Tabela3[Detratores (0-6)],Tabela3[Período],E$5,Tabela3[Curso],$A10))/SUMIFS(Tabela3[Respondentes],Tabela3[Período],E$5,Tabela3[Curso],$A10)*100,""))) | F10: =IF(F$5="","",IF(COUNTIFS(Tabela3[Período],F$5,Tabela3[Curso],$A10)=0,"",IFERROR((SUMIFS(Tabela3[Promotores (9-10)],Tabela3[Período],F$5,Tabela3[Curso],$A10)-SUMIFS(Tabela3[Detratores (0-6)],Tabela3[Período],F$5,Tabela3[Curso],$A10))/SUMIFS(Tabela3[Respondentes],Tabela3[Período],F$5,Tabela3[Curso],$A10)*100,""))) | G10: =IF(G$5="","",IF(COUNTIFS(Tabela3[Período],G$5,Tabela3[Curso],$A10)=0,"",IFERROR((SUMIFS(Tabela3[Promotores (9-10)],Tabela3[Período],G$5,Tabela3[Curso],$A10)-SUMIFS(Tabela3[Detratores (0-6)],Tabela3[Período],G$5,Tabela3[Curso],$A10))/SUMIFS(Tabela3[Respondentes],Tabela3[Período],G$5,Tabela3[Curso],$A10)*100,""))) | H10: =IF(H$5="","",IF(COUNTIFS(Tabela3[Período],H$5,Tabela3[Curso],$A10)=0,"",IFERROR((SUMIFS(Tabela3[Promotores (9-10)],Tabela3[Período],H$5,Tabela3[Curso],$A10)-SUMIFS(Tabela3[Detratores (0-6)],Tabela3[Período],H$5,Tabela3[Curso],$A10))/SUMIFS(Tabela3[Respondentes],Tabela3[Período],H$5,Tabela3[Curso],$A10)*100,""))) | I10: =IF(I$5="","",IF(COUNTIFS(Tabela3[Período],I$5,Tabela3[Curso],$A10)=0,"",IFERROR((SUMIFS(Tabela3[Promotores (9-10)],Tabela3[Período],I$5,Tabela3[Curso],$A10)-SUMIFS(Tabela3[Detratores (0-6)],Tabela3[Período],I$5,Tabela3[Curso],$A10))/SUMIFS(Tabela3[Respondentes],Tabela3[Período],I$5,Tabela3[Curso],$A10)*100,""))) | ... M10: =IF(M$5="","",IF(COUNTIFS(Tabela3[Período],M$5,Tabela3[Curso],$A10)=0,"",IFERROR((SUMIFS(Tabela3[Promotores (9-10)],Tabela3[Período],M$5,Tabela3[Curso],$A10)-SUMIFS(Tabela3[Detratores (0-6)],Tabela3[Período],M$5,Tabela3[Curso],$A10))/SUMIFS(Tabela3[Respondentes],Tabela3[Período],M$5,Tabela3[Curso],$A10)*100,""))) | N10: =IF(CALC!$N$37="","",IF(COUNTIFS(Tabela3[Período],CALC!$N$37,Tabela3[Curso],$A10)=0,"",IFERROR((SUMIFS(Tabela3[Promotores (9-10)],Tabela3[Período],CALC!$N$37,Tabela3[Curso],$A10)-SUMIFS(Tabela3[Detratores (0-6)],Tabela3[Período],CALC!$N$37,Tabela3[Curso],$A10))/SUMIFS(Tabela3[Respondentes],Tabela3[Período],CALC!$N$37,Tabela3[Curso],$A10)*100,""))) | O10: =IF(CALC!$O$37="","",IF(COUNTIFS(Tabela3[Período],CALC!$O$37,Tabela3[Curso],$A10)=0,"",IFERROR((SUMIFS(Tabela3[Promotores (9-10)],Tabela3[Período],CALC!$O$37,Tabela3[Curso],$A10)-SUMIFS(Tabela3[Detratores (0-6)],Tabela3[Período],CALC!$O$37,Tabela3[Curso],$A10))/SUMIFS(Tabela3[Respondentes],Tabela3[Período],CALC!$O$37,Tabela3[Curso],$A10)*100,""))) | P10: =IF(OR(N10="",O10=""),"",N10-O10) | Q10: =IFERROR(INDEX(CALC!$B$8:$B$17,MATCH($A10,CALC!$A$8:$A$17,0)),"") | R10: =IF(OR(N10="",Q10=""),"",IF(ROUND(N10,6)>=ROUND(Q10,6),"Dentro da meta",IF(AND(IFERROR(IFERROR(INDEX(CALC!$C$8:$C$17,MATCH($A10,CALC!$A$8:$A$17,0)),""),"")<>"",ROUND(N10,6)>=ROUND(IFERROR(IFERROR(INDEX(CALC!$C$8:$C$17,MATCH($A10,CALC!$A$8:$A$17,0)),""),""),6)),"Atenção","Fora da meta")))
A11: =CURSOS!$A$10 | B11: =IF(B$5="","",IF(COUNTIFS(Tabela3[Período],B$5,Tabela3[Curso],$A11)=0,"",IFERROR((SUMIFS(Tabela3[Promotores (9-10)],Tabela3[Período],B$5,Tabela3[Curso],$A11)-SUMIFS(Tabela3[Detratores (0-6)],Tabela3[Período],B$5,Tabela3[Curso],$A11))/SUMIFS(Tabela3[Respondentes],Tabela3[Período],B$5,Tabela3[Curso],$A11)*100,""))) | C11: =IF(C$5="","",IF(COUNTIFS(Tabela3[Período],C$5,Tabela3[Curso],$A11)=0,"",IFERROR((SUMIFS(Tabela3[Promotores (9-10)],Tabela3[Período],C$5,Tabela3[Curso],$A11)-SUMIFS(Tabela3[Detratores (0-6)],Tabela3[Período],C$5,Tabela3[Curso],$A11))/SUMIFS(Tabela3[Respondentes],Tabela3[Período],C$5,Tabela3[Curso],$A11)*100,""))) | D11: =IF(D$5="","",IF(COUNTIFS(Tabela3[Período],D$5,Tabela3[Curso],$A11)=0,"",IFERROR((SUMIFS(Tabela3[Promotores (9-10)],Tabela3[Período],D$5,Tabela3[Curso],$A11)-SUMIFS(Tabela3[Detratores (0-6)],Tabela3[Período],D$5,Tabela3[Curso],$A11))/SUMIFS(Tabela3[Respondentes],Tabela3[Período],D$5,Tabela3[Curso],$A11)*100,""))) | E11: =IF(E$5="","",IF(COUNTIFS(Tabela3[Período],E$5,Tabela3[Curso],$A11)=0,"",IFERROR((SUMIFS(Tabela3[Promotores (9-10)],Tabela3[Período],E$5,Tabela3[Curso],$A11)-SUMIFS(Tabela3[Detratores (0-6)],Tabela3[Período],E$5,Tabela3[Curso],$A11))/SUMIFS(Tabela3[Respondentes],Tabela3[Período],E$5,Tabela3[Curso],$A11)*100,""))) | F11: =IF(F$5="","",IF(COUNTIFS(Tabela3[Período],F$5,Tabela3[Curso],$A11)=0,"",IFERROR((SUMIFS(Tabela3[Promotores (9-10)],Tabela3[Período],F$5,Tabela3[Curso],$A11)-SUMIFS(Tabela3[Detratores (0-6)],Tabela3[Período],F$5,Tabela3[Curso],$A11))/SUMIFS(Tabela3[Respondentes],Tabela3[Período],F$5,Tabela3[Curso],$A11)*100,""))) | G11: =IF(G$5="","",IF(COUNTIFS(Tabela3[Período],G$5,Tabela3[Curso],$A11)=0,"",IFERROR((SUMIFS(Tabela3[Promotores (9-10)],Tabela3[Período],G$5,Tabela3[Curso],$A11)-SUMIFS(Tabela3[Detratores (0-6)],Tabela3[Período],G$5,Tabela3[Curso],$A11))/SUMIFS(Tabela3[Respondentes],Tabela3[Período],G$5,Tabela3[Curso],$A11)*100,""))) | H11: =IF(H$5="","",IF(COUNTIFS(Tabela3[Período],H$5,Tabela3[Curso],$A11)=0,"",IFERROR((SUMIFS(Tabela3[Promotores (9-10)],Tabela3[Período],H$5,Tabela3[Curso],$A11)-SUMIFS(Tabela3[Detratores (0-6)],Tabela3[Período],H$5,Tabela3[Curso],$A11))/SUMIFS(Tabela3[Respondentes],Tabela3[Período],H$5,Tabela3[Curso],$A11)*100,""))) | I11: =IF(I$5="","",IF(COUNTIFS(Tabela3[Período],I$5,Tabela3[Curso],$A11)=0,"",IFERROR((SUMIFS(Tabela3[Promotores (9-10)],Tabela3[Período],I$5,Tabela3[Curso],$A11)-SUMIFS(Tabela3[Detratores (0-6)],Tabela3[Período],I$5,Tabela3[Curso],$A11))/SUMIFS(Tabela3[Respondentes],Tabela3[Período],I$5,Tabela3[Curso],$A11)*100,""))) | ... M11: =IF(M$5="","",IF(COUNTIFS(Tabela3[Período],M$5,Tabela3[Curso],$A11)=0,"",IFERROR((SUMIFS(Tabela3[Promotores (9-10)],Tabela3[Período],M$5,Tabela3[Curso],$A11)-SUMIFS(Tabela3[Detratores (0-6)],Tabela3[Período],M$5,Tabela3[Curso],$A11))/SUMIFS(Tabela3[Respondentes],Tabela3[Período],M$5,Tabela3[Curso],$A11)*100,""))) | N11: =IF(CALC!$N$37="","",IF(COUNTIFS(Tabela3[Período],CALC!$N$37,Tabela3[Curso],$A11)=0,"",IFERROR((SUMIFS(Tabela3[Promotores (9-10)],Tabela3[Período],CALC!$N$37,Tabela3[Curso],$A11)-SUMIFS(Tabela3[Detratores (0-6)],Tabela3[Período],CALC!$N$37,Tabela3[Curso],$A11))/SUMIFS(Tabela3[Respondentes],Tabela3[Período],CALC!$N$37,Tabela3[Curso],$A11)*100,""))) | O11: =IF(CALC!$O$37="","",IF(COUNTIFS(Tabela3[Período],CALC!$O$37,Tabela3[Curso],$A11)=0,"",IFERROR((SUMIFS(Tabela3[Promotores (9-10)],Tabela3[Período],CALC!$O$37,Tabela3[Curso],$A11)-SUMIFS(Tabela3[Detratores (0-6)],Tabela3[Período],CALC!$O$37,Tabela3[Curso],$A11))/SUMIFS(Tabela3[Respondentes],Tabela3[Período],CALC!$O$37,Tabela3[Curso],$A11)*100,""))) | P11: =IF(OR(N11="",O11=""),"",N11-O11) | Q11: =IFERROR(INDEX(CALC!$B$8:$B$17,MATCH($A11,CALC!$A$8:$A$17,0)),"") | R11: =IF(OR(N11="",Q11=""),"",IF(ROUND(N11,6)>=ROUND(Q11,6),"Dentro da meta",IF(AND(IFERROR(IFERROR(INDEX(CALC!$C$8:$C$17,MATCH($A11,CALC!$A$8:$A$17,0)),""),"")<>"",ROUND(N11,6)>=ROUND(IFERROR(IFERROR(INDEX(CALC!$C$8:$C$17,MATCH($A11,CALC!$A$8:$A$17,0)),""),""),6)),"Atenção","Fora da meta")))
A12: =CURSOS!$A$11 | B12: =IF(B$5="","",IF(COUNTIFS(Tabela3[Período],B$5,Tabela3[Curso],$A12)=0,"",IFERROR((SUMIFS(Tabela3[Promotores (9-10)],Tabela3[Período],B$5,Tabela3[Curso],$A12)-SUMIFS(Tabela3[Detratores (0-6)],Tabela3[Período],B$5,Tabela3[Curso],$A12))/SUMIFS(Tabela3[Respondentes],Tabela3[Período],B$5,Tabela3[Curso],$A12)*100,""))) | C12: =IF(C$5="","",IF(COUNTIFS(Tabela3[Período],C$5,Tabela3[Curso],$A12)=0,"",IFERROR((SUMIFS(Tabela3[Promotores (9-10)],Tabela3[Período],C$5,Tabela3[Curso],$A12)-SUMIFS(Tabela3[Detratores (0-6)],Tabela3[Período],C$5,Tabela3[Curso],$A12))/SUMIFS(Tabela3[Respondentes],Tabela3[Período],C$5,Tabela3[Curso],$A12)*100,""))) | D12: =IF(D$5="","",IF(COUNTIFS(Tabela3[Período],D$5,Tabela3[Curso],$A12)=0,"",IFERROR((SUMIFS(Tabela3[Promotores (9-10)],Tabela3[Período],D$5,Tabela3[Curso],$A12)-SUMIFS(Tabela3[Detratores (0-6)],Tabela3[Período],D$5,Tabela3[Curso],$A12))/SUMIFS(Tabela3[Respondentes],Tabela3[Período],D$5,Tabela3[Curso],$A12)*100,""))) | E12: =IF(E$5="","",IF(COUNTIFS(Tabela3[Período],E$5,Tabela3[Curso],$A12)=0,"",IFERROR((SUMIFS(Tabela3[Promotores (9-10)],Tabela3[Período],E$5,Tabela3[Curso],$A12)-SUMIFS(Tabela3[Detratores (0-6)],Tabela3[Período],E$5,Tabela3[Curso],$A12))/SUMIFS(Tabela3[Respondentes],Tabela3[Período],E$5,Tabela3[Curso],$A12)*100,""))) | F12: =IF(F$5="","",IF(COUNTIFS(Tabela3[Período],F$5,Tabela3[Curso],$A12)=0,"",IFERROR((SUMIFS(Tabela3[Promotores (9-10)],Tabela3[Período],F$5,Tabela3[Curso],$A12)-SUMIFS(Tabela3[Detratores (0-6)],Tabela3[Período],F$5,Tabela3[Curso],$A12))/SUMIFS(Tabela3[Respondentes],Tabela3[Período],F$5,Tabela3[Curso],$A12)*100,""))) | G12: =IF(G$5="","",IF(COUNTIFS(Tabela3[Período],G$5,Tabela3[Curso],$A12)=0,"",IFERROR((SUMIFS(Tabela3[Promotores (9-10)],Tabela3[Período],G$5,Tabela3[Curso],$A12)-SUMIFS(Tabela3[Detratores (0-6)],Tabela3[Período],G$5,Tabela3[Curso],$A12))/SUMIFS(Tabela3[Respondentes],Tabela3[Período],G$5,Tabela3[Curso],$A12)*100,""))) | H12: =IF(H$5="","",IF(COUNTIFS(Tabela3[Período],H$5,Tabela3[Curso],$A12)=0,"",IFERROR((SUMIFS(Tabela3[Promotores (9-10)],Tabela3[Período],H$5,Tabela3[Curso],$A12)-SUMIFS(Tabela3[Detratores (0-6)],Tabela3[Período],H$5,Tabela3[Curso],$A12))/SUMIFS(Tabela3[Respondentes],Tabela3[Período],H$5,Tabela3[Curso],$A12)*100,""))) | I12: =IF(I$5="","",IF(COUNTIFS(Tabela3[Período],I$5,Tabela3[Curso],$A12)=0,"",IFERROR((SUMIFS(Tabela3[Promotores (9-10)],Tabela3[Período],I$5,Tabela3[Curso],$A12)-SUMIFS(Tabela3[Detratores (0-6)],Tabela3[Período],I$5,Tabela3[Curso],$A12))/SUMIFS(Tabela3[Respondentes],Tabela3[Período],I$5,Tabela3[Curso],$A12)*100,""))) | ... M12: =IF(M$5="","",IF(COUNTIFS(Tabela3[Período],M$5,Tabela3[Curso],$A12)=0,"",IFERROR((SUMIFS(Tabela3[Promotores (9-10)],Tabela3[Período],M$5,Tabela3[Curso],$A12)-SUMIFS(Tabela3[Detratores (0-6)],Tabela3[Período],M$5,Tabela3[Curso],$A12))/SUMIFS(Tabela3[Respondentes],Tabela3[Período],M$5,Tabela3[Curso],$A12)*100,""))) | N12: =IF(CALC!$N$37="","",IF(COUNTIFS(Tabela3[Período],CALC!$N$37,Tabela3[Curso],$A12)=0,"",IFERROR((SUMIFS(Tabela3[Promotores (9-10)],Tabela3[Período],CALC!$N$37,Tabela3[Curso],$A12)-SUMIFS(Tabela3[Detratores (0-6)],Tabela3[Período],CALC!$N$37,Tabela3[Curso],$A12))/SUMIFS(Tabela3[Respondentes],Tabela3[Período],CALC!$N$37,Tabela3[Curso],$A12)*100,""))) | O12: =IF(CALC!$O$37="","",IF(COUNTIFS(Tabela3[Período],CALC!$O$37,Tabela3[Curso],$A12)=0,"",IFERROR((SUMIFS(Tabela3[Promotores (9-10)],Tabela3[Período],CALC!$O$37,Tabela3[Curso],$A12)-SUMIFS(Tabela3[Detratores (0-6)],Tabela3[Período],CALC!$O$37,Tabela3[Curso],$A12))/SUMIFS(Tabela3[Respondentes],Tabela3[Período],CALC!$O$37,Tabela3[Curso],$A12)*100,""))) | P12: =IF(OR(N12="",O12=""),"",N12-O12) | Q12: =IFERROR(INDEX(CALC!$B$8:$B$17,MATCH($A12,CALC!$A$8:$A$17,0)),"") | R12: =IF(OR(N12="",Q12=""),"",IF(ROUND(N12,6)>=ROUND(Q12,6),"Dentro da meta",IF(AND(IFERROR(IFERROR(INDEX(CALC!$C$8:$C$17,MATCH($A12,CALC!$A$8:$A$17,0)),""),"")<>"",ROUND(N12,6)>=ROUND(IFERROR(IFERROR(INDEX(CALC!$C$8:$C$17,MATCH($A12,CALC!$A$8:$A$17,0)),""),""),6)),"Atenção","Fora da meta")))
A13: =CURSOS!$A$12 | B13: =IF(B$5="","",IF(COUNTIFS(Tabela3[Período],B$5,Tabela3[Curso],$A13)=0,"",IFERROR((SUMIFS(Tabela3[Promotores (9-10)],Tabela3[Período],B$5,Tabela3[Curso],$A13)-SUMIFS(Tabela3[Detratores (0-6)],Tabela3[Período],B$5,Tabela3[Curso],$A13))/SUMIFS(Tabela3[Respondentes],Tabela3[Período],B$5,Tabela3[Curso],$A13)*100,""))) | C13: =IF(C$5="","",IF(COUNTIFS(Tabela3[Período],C$5,Tabela3[Curso],$A13)=0,"",IFERROR((SUMIFS(Tabela3[Promotores (9-10)],Tabela3[Período],C$5,Tabela3[Curso],$A13)-SUMIFS(Tabela3[Detratores (0-6)],Tabela3[Período],C$5,Tabela3[Curso],$A13))/SUMIFS(Tabela3[Respondentes],Tabela3[Período],C$5,Tabela3[Curso],$A13)*100,""))) | D13: =IF(D$5="","",IF(COUNTIFS(Tabela3[Período],D$5,Tabela3[Curso],$A13)=0,"",IFERROR((SUMIFS(Tabela3[Promotores (9-10)],Tabela3[Período],D$5,Tabela3[Curso],$A13)-SUMIFS(Tabela3[Detratores (0-6)],Tabela3[Período],D$5,Tabela3[Curso],$A13))/SUMIFS(Tabela3[Respondentes],Tabela3[Período],D$5,Tabela3[Curso],$A13)*100,""))) | E13: =IF(E$5="","",IF(COUNTIFS(Tabela3[Período],E$5,Tabela3[Curso],$A13)=0,"",IFERROR((SUMIFS(Tabela3[Promotores (9-10)],Tabela3[Período],E$5,Tabela3[Curso],$A13)-SUMIFS(Tabela3[Detratores (0-6)],Tabela3[Período],E$5,Tabela3[Curso],$A13))/SUMIFS(Tabela3[Respondentes],Tabela3[Período],E$5,Tabela3[Curso],$A13)*100,""))) | F13: =IF(F$5="","",IF(COUNTIFS(Tabela3[Período],F$5,Tabela3[Curso],$A13)=0,"",IFERROR((SUMIFS(Tabela3[Promotores (9-10)],Tabela3[Período],F$5,Tabela3[Curso],$A13)-SUMIFS(Tabela3[Detratores (0-6)],Tabela3[Período],F$5,Tabela3[Curso],$A13))/SUMIFS(Tabela3[Respondentes],Tabela3[Período],F$5,Tabela3[Curso],$A13)*100,""))) | G13: =IF(G$5="","",IF(COUNTIFS(Tabela3[Período],G$5,Tabela3[Curso],$A13)=0,"",IFERROR((SUMIFS(Tabela3[Promotores (9-10)],Tabela3[Período],G$5,Tabela3[Curso],$A13)-SUMIFS(Tabela3[Detratores (0-6)],Tabela3[Período],G$5,Tabela3[Curso],$A13))/SUMIFS(Tabela3[Respondentes],Tabela3[Período],G$5,Tabela3[Curso],$A13)*100,""))) | H13: =IF(H$5="","",IF(COUNTIFS(Tabela3[Período],H$5,Tabela3[Curso],$A13)=0,"",IFERROR((SUMIFS(Tabela3[Promotores (9-10)],Tabela3[Período],H$5,Tabela3[Curso],$A13)-SUMIFS(Tabela3[Detratores (0-6)],Tabela3[Período],H$5,Tabela3[Curso],$A13))/SUMIFS(Tabela3[Respondentes],Tabela3[Período],H$5,Tabela3[Curso],$A13)*100,""))) | I13: =IF(I$5="","",IF(COUNTIFS(Tabela3[Período],I$5,Tabela3[Curso],$A13)=0,"",IFERROR((SUMIFS(Tabela3[Promotores (9-10)],Tabela3[Período],I$5,Tabela3[Curso],$A13)-SUMIFS(Tabela3[Detratores (0-6)],Tabela3[Período],I$5,Tabela3[Curso],$A13))/SUMIFS(Tabela3[Respondentes],Tabela3[Período],I$5,Tabela3[Curso],$A13)*100,""))) | ... M13: =IF(M$5="","",IF(COUNTIFS(Tabela3[Período],M$5,Tabela3[Curso],$A13)=0,"",IFERROR((SUMIFS(Tabela3[Promotores (9-10)],Tabela3[Período],M$5,Tabela3[Curso],$A13)-SUMIFS(Tabela3[Detratores (0-6)],Tabela3[Período],M$5,Tabela3[Curso],$A13))/SUMIFS(Tabela3[Respondentes],Tabela3[Período],M$5,Tabela3[Curso],$A13)*100,""))) | N13: =IF(CALC!$N$37="","",IF(COUNTIFS(Tabela3[Período],CALC!$N$37,Tabela3[Curso],$A13)=0,"",IFERROR((SUMIFS(Tabela3[Promotores (9-10)],Tabela3[Período],CALC!$N$37,Tabela3[Curso],$A13)-SUMIFS(Tabela3[Detratores (0-6)],Tabela3[Período],CALC!$N$37,Tabela3[Curso],$A13))/SUMIFS(Tabela3[Respondentes],Tabela3[Período],CALC!$N$37,Tabela3[Curso],$A13)*100,""))) | O13: =IF(CALC!$O$37="","",IF(COUNTIFS(Tabela3[Período],CALC!$O$37,Tabela3[Curso],$A13)=0,"",IFERROR((SUMIFS(Tabela3[Promotores (9-10)],Tabela3[Período],CALC!$O$37,Tabela3[Curso],$A13)-SUMIFS(Tabela3[Detratores (0-6)],Tabela3[Período],CALC!$O$37,Tabela3[Curso],$A13))/SUMIFS(Tabela3[Respondentes],Tabela3[Período],CALC!$O$37,Tabela3[Curso],$A13)*100,""))) | P13: =IF(OR(N13="",O13=""),"",N13-O13) | Q13: =IFERROR(INDEX(CALC!$B$8:$B$17,MATCH($A13,CALC!$A$8:$A$17,0)),"") | R13: =IF(OR(N13="",Q13=""),"",IF(ROUND(N13,6)>=ROUND(Q13,6),"Dentro da meta",IF(AND(IFERROR(IFERROR(INDEX(CALC!$C$8:$C$17,MATCH($A13,CALC!$A$8:$A$17,0)),""),"")<>"",ROUND(N13,6)>=ROUND(IFERROR(IFERROR(INDEX(CALC!$C$8:$C$17,MATCH($A13,CALC!$A$8:$A$17,0)),""),""),6)),"Atenção","Fora da meta")))
A14: =CURSOS!$A$13 | B14: =IF(B$5="","",IF(COUNTIFS(Tabela3[Período],B$5,Tabela3[Curso],$A14)=0,"",IFERROR((SUMIFS(Tabela3[Promotores (9-10)],Tabela3[Período],B$5,Tabela3[Curso],$A14)-SUMIFS(Tabela3[Detratores (0-6)],Tabela3[Período],B$5,Tabela3[Curso],$A14))/SUMIFS(Tabela3[Respondentes],Tabela3[Período],B$5,Tabela3[Curso],$A14)*100,""))) | C14: =IF(C$5="","",IF(COUNTIFS(Tabela3[Período],C$5,Tabela3[Curso],$A14)=0,"",IFERROR((SUMIFS(Tabela3[Promotores (9-10)],Tabela3[Período],C$5,Tabela3[Curso],$A14)-SUMIFS(Tabela3[Detratores (0-6)],Tabela3[Período],C$5,Tabela3[Curso],$A14))/SUMIFS(Tabela3[Respondentes],Tabela3[Período],C$5,Tabela3[Curso],$A14)*100,""))) | D14: =IF(D$5="","",IF(COUNTIFS(Tabela3[Período],D$5,Tabela3[Curso],$A14)=0,"",IFERROR((SUMIFS(Tabela3[Promotores (9-10)],Tabela3[Período],D$5,Tabela3[Curso],$A14)-SUMIFS(Tabela3[Detratores (0-6)],Tabela3[Período],D$5,Tabela3[Curso],$A14))/SUMIFS(Tabela3[Respondentes],Tabela3[Período],D$5,Tabela3[Curso],$A14)*100,""))) | E14: =IF(E$5="","",IF(COUNTIFS(Tabela3[Período],E$5,Tabela3[Curso],$A14)=0,"",IFERROR((SUMIFS(Tabela3[Promotores (9-10)],Tabela3[Período],E$5,Tabela3[Curso],$A14)-SUMIFS(Tabela3[Detratores (0-6)],Tabela3[Período],E$5,Tabela3[Curso],$A14))/SUMIFS(Tabela3[Respondentes],Tabela3[Período],E$5,Tabela3[Curso],$A14)*100,""))) | F14: =IF(F$5="","",IF(COUNTIFS(Tabela3[Período],F$5,Tabela3[Curso],$A14)=0,"",IFERROR((SUMIFS(Tabela3[Promotores (9-10)],Tabela3[Período],F$5,Tabela3[Curso],$A14)-SUMIFS(Tabela3[Detratores (0-6)],Tabela3[Período],F$5,Tabela3[Curso],$A14))/SUMIFS(Tabela3[Respondentes],Tabela3[Período],F$5,Tabela3[Curso],$A14)*100,""))) | G14: =IF(G$5="","",IF(COUNTIFS(Tabela3[Período],G$5,Tabela3[Curso],$A14)=0,"",IFERROR((SUMIFS(Tabela3[Promotores (9-10)],Tabela3[Período],G$5,Tabela3[Curso],$A14)-SUMIFS(Tabela3[Detratores (0-6)],Tabela3[Período],G$5,Tabela3[Curso],$A14))/SUMIFS(Tabela3[Respondentes],Tabela3[Período],G$5,Tabela3[Curso],$A14)*100,""))) | H14: =IF(H$5="","",IF(COUNTIFS(Tabela3[Período],H$5,Tabela3[Curso],$A14)=0,"",IFERROR((SUMIFS(Tabela3[Promotores (9-10)],Tabela3[Período],H$5,Tabela3[Curso],$A14)-SUMIFS(Tabela3[Detratores (0-6)],Tabela3[Período],H$5,Tabela3[Curso],$A14))/SUMIFS(Tabela3[Respondentes],Tabela3[Período],H$5,Tabela3[Curso],$A14)*100,""))) | I14: =IF(I$5="","",IF(COUNTIFS(Tabela3[Período],I$5,Tabela3[Curso],$A14)=0,"",IFERROR((SUMIFS(Tabela3[Promotores (9-10)],Tabela3[Período],I$5,Tabela3[Curso],$A14)-SUMIFS(Tabela3[Detratores (0-6)],Tabela3[Período],I$5,Tabela3[Curso],$A14))/SUMIFS(Tabela3[Respondentes],Tabela3[Período],I$5,Tabela3[Curso],$A14)*100,""))) | ... M14: =IF(M$5="","",IF(COUNTIFS(Tabela3[Período],M$5,Tabela3[Curso],$A14)=0,"",IFERROR((SUMIFS(Tabela3[Promotores (9-10)],Tabela3[Período],M$5,Tabela3[Curso],$A14)-SUMIFS(Tabela3[Detratores (0-6)],Tabela3[Período],M$5,Tabela3[Curso],$A14))/SUMIFS(Tabela3[Respondentes],Tabela3[Período],M$5,Tabela3[Curso],$A14)*100,""))) | N14: =IF(CALC!$N$37="","",IF(COUNTIFS(Tabela3[Período],CALC!$N$37,Tabela3[Curso],$A14)=0,"",IFERROR((SUMIFS(Tabela3[Promotores (9-10)],Tabela3[Período],CALC!$N$37,Tabela3[Curso],$A14)-SUMIFS(Tabela3[Detratores (0-6)],Tabela3[Período],CALC!$N$37,Tabela3[Curso],$A14))/SUMIFS(Tabela3[Respondentes],Tabela3[Período],CALC!$N$37,Tabela3[Curso],$A14)*100,""))) | O14: =IF(CALC!$O$37="","",IF(COUNTIFS(Tabela3[Período],CALC!$O$37,Tabela3[Curso],$A14)=0,"",IFERROR((SUMIFS(Tabela3[Promotores (9-10)],Tabela3[Período],CALC!$O$37,Tabela3[Curso],$A14)-SUMIFS(Tabela3[Detratores (0-6)],Tabela3[Período],CALC!$O$37,Tabela3[Curso],$A14))/SUMIFS(Tabela3[Respondentes],Tabela3[Período],CALC!$O$37,Tabela3[Curso],$A14)*100,""))) | P14: =IF(OR(N14="",O14=""),"",N14-O14) | Q14: =IFERROR(INDEX(CALC!$B$8:$B$17,MATCH($A14,CALC!$A$8:$A$17,0)),"") | R14: =IF(OR(N14="",Q14=""),"",IF(ROUND(N14,6)>=ROUND(Q14,6),"Dentro da meta",IF(AND(IFERROR(IFERROR(INDEX(CALC!$C$8:$C$17,MATCH($A14,CALC!$A$8:$A$17,0)),""),"")<>"",ROUND(N14,6)>=ROUND(IFERROR(IFERROR(INDEX(CALC!$C$8:$C$17,MATCH($A14,CALC!$A$8:$A$17,0)),""),""),6)),"Atenção","Fora da meta")))
A17: DTNH-02 — Matrículas Ativas por Curso
A18: Curso | B18: =CALC!$B$55 | C18: =CALC!$B$56 | D18: =CALC!$B$57 | E18: =CALC!$B$58 | F18: =CALC!$B$59 | G18: =CALC!$B$60 | H18: =CALC!$B$61 | I18: =CALC!$B$62 | J18: =CALC!$B$63 | K18: =CALC!$B$64 | L18: =CALC!$B$65 | M18: =CALC!$B$66 | N18: Referência | O18: Comparação | P18: Variação | Q18: Meta | R18: Status
A19: =CURSOS!$A$5 | B19: =IF(B$18="","",IF(COUNTIFS(Tabela36[Período],B$18,Tabela36[Curso],$A19)=0,"",IFERROR(SUMIFS(Tabela36[Matrículas Ativas],Tabela36[Período],B$18,Tabela36[Curso],$A19),""))) | C19: =IF(C$18="","",IF(COUNTIFS(Tabela36[Período],C$18,Tabela36[Curso],$A19)=0,"",IFERROR(SUMIFS(Tabela36[Matrículas Ativas],Tabela36[Período],C$18,Tabela36[Curso],$A19),""))) | D19: =IF(D$18="","",IF(COUNTIFS(Tabela36[Período],D$18,Tabela36[Curso],$A19)=0,"",IFERROR(SUMIFS(Tabela36[Matrículas Ativas],Tabela36[Período],D$18,Tabela36[Curso],$A19),""))) | E19: =IF(E$18="","",IF(COUNTIFS(Tabela36[Período],E$18,Tabela36[Curso],$A19)=0,"",IFERROR(SUMIFS(Tabela36[Matrículas Ativas],Tabela36[Período],E$18,Tabela36[Curso],$A19),""))) | F19: =IF(F$18="","",IF(COUNTIFS(Tabela36[Período],F$18,Tabela36[Curso],$A19)=0,"",IFERROR(SUMIFS(Tabela36[Matrículas Ativas],Tabela36[Período],F$18,Tabela36[Curso],$A19),""))) | G19: =IF(G$18="","",IF(COUNTIFS(Tabela36[Período],G$18,Tabela36[Curso],$A19)=0,"",IFERROR(SUMIFS(Tabela36[Matrículas Ativas],Tabela36[Período],G$18,Tabela36[Curso],$A19),""))) | H19: =IF(H$18="","",IF(COUNTIFS(Tabela36[Período],H$18,Tabela36[Curso],$A19)=0,"",IFERROR(SUMIFS(Tabela36[Matrículas Ativas],Tabela36[Período],H$18,Tabela36[Curso],$A19),""))) | I19: =IF(I$18="","",IF(COUNTIFS(Tabela36[Período],I$18,Tabela36[Curso],$A19)=0,"",IFERROR(SUMIFS(Tabela36[Matrículas Ativas],Tabela36[Período],I$18,Tabela36[Curso],$A19),""))) | ... M19: =IF(M$18="","",IF(COUNTIFS(Tabela36[Período],M$18,Tabela36[Curso],$A19)=0,"",IFERROR(SUMIFS(Tabela36[Matrículas Ativas],Tabela36[Período],M$18,Tabela36[Curso],$A19),""))) | N19: =IF(CALC!$N$70="","",IF(COUNTIFS(Tabela36[Período],CALC!$N$70,Tabela36[Curso],$A19)=0,"",IFERROR(SUMIFS(Tabela36[Matrículas Ativas],Tabela36[Período],CALC!$N$70,Tabela36[Curso],$A19),""))) | O19: =IF(CALC!$O$70="","",IF(COUNTIFS(Tabela36[Período],CALC!$O$70,Tabela36[Curso],$A19)=0,"",IFERROR(SUMIFS(Tabela36[Matrículas Ativas],Tabela36[Período],CALC!$O$70,Tabela36[Curso],$A19),""))) | P19: =IFERROR(N19/O19-1,"") | Q19: =IFERROR(INDEX(CALC!$D$8:$D$17,MATCH($A19,CALC!$A$8:$A$17,0)),"") | R19: =IF(OR(N19="",O19="",O19=0,Q19=""),"",IF(ROUND(N19/O19-1,6)>=ROUND(Q19,6),"Dentro da meta",IF(AND(IFERROR(IFERROR(INDEX(CALC!$E$8:$E$17,MATCH($A19,CALC!$A$8:$A$17,0)),""),"")<>"",ROUND(N19/O19-1,6)>=ROUND(IFERROR(IFERROR(INDEX(CALC!$E$8:$E$17,MATCH($A19,CALC!$A$8:$A$17,0)),""),""),6)),"Atenção","Fora da meta")))
A20: =CURSOS!$A$6 | B20: =IF(B$18="","",IF(COUNTIFS(Tabela36[Período],B$18,Tabela36[Curso],$A20)=0,"",IFERROR(SUMIFS(Tabela36[Matrículas Ativas],Tabela36[Período],B$18,Tabela36[Curso],$A20),""))) | C20: =IF(C$18="","",IF(COUNTIFS(Tabela36[Período],C$18,Tabela36[Curso],$A20)=0,"",IFERROR(SUMIFS(Tabela36[Matrículas Ativas],Tabela36[Período],C$18,Tabela36[Curso],$A20),""))) | D20: =IF(D$18="","",IF(COUNTIFS(Tabela36[Período],D$18,Tabela36[Curso],$A20)=0,"",IFERROR(SUMIFS(Tabela36[Matrículas Ativas],Tabela36[Período],D$18,Tabela36[Curso],$A20),""))) | E20: =IF(E$18="","",IF(COUNTIFS(Tabela36[Período],E$18,Tabela36[Curso],$A20)=0,"",IFERROR(SUMIFS(Tabela36[Matrículas Ativas],Tabela36[Período],E$18,Tabela36[Curso],$A20),""))) | F20: =IF(F$18="","",IF(COUNTIFS(Tabela36[Período],F$18,Tabela36[Curso],$A20)=0,"",IFERROR(SUMIFS(Tabela36[Matrículas Ativas],Tabela36[Período],F$18,Tabela36[Curso],$A20),""))) | G20: =IF(G$18="","",IF(COUNTIFS(Tabela36[Período],G$18,Tabela36[Curso],$A20)=0,"",IFERROR(SUMIFS(Tabela36[Matrículas Ativas],Tabela36[Período],G$18,Tabela36[Curso],$A20),""))) | H20: =IF(H$18="","",IF(COUNTIFS(Tabela36[Período],H$18,Tabela36[Curso],$A20)=0,"",IFERROR(SUMIFS(Tabela36[Matrículas Ativas],Tabela36[Período],H$18,Tabela36[Curso],$A20),""))) | I20: =IF(I$18="","",IF(COUNTIFS(Tabela36[Período],I$18,Tabela36[Curso],$A20)=0,"",IFERROR(SUMIFS(Tabela36[Matrículas Ativas],Tabela36[Período],I$18,Tabela36[Curso],$A20),""))) | ... M20: =IF(M$18="","",IF(COUNTIFS(Tabela36[Período],M$18,Tabela36[Curso],$A20)=0,"",IFERROR(SUMIFS(Tabela36[Matrículas Ativas],Tabela36[Período],M$18,Tabela36[Curso],$A20),""))) | N20: =IF(CALC!$N$70="","",IF(COUNTIFS(Tabela36[Período],CALC!$N$70,Tabela36[Curso],$A20)=0,"",IFERROR(SUMIFS(Tabela36[Matrículas Ativas],Tabela36[Período],CALC!$N$70,Tabela36[Curso],$A20),""))) | O20: =IF(CALC!$O$70="","",IF(COUNTIFS(Tabela36[Período],CALC!$O$70,Tabela36[Curso],$A20)=0,"",IFERROR(SUMIFS(Tabela36[Matrículas Ativas],Tabela36[Período],CALC!$O$70,Tabela36[Curso],$A20),""))) | P20: =IFERROR(N20/O20-1,"") | Q20: =IFERROR(INDEX(CALC!$D$8:$D$17,MATCH($A20,CALC!$A$8:$A$17,0)),"") | R20: =IF(OR(N20="",O20="",O20=0,Q20=""),"",IF(ROUND(N20/O20-1,6)>=ROUND(Q20,6),"Dentro da meta",IF(AND(IFERROR(IFERROR(INDEX(CALC!$E$8:$E$17,MATCH($A20,CALC!$A$8:$A$17,0)),""),"")<>"",ROUND(N20/O20-1,6)>=ROUND(IFERROR(IFERROR(INDEX(CALC!$E$8:$E$17,MATCH($A20,CALC!$A$8:$A$17,0)),""),""),6)),"Atenção","Fora da meta")))
A21: =CURSOS!$A$7 | B21: =IF(B$18="","",IF(COUNTIFS(Tabela36[Período],B$18,Tabela36[Curso],$A21)=0,"",IFERROR(SUMIFS(Tabela36[Matrículas Ativas],Tabela36[Período],B$18,Tabela36[Curso],$A21),""))) | C21: =IF(C$18="","",IF(COUNTIFS(Tabela36[Período],C$18,Tabela36[Curso],$A21)=0,"",IFERROR(SUMIFS(Tabela36[Matrículas Ativas],Tabela36[Período],C$18,Tabela36[Curso],$A21),""))) | D21: =IF(D$18="","",IF(COUNTIFS(Tabela36[Período],D$18,Tabela36[Curso],$A21)=0,"",IFERROR(SUMIFS(Tabela36[Matrículas Ativas],Tabela36[Período],D$18,Tabela36[Curso],$A21),""))) | E21: =IF(E$18="","",IF(COUNTIFS(Tabela36[Período],E$18,Tabela36[Curso],$A21)=0,"",IFERROR(SUMIFS(Tabela36[Matrículas Ativas],Tabela36[Período],E$18,Tabela36[Curso],$A21),""))) | F21: =IF(F$18="","",IF(COUNTIFS(Tabela36[Período],F$18,Tabela36[Curso],$A21)=0,"",IFERROR(SUMIFS(Tabela36[Matrículas Ativas],Tabela36[Período],F$18,Tabela36[Curso],$A21),""))) | G21: =IF(G$18="","",IF(COUNTIFS(Tabela36[Período],G$18,Tabela36[Curso],$A21)=0,"",IFERROR(SUMIFS(Tabela36[Matrículas Ativas],Tabela36[Período],G$18,Tabela36[Curso],$A21),""))) | H21: =IF(H$18="","",IF(COUNTIFS(Tabela36[Período],H$18,Tabela36[Curso],$A21)=0,"",IFERROR(SUMIFS(Tabela36[Matrículas Ativas],Tabela36[Período],H$18,Tabela36[Curso],$A21),""))) | I21: =IF(I$18="","",IF(COUNTIFS(Tabela36[Período],I$18,Tabela36[Curso],$A21)=0,"",IFERROR(SUMIFS(Tabela36[Matrículas Ativas],Tabela36[Período],I$18,Tabela36[Curso],$A21),""))) | ... M21: =IF(M$18="","",IF(COUNTIFS(Tabela36[Período],M$18,Tabela36[Curso],$A21)=0,"",IFERROR(SUMIFS(Tabela36[Matrículas Ativas],Tabela36[Período],M$18,Tabela36[Curso],$A21),""))) | N21: =IF(CALC!$N$70="","",IF(COUNTIFS(Tabela36[Período],CALC!$N$70,Tabela36[Curso],$A21)=0,"",IFERROR(SUMIFS(Tabela36[Matrículas Ativas],Tabela36[Período],CALC!$N$70,Tabela36[Curso],$A21),""))) | O21: =IF(CALC!$O$70="","",IF(COUNTIFS(Tabela36[Período],CALC!$O$70,Tabela36[Curso],$A21)=0,"",IFERROR(SUMIFS(Tabela36[Matrículas Ativas],Tabela36[Período],CALC!$O$70,Tabela36[Curso],$A21),""))) | P21: =IFERROR(N21/O21-1,"") | Q21: =IFERROR(INDEX(CALC!$D$8:$D$17,MATCH($A21,CALC!$A$8:$A$17,0)),"") | R21: =IF(OR(N21="",O21="",O21=0,Q21=""),"",IF(ROUND(N21/O21-1,6)>=ROUND(Q21,6),"Dentro da meta",IF(AND(IFERROR(IFERROR(INDEX(CALC!$E$8:$E$17,MATCH($A21,CALC!$A$8:$A$17,0)),""),"")<>"",ROUND(N21/O21-1,6)>=ROUND(IFERROR(IFERROR(INDEX(CALC!$E$8:$E$17,MATCH($A21,CALC!$A$8:$A$17,0)),""),""),6)),"Atenção","Fora da meta")))
